<sdf version='1.5'>
  <model name='blimp'>
    <link name='base_link'>
      <inertial>
        <pose>0 0 0.50831 0 -0 0</pose>
        <mass>1.505</mass>
        <inertia>
          <ixx>0.0214388</ixx>
          <ixy>3.46972e-19</ixy>
          <ixz>-2.89907e-20</ixz>
          <iyy>0.0369914</iyy>
          <iyz>2.1684e-19</iyz>
          <izz>0.0286943</izz>
        </inertia>
      </inertial>
      <collision name='base_link_fixed_joint_lump__gondola_body_link_collision'>
        <pose>0 0 0.1 0 -0 0</pose>
        <geometry>
          <mesh>
            <scale>1 1 1</scale>
            <uri>model://rblimp/meshes/blimp_gondola/blimp_gondola_v4.dae</uri>
          </mesh>
        </geometry>
        <surface>
          <contact>
            <ode>
              <kp>1e+06</kp>
              <kd>1e+06</kd>
            </ode>
          </contact>
          <friction>
            <ode>
              <mu>10</mu>
              <mu2>10</mu2>
            </ode>
          </friction>
        </surface>
      </collision>
      <collision name='base_link_fixed_joint_lump__gondola_left_support_link_collision_1'>
        <pose>0 0.1 -0.085 0.4 -0 0</pose>
        <geometry>
          <mesh>
            <scale>1 1 1</scale>
            <uri>model://rblimp/meshes/blimp_support/blimp_support_v5.dae</uri>
          </mesh>
        </geometry>
        <surface>
          <contact>
            <ode>
              <kp>1e+06</kp>
              <kd>1e+06</kd>
            </ode>
          </contact>
          <friction>
            <ode>
              <mu>10</mu>
              <mu2>10</mu2>
            </ode>
          </friction>
        </surface>
      </collision>
      <collision name='base_link_fixed_joint_lump__gondola_right_support_link_collision_2'>
        <pose>0 -0.1 -0.085 0.4 -0 3.14159</pose>
        <geometry>
          <mesh>
            <scale>1 1 1</scale>
            <uri>model://rblimp/meshes/blimp_support/blimp_support_v5.dae</uri>
          </mesh>
        </geometry>
        <surface>
          <contact>
            <ode>
              <kp>1e+06</kp>
              <kd>1e+06</kd>
            </ode>
          </contact>
          <friction>
            <ode>
              <mu>10</mu>
              <mu2>10</mu2>
            </ode>
          </friction>
        </surface>
      </collision>
      <visual name='base_link_fixed_joint_lump__gondola_body_link_visual'>
        <pose>0 0 0.1 0 -0 0</pose>
        <geometry>
          <mesh>
            <scale>1 1 1</scale>
            <uri>model://rblimp/meshes/blimp_gondola/blimp_gondola_v4.dae</uri>
          </mesh>
        </geometry>
      </visual>
      <visual name='base_link_fixed_joint_lump__gondola_left_support_link_visual_1'>
        <pose>0 0.1 -0.085 0.4 -0 0</pose>
        <geometry>
          <mesh>
            <scale>1 1 1</scale>
            <uri>model://rblimp/meshes/blimp_support/blimp_support_v5.dae</uri>
          </mesh>
        </geometry>
      </visual>
      <visual name='base_link_fixed_joint_lump__gondola_right_support_link_visual_2'>
        <pose>0 -0.1 -0.085 0.4 -0 3.14159</pose>
        <geometry>
          <mesh>
            <scale>1 1 1</scale>
            <uri>model://rblimp/meshes/blimp_support/blimp_support_v5.dae</uri>
          </mesh>
        </geometry>
      </visual>
    </link>
    <joint name='blimp/gondola_body_joint_link_joint0' type='revolute'>
      <pose relative_to='base_link'>0 0 0.1 0 -0 0</pose>
      <parent>base_link</parent>
      <child>gondola_body_joint_link0</child>
      <axis>
        <xyz>1 0 0</xyz>
        <limit>
          <lower>0</lower>
          <upper>0</upper>
          <effort>-1</effort>
          <velocity>-1</velocity>
        </limit>
        <dynamics>
          <damping>0.5</damping>
          <friction>0</friction>
          <spring_reference>0</spring_reference>
          <spring_stiffness>0</spring_stiffness>
        </dynamics>
      </axis>
      <physics>
        <ode>
          <limit>
            <cfm>0.5</cfm>
            <erp>0.2</erp>
          </limit>
        </ode>
      </physics>
    </joint>
    <link name='gondola_body_joint_link0'>
      <pose relative_to='blimp/gondola_body_joint_link_joint0'>0 0 0 0 -0 0</pose>
      <inertial>
        <pose>0 0 0 0 -0 0</pose>
        <mass>0.0001</mass>
        <inertia>
          <ixx>0.01</ixx>
          <ixy>0</ixy>
          <ixz>0</ixz>
          <iyy>0.01</iyy>
          <iyz>0</iyz>
          <izz>0.01</izz>
        </inertia>
      </inertial>
    </link>
    <joint name='blimp/gondola_body_joint_link_joint1' type='revolute'>
      <pose relative_to='gondola_body_joint_link0'>0 0 0 0 -0 0</pose>
      <parent>gondola_body_joint_link0</parent>
      <child>gondola_body_joint_link1</child>
      <axis>
        <xyz>0 1 0</xyz>
        <limit>
          <lower>0</lower>
          <upper>0</upper>
          <effort>-1</effort>
          <velocity>-1</velocity>
        </limit>
        <dynamics>
          <damping>0.5</damping>
          <friction>0</friction>
          <spring_reference>0</spring_reference>
          <spring_stiffness>0</spring_stiffness>
        </dynamics>
      </axis>
      <physics>
        <ode>
          <limit>
            <cfm>0.1</cfm>
            <erp>0.2</erp>
          </limit>
        </ode>
      </physics>
    </joint>
    <link name='gondola_body_joint_link1'>
      <pose relative_to='blimp/gondola_body_joint_link_joint1'>0 0 0 0 -0 0</pose>
      <inertial>
        <pose>0 0 0 0 -0 0</pose>
        <mass>0.0001</mass>
        <inertia>
          <ixx>0.01</ixx>
          <ixy>0</ixy>
          <ixz>0</ixz>
          <iyy>0.01</iyy>
          <iyz>0</iyz>
          <izz>0.01</izz>
        </inertia>
      </inertial>
    </link>
    <joint name='blimp/gondola_body_joint_link_joint' type='revolute'>
      <pose relative_to='gondola_body_joint_link1'>0 0 0 0 -0 0</pose>
      <parent>gondola_body_joint_link1</parent>
      <child>gondola_body_joint_link</child>
      <axis>
        <xyz>0 0 1</xyz>
        <limit>
          <lower>0</lower>
          <upper>0</upper>
          <effort>-1</effort>
          <velocity>-1</velocity>
        </limit>
        <dynamics>
          <damping>0.5</damping>
          <friction>0</friction>
          <spring_reference>0</spring_reference>
          <spring_stiffness>0</spring_stiffness>
        </dynamics>
      </axis>
      <physics>
        <ode>
          <limit>
            <cfm>0.05</cfm>
            <erp>0.2</erp>
          </limit>
        </ode>
      </physics>
    </joint>
    <link name='gondola_body_joint_link'>
      <pose relative_to='blimp/gondola_body_joint_link_joint'>0 0 0 0 -0 0</pose>
      <inertial>
        <pose>0 0 0 0 -0 0</pose>
        <mass>0.0001</mass>
        <inertia>
          <ixx>0.01</ixx>
          <ixy>0</ixy>
          <ixz>0</ixz>
          <iyy>0.01</iyy>
          <iyz>0</iyz>
          <izz>0.01</izz>
        </inertia>
      </inertial>
      <visual name='gondola_body_joint_link_visual'>
        <pose>0 0 0 0 -0 0</pose>
        <geometry>
          <cylinder>
            <length>0.3</length>
            <radius>0.01</radius>
          </cylinder>
        </geometry>
      </visual>
    </link>
    <joint name='gondola_joint_blimb_body_joint' type='revolute'>
      <!-- <pose relative_to='gondola_body_joint_link'>-1 0 1.05 0 1.5708 0</pose> -->
      <pose relative_to='base_link'>-1 0 1.05 0 1.5708 0</pose>
      <!-- <parent>gondola_body_joint_link</parent> -->
      <parent>base_link</parent>
      <child>blimp_body_link</child>
      <axis>
        <xyz>1 0 0</xyz>
        <limit>
          <lower>0</lower>
          <upper>0</upper>
          <effort>1000</effort>
          <velocity>1000</velocity>
        </limit>
        <dynamics>
          <spring_reference>0</spring_reference>
          <spring_stiffness>0</spring_stiffness>
        </dynamics>
      </axis>
    </joint>
    <link name='blimp_body_link'>
      <pose relative_to='gondola_joint_blimb_body_joint'>0 0 0 0 -0 0</pose>
      <inertial>
        <pose>0 0 0 0 -0 0</pose>
        <mass>4.622</mass>
        <inertia>
          <ixx>7.49137</ixx>
          <ixy>0</ixy>
          <ixz>0</ixz>
          <iyy>7.49137</iyy>
          <iyz>0</iyz>
          <izz>2.89942</izz>
        </inertia>
      </inertial>
      <collision name='blimp_body_link_collision'>
        <pose>0 0 0 0 -0 0</pose>
        <geometry>
          <mesh>
            <scale>1 1 1</scale>
            <uri>model://rblimp/meshes/blimp_body/blimp_body_v4.dae</uri>
          </mesh>
        </geometry>
        <surface>
          <contact>
            <ode>
              <kp>1e+06</kp>
              <kd>1e+06</kd>
            </ode>
          </contact>
          <friction>
            <ode>
              <mu>10</mu>
              <mu2>10</mu2>
            </ode>
          </friction>
        </surface>
      </collision>
      <visual name='blimp_body_link_visual'>
        <pose>0 0 0 0 -0 0</pose>
        <geometry>
          <mesh>
            <scale>1 1 1</scale>
            <uri>model://rblimp/meshes/blimp_body/blimp_body_v4.dae</uri>
          </mesh>
        </geometry>
      </visual>
    </link>
    <joint name='blimp/bot_rud_base_joint_link_joint0' type='revolute'>
      <pose relative_to='blimp_body_link'>0.59 0 -1.5 0 -1.5708 0</pose>
      <parent>blimp_body_link</parent>
      <!-- <child>bot_rud_base_joint_link0</child> -->
      <child>bot_rud_part1_link</child>
      <axis>
        <xyz>1 0 0</xyz>
        <limit>
          <lower>0</lower>
          <upper>0</upper>
          <effort>-1</effort>
          <velocity>-1</velocity>
        </limit>
        <dynamics>
          <damping>0.5</damping>
          <friction>0</friction>
          <spring_reference>0</spring_reference>
          <spring_stiffness>0</spring_stiffness>
        </dynamics>
      </axis>
      <physics>
        <ode>
          <limit>
            <cfm>1</cfm>
            <erp>0.2</erp>
          </limit>
        </ode>
      </physics>
    </joint>
    <link name='bot_rud_base_joint_link0'>
      <pose relative_to='blimp/bot_rud_base_joint_link_joint0'>0 0 0 0 -0 0</pose>
      <inertial>
        <pose>0 0 0 0 -0 0</pose>
        <mass>0.0001</mass>
        <inertia>
          <ixx>0.01</ixx>
          <ixy>0</ixy>
          <ixz>0</ixz>
          <iyy>0.01</iyy>
          <iyz>0</iyz>
          <izz>0.01</izz>
        </inertia>
      </inertial>
    </link>
    <joint name='blimp/bot_rud_base_joint_link_joint1' type='revolute'>
      <pose relative_to='bot_rud_base_joint_link0'>0 0 0 0 -0 0</pose>
      <parent>bot_rud_base_joint_link0</parent>
      <child>bot_rud_base_joint_link1</child>
      <axis>
        <xyz>0 1 0</xyz>
        <limit>
          <lower>0</lower>
          <upper>0</upper>
          <effort>-1</effort>
          <velocity>-1</velocity>
        </limit>
        <dynamics>
          <damping>0.5</damping>
          <friction>0</friction>
          <spring_reference>0</spring_reference>
          <spring_stiffness>0</spring_stiffness>
        </dynamics>
      </axis>
      <physics>
        <ode>
          <limit>
            <cfm>0.2</cfm>
            <erp>0.2</erp>
          </limit>
        </ode>
      </physics>
    </joint>
    <link name='bot_rud_base_joint_link1'>
      <pose relative_to='blimp/bot_rud_base_joint_link_joint1'>0 0 0 0 -0 0</pose>
      <inertial>
        <pose>0 0 0 0 -0 0</pose>
        <mass>0.0001</mass>
        <inertia>
          <ixx>0.01</ixx>
          <ixy>0</ixy>
          <ixz>0</ixz>
          <iyy>0.01</iyy>
          <iyz>0</iyz>
          <izz>0.01</izz>
        </inertia>
      </inertial>
    </link>
    <joint name='blimp/bot_rud_base_joint_link_joint' type='revolute'>
      <pose relative_to='bot_rud_base_joint_link1'>0 0 0 0 -0 0</pose>
      <parent>bot_rud_base_joint_link1</parent>
      <child>bot_rud_base_joint_link</child>
      <axis>
        <xyz>0 0 1</xyz>
        <limit>
          <lower>0</lower>
          <upper>0</upper>
          <effort>-1</effort>
          <velocity>-1</velocity>
        </limit>
        <dynamics>
          <damping>0.5</damping>
          <friction>0</friction>
          <spring_reference>0</spring_reference>
          <spring_stiffness>0</spring_stiffness>
        </dynamics>
      </axis>
      <physics>
        <ode>
          <limit>
            <cfm>0.1</cfm>
            <erp>0.2</erp>
          </limit>
        </ode>
      </physics>
    </joint>
    <link name='bot_rud_base_joint_link'>
      <pose relative_to='blimp/bot_rud_base_joint_link_joint'>0 0 0 0 -0 0</pose>
      <inertial>
        <pose>0 0 0 0 -0 0</pose>
        <mass>0.0001</mass>
        <inertia>
          <ixx>0.01</ixx>
          <ixy>0</ixy>
          <ixz>0</ixz>
          <iyy>0.01</iyy>
          <iyz>0</iyz>
          <izz>0.01</izz>
        </inertia>
      </inertial>
      <visual name='bot_rud_base_joint_link_visual'>
        <pose>0 0 0 0 -0 0</pose>
        <geometry>
          <cylinder>
            <length>0.3</length>
            <radius>0.01</radius>
          </cylinder>
        </geometry>
      </visual>
    </link>
    <joint name='blimp_body_bot_rud_part1_joint' type='revolute'>
      <pose relative_to='bot_rud_base_joint_link'>0 0 -0.24 0 -0 0</pose>
      <parent>bot_rud_base_joint_link</parent>
      <child>bot_rud_part1_link</child>
      <axis>
        <xyz>1 0 0</xyz>
        <limit>
          <lower>0</lower>
          <upper>0</upper>
          <effort>1000</effort>
          <velocity>1000</velocity>
        </limit>
        <dynamics>
          <spring_reference>0</spring_reference>
          <spring_stiffness>0</spring_stiffness>
        </dynamics>
      </axis>
    </joint>
    <link name='bot_rud_part1_link'>
      <pose relative_to='blimp_body_bot_rud_part1_joint'>0 0 0 0 -0 0</pose>
      <inertial>
        <pose>0 0 0 0 -0 0</pose>
        <mass>0.41</mass>
        <inertia>
          <ixx>0.0111553</ixx>
          <ixy>0</ixy>
          <ixz>0</ixz>
          <iyy>0.0257568</iyy>
          <iyz>0</iyz>
          <izz>0.0146402</izz>
        </inertia>
      </inertial>
      <collision name='bot_rud_part1_link_collision'>
        <pose>0 0 0 0 -0 0</pose>
        <geometry>
          <mesh>
            <scale>1 1 1</scale>
            <uri>model://rblimp/meshes/blimp_fin/blimp_bot_rud_part1_v3.dae</uri>
          </mesh>
        </geometry>
        <surface>
          <contact>
            <ode>
              <kp>1e+06</kp>
              <kd>1e+06</kd>
            </ode>
          </contact>
          <friction>
            <ode>
              <mu>10</mu>
              <mu2>10</mu2>
            </ode>
          </friction>
        </surface>
      </collision>
      <visual name='bot_rud_part1_link_visual'>
        <pose>0 0 0 0 -0 0</pose>
        <geometry>
          <mesh>
            <scale>1 1 1</scale>
            <uri>model://rblimp/meshes/blimp_fin/blimp_bot_rud_part1_v3.dae</uri>
          </mesh>
        </geometry>
      </visual>
    </link>
    <joint name='bot_rud_part1_bot_rud_joint_link_joint' type='revolute'>
      <pose relative_to='bot_rud_part1_link'>-0.28 0 0 0 -0 0</pose>
      <parent>bot_rud_part1_link</parent>
      <child>bot_rud_joint_link</child>
      <axis>
        <xyz>0 0 1</xyz>
        <limit>
          <lower>-1.0472</lower>
          <upper>1.0472</upper>
          <effort>500</effort>
          <velocity>2</velocity>
        </limit>
        <dynamics>
          <spring_reference>0</spring_reference>
          <spring_stiffness>0</spring_stiffness>
        </dynamics>
      </axis>
    </joint>
    <link name='bot_rud_joint_link'>
      <pose relative_to='bot_rud_part1_bot_rud_joint_link_joint'>0 0 0 0 -0 0</pose>
      <inertial>
        <pose>-0.125 0 0 0 -0 0</pose>
        <mass>0.113</mass>
        <inertia>
          <ixx>0.00217337</ixx>
          <ixy>0</ixy>
          <ixz>0</ixz>
          <iyy>0.0030171</iyy>
          <iyz>0</iyz>
          <izz>0.000851266</izz>
        </inertia>
      </inertial>
      <collision name='bot_rud_joint_link_fixed_joint_lump__bot_rud_part2_link_collision'>
        <pose>-0.125 0 0 0 -0 0</pose>
        <geometry>
          <mesh>
            <scale>1 1 1</scale>
            <uri>model://rblimp/meshes/blimp_fin/blimp_top_rud_part2_v5.dae</uri>
          </mesh>
        </geometry>
        <surface>
          <contact>
            <ode>
              <kp>1e+06</kp>
              <kd>1e+06</kd>
            </ode>
          </contact>
          <friction>
            <ode>
              <mu>10</mu>
              <mu2>10</mu2>
            </ode>
          </friction>
        </surface>
      </collision>
      <visual name='bot_rud_joint_link_visual'>
        <pose>0 0 0 0 -0 0</pose>
        <geometry>
          <cylinder>
            <length>0.3</length>
            <radius>0.01</radius>
          </cylinder>
        </geometry>
      </visual>
      <visual name='bot_rud_joint_link_fixed_joint_lump__bot_rud_part2_link_visual_1'>
        <pose>-0.125 0 0 0 -0 0</pose>
        <geometry>
          <mesh>
            <scale>1 1 1</scale>
            <uri>model://rblimp/meshes/blimp_fin/blimp_top_rud_part2_v5.dae</uri>
          </mesh>
        </geometry>
      </visual>
    </link>
    <joint name='bot_rud_part1_bot_rud_motor_joint' type='revolute'>
      <pose relative_to='bot_rud_part1_link'>-0.065 0.01 -0.025 -1.5708 0 0</pose>
      <parent>bot_rud_part1_link</parent>
      <child>bot_rud_motor_link</child>
      <axis>
        <xyz>0 0 -1</xyz>
        <limit>
          <lower>-1e+16</lower>
          <upper>1e+16</upper>
        </limit>
        <dynamics>
          <spring_reference>0</spring_reference>
          <spring_stiffness>0</spring_stiffness>
        </dynamics>
      </axis>
    </joint>
    <link name='bot_rud_motor_link'>
      <pose relative_to='bot_rud_part1_bot_rud_motor_joint'>0 0 0 0 -0 0</pose>
      <inertial>
        <pose>0 0 0 0 -0 0</pose>
        <mass>0.127</mass>
        <inertia>
          <ixx>0.000662252</ixx>
          <ixy>0</ixy>
          <ixz>0</ixz>
          <iyy>0.000662252</iyy>
          <iyz>0</iyz>
          <izz>1.5875e-06</izz>
        </inertia>
      </inertial>
      <collision name='bot_rud_motor_link_collision'>
        <pose>0 0 0 0 -0 0</pose>
        <geometry>
          <mesh>
            <scale>1 1 1</scale>
            <uri>model://rblimp/meshes/blimp_propeller/blimp_bot_propeller_cw_v3.dae</uri>
          </mesh>
        </geometry>
        <surface>
          <contact>
            <ode>
              <kp>1e+06</kp>
              <kd>1e+06</kd>
            </ode>
          </contact>
          <friction>
            <ode>
              <mu>10</mu>
              <mu2>10</mu2>
            </ode>
          </friction>
        </surface>
      </collision>
      <visual name='bot_rud_motor_link_visual'>
        <pose>0 0 0 0 -0 0</pose>
        <geometry>
          <mesh>
            <scale>1 1 1</scale>
            <uri>model://rblimp/meshes/blimp_propeller/blimp_bot_propeller_cw_v3.dae</uri>
          </mesh>
        </geometry>
      </visual>
    </link>
    <joint name='blimp/left_elv_base_joint_link_joint0' type='revolute'>
      <pose relative_to='blimp_body_link'>0 0.59 -1.5 1.5708 -1.5708 0</pose>
      <parent>blimp_body_link</parent>
      <!-- <child>left_elv_base_joint_link0</child> -->
      <child>left_elv_part1_link</child>
      <axis>
        <xyz>1 0 0</xyz>
        <limit>
          <lower>0</lower>
          <upper>0</upper>
          <effort>-1</effort>
          <velocity>-1</velocity>
        </limit>
        <dynamics>
          <damping>0.5</damping>
          <friction>0</friction>
          <spring_reference>0</spring_reference>
          <spring_stiffness>0</spring_stiffness>
        </dynamics>
      </axis>
      <physics>
        <ode>
          <limit>
            <cfm>1</cfm>
            <erp>0.2</erp>
          </limit>
        </ode>
      </physics>
    </joint>
    <link name='left_elv_base_joint_link0'>
      <pose relative_to='blimp/left_elv_base_joint_link_joint0'>0 0 0 0 -0 0</pose>
      <inertial>
        <pose>0 0 0 0 -0 0</pose>
        <mass>0.0001</mass>
        <inertia>
          <ixx>0.01</ixx>
          <ixy>0</ixy>
          <ixz>0</ixz>
          <iyy>0.01</iyy>
          <iyz>0</iyz>
          <izz>0.01</izz>
        </inertia>
      </inertial>
    </link>
    <joint name='blimp/left_elv_base_joint_link_joint1' type='revolute'>
      <pose relative_to='left_elv_base_joint_link0'>0 0 0 0 -0 0</pose>
      <parent>left_elv_base_joint_link0</parent>
      <child>left_elv_base_joint_link1</child>
      <axis>
        <xyz>0 1 0</xyz>
        <limit>
          <lower>0</lower>
          <upper>0</upper>
          <effort>-1</effort>
          <velocity>-1</velocity>
        </limit>
        <dynamics>
          <damping>0.5</damping>
          <friction>0</friction>
          <spring_reference>0</spring_reference>
          <spring_stiffness>0</spring_stiffness>
        </dynamics>
      </axis>
      <physics>
        <ode>
          <limit>
            <cfm>0.2</cfm>
            <erp>0.2</erp>
          </limit>
        </ode>
      </physics>
    </joint>
    <link name='left_elv_base_joint_link1'>
      <pose relative_to='blimp/left_elv_base_joint_link_joint1'>0 0 0 0 -0 0</pose>
      <inertial>
        <pose>0 0 0 0 -0 0</pose>
        <mass>0.0001</mass>
        <inertia>
          <ixx>0.01</ixx>
          <ixy>0</ixy>
          <ixz>0</ixz>
          <iyy>0.01</iyy>
          <iyz>0</iyz>
          <izz>0.01</izz>
        </inertia>
      </inertial>
    </link>
    <joint name='blimp/left_elv_base_joint_link_joint' type='revolute'>
      <pose relative_to='left_elv_base_joint_link1'>0 0 0 0 -0 0</pose>
      <parent>left_elv_base_joint_link1</parent>
      <child>left_elv_base_joint_link</child>
      <axis>
        <xyz>0 0 1</xyz>
        <limit>
          <lower>0</lower>
          <upper>0</upper>
          <effort>-1</effort>
          <velocity>-1</velocity>
        </limit>
        <dynamics>
          <damping>0.5</damping>
          <friction>0</friction>
          <spring_reference>0</spring_reference>
          <spring_stiffness>0</spring_stiffness>
        </dynamics>
      </axis>
      <physics>
        <ode>
          <limit>
            <cfm>0.1</cfm>
            <erp>0.2</erp>
          </limit>
        </ode>
      </physics>
    </joint>
    <link name='left_elv_base_joint_link'>
      <pose relative_to='blimp/left_elv_base_joint_link_joint'>0 0 0 0 -0 0</pose>
      <inertial>
        <pose>0 0 0 0 -0 0</pose>
        <mass>0.0001</mass>
        <inertia>
          <ixx>0.01</ixx>
          <ixy>0</ixy>
          <ixz>0</ixz>
          <iyy>0.01</iyy>
          <iyz>0</iyz>
          <izz>0.01</izz>
        </inertia>
      </inertial>
      <visual name='left_elv_base_joint_link_visual'>
        <pose>0 0 0 0 -0 0</pose>
        <geometry>
          <cylinder>
            <length>0.3</length>
            <radius>0.01</radius>
          </cylinder>
        </geometry>
      </visual>
    </link>
    <joint name='blimp_body_left_elv_part1_joint' type='revolute'>
      <pose relative_to='left_elv_base_joint_link'>0 0 -0.24 0 -0 0</pose>
      <parent>left_elv_base_joint_link</parent>
      <child>left_elv_part1_link</child>
      <axis>
        <xyz>1 0 0</xyz>
        <limit>
          <lower>0</lower>
          <upper>0</upper>
          <effort>1000</effort>
          <velocity>1000</velocity>
        </limit>
        <dynamics>
          <spring_reference>0</spring_reference>
          <spring_stiffness>0</spring_stiffness>
        </dynamics>
      </axis>
    </joint>
    <link name='left_elv_part1_link'>
      <pose relative_to='blimp_body_left_elv_part1_joint'>0 0 0 0 -0 0</pose>
      <inertial>
        <pose>0 0 0 0 -0 0</pose>
        <mass>0.58</mass>
        <inertia>
          <ixx>0.0111553</ixx>
          <ixy>0</ixy>
          <ixz>0</ixz>
          <iyy>0.0257568</iyy>
          <iyz>0</iyz>
          <izz>0.0146402</izz>
        </inertia>
      </inertial>
      <collision name='left_elv_part1_link_collision'>
        <pose>0 0 0 0 -0 0</pose>
        <geometry>
          <mesh>
            <scale>1 1 1</scale>
            <uri>model://rblimp/meshes/blimp_fin/blimp_top_rud_part1_v3.dae</uri>
          </mesh>
        </geometry>
        <surface>
          <contact>
            <ode>
              <kp>1e+06</kp>
              <kd>1e+06</kd>
            </ode>
          </contact>
          <friction>
            <ode>
              <mu>10</mu>
              <mu2>10</mu2>
            </ode>
          </friction>
        </surface>
      </collision>
      <visual name='left_elv_part1_link_visual'>
        <pose>0 0 0 0 -0 0</pose>
        <geometry>
          <mesh>
            <scale>1 1 1</scale>
            <uri>model://rblimp/meshes/blimp_fin/blimp_top_rud_part1_v3.dae</uri>
          </mesh>
        </geometry>
      </visual>
    </link>
    <joint name='left_elv_part1_left_elv_joint_link_joint' type='revolute'>
      <pose relative_to='left_elv_part1_link'>-0.28 0 0 0 -0 0</pose>
      <parent>left_elv_part1_link</parent>
      <child>left_elv_joint_link</child>
      <axis>
        <xyz>0 0 1</xyz>
        <limit>
          <lower>-1.0472</lower>
          <upper>1.0472</upper>
          <effort>500</effort>
          <velocity>2</velocity>
        </limit>
        <dynamics>
          <spring_reference>0</spring_reference>
          <spring_stiffness>0</spring_stiffness>
        </dynamics>
      </axis>
    </joint>
    <link name='left_elv_joint_link'>
      <pose relative_to='left_elv_part1_left_elv_joint_link_joint'>0 0 0 0 -0 0</pose>
      <inertial>
        <pose>-0.125 0 0 0 -0 0</pose>
        <mass>0.113</mass>
        <inertia>
          <ixx>0.00217337</ixx>
          <ixy>0</ixy>
          <ixz>0</ixz>
          <iyy>0.0030171</iyy>
          <iyz>0</iyz>
          <izz>0.000851266</izz>
        </inertia>
      </inertial>
      <collision name='left_elv_joint_link_fixed_joint_lump__left_elv_part2_link_collision'>
        <pose>-0.125 0 0 0 -0 0</pose>
        <geometry>
          <mesh>
            <scale>1 1 1</scale>
            <uri>model://rblimp/meshes/blimp_fin/blimp_top_rud_part2_v5.dae</uri>
          </mesh>
        </geometry>
        <surface>
          <contact>
            <ode>
              <kp>1e+06</kp>
              <kd>1e+06</kd>
            </ode>
          </contact>
          <friction>
            <ode>
              <mu>10</mu>
              <mu2>10</mu2>
            </ode>
          </friction>
        </surface>
      </collision>
      <visual name='left_elv_joint_link_visual'>
        <pose>0 0 0 0 -0 0</pose>
        <geometry>
          <cylinder>
            <length>0.3</length>
            <radius>0.01</radius>
          </cylinder>
        </geometry>
      </visual>
      <visual name='left_elv_joint_link_fixed_joint_lump__left_elv_part2_link_visual_1'>
        <pose>-0.125 0 0 0 -0 0</pose>
        <geometry>
          <mesh>
            <scale>1 1 1</scale>
            <uri>model://rblimp/meshes/blimp_fin/blimp_top_rud_part2_v5.dae</uri>
          </mesh>
        </geometry>
      </visual>
    </link>
    <joint name='blimp/right_elv_base_joint_link_joint0' type='revolute'>
      <pose relative_to='blimp_body_link'>0 -0.59 -1.5 -1.5708 -1.5708 0</pose>
      <parent>blimp_body_link</parent>
      <!-- <child>right_elv_base_joint_link0</child> -->
      <child>right_elv_part1_link</child>
      <axis>
        <xyz>1 0 0</xyz>
        <limit>
          <lower>0</lower>
          <upper>0</upper>
          <effort>-1</effort>
          <velocity>-1</velocity>
        </limit>
        <dynamics>
          <damping>0.5</damping>
          <friction>0</friction>
          <spring_reference>0</spring_reference>
          <spring_stiffness>0</spring_stiffness>
        </dynamics>
      </axis>
      <physics>
        <ode>
          <limit>
            <cfm>1</cfm>
            <erp>0.2</erp>
          </limit>
        </ode>
      </physics>
    </joint>
    <link name='right_elv_base_joint_link0'>
      <pose relative_to='blimp/right_elv_base_joint_link_joint0'>0 0 0 0 -0 0</pose>
      <inertial>
        <pose>0 0 0 0 -0 0</pose>
        <mass>0.0001</mass>
        <inertia>
          <ixx>0.01</ixx>
          <ixy>0</ixy>
          <ixz>0</ixz>
          <iyy>0.01</iyy>
          <iyz>0</iyz>
          <izz>0.01</izz>
        </inertia>
      </inertial>
    </link>
    <joint name='blimp/right_elv_base_joint_link_joint1' type='revolute'>
      <pose relative_to='right_elv_base_joint_link0'>0 0 0 0 -0 0</pose>
      <parent>right_elv_base_joint_link0</parent>
      <child>right_elv_base_joint_link1</child>
      <axis>
        <xyz>0 1 0</xyz>
        <limit>
          <lower>0</lower>
          <upper>0</upper>
          <effort>-1</effort>
          <velocity>-1</velocity>
        </limit>
        <dynamics>
          <damping>0.5</damping>
          <friction>0</friction>
          <spring_reference>0</spring_reference>
          <spring_stiffness>0</spring_stiffness>
        </dynamics>
      </axis>
      <physics>
        <ode>
          <limit>
            <cfm>0.2</cfm>
            <erp>0.2</erp>
          </limit>
        </ode>
      </physics>
    </joint>
    <link name='right_elv_base_joint_link1'>
      <pose relative_to='blimp/right_elv_base_joint_link_joint1'>0 0 0 0 -0 0</pose>
      <inertial>
        <pose>0 0 0 0 -0 0</pose>
        <mass>0.0001</mass>
        <inertia>
          <ixx>0.01</ixx>
          <ixy>0</ixy>
          <ixz>0</ixz>
          <iyy>0.01</iyy>
          <iyz>0</iyz>
          <izz>0.01</izz>
        </inertia>
      </inertial>
    </link>
    <joint name='blimp/right_elv_base_joint_link_joint' type='revolute'>
      <pose relative_to='right_elv_base_joint_link1'>0 0 0 0 -0 0</pose>
      <parent>right_elv_base_joint_link1</parent>
      <child>right_elv_base_joint_link</child>
      <axis>
        <xyz>0 0 1</xyz>
        <limit>
          <lower>0</lower>
          <upper>0</upper>
          <effort>-1</effort>
          <velocity>-1</velocity>
        </limit>
        <dynamics>
          <damping>0.5</damping>
          <friction>0</friction>
          <spring_reference>0</spring_reference>
          <spring_stiffness>0</spring_stiffness>
        </dynamics>
      </axis>
      <physics>
        <ode>
          <limit>
            <cfm>0.1</cfm>
            <erp>0.2</erp>
          </limit>
        </ode>
      </physics>
    </joint>
    <link name='right_elv_base_joint_link'>
      <pose relative_to='blimp/right_elv_base_joint_link_joint'>0 0 0 0 -0 0</pose>
      <inertial>
        <pose>0 0 0 0 -0 0</pose>
        <mass>0.0001</mass>
        <inertia>
          <ixx>0.01</ixx>
          <ixy>0</ixy>
          <ixz>0</ixz>
          <iyy>0.01</iyy>
          <iyz>0</iyz>
          <izz>0.01</izz>
        </inertia>
      </inertial>
      <visual name='right_elv_base_joint_link_visual'>
        <pose>0 0 0 0 -0 0</pose>
        <geometry>
          <cylinder>
            <length>0.3</length>
            <radius>0.01</radius>
          </cylinder>
        </geometry>
      </visual>
    </link>
    <joint name='blimp_body_right_elv_part1_joint' type='revolute'>
      <pose relative_to='right_elv_base_joint_link'>0 0 -0.24 0 -0 0</pose>
      <parent>right_elv_base_joint_link</parent>
      <child>right_elv_part1_link</child>
      <axis>
        <xyz>1 0 0</xyz>
        <limit>
          <lower>0</lower>
          <upper>0</upper>
          <effort>1000</effort>
          <velocity>1000</velocity>
        </limit>
        <dynamics>
          <spring_reference>0</spring_reference>
          <spring_stiffness>0</spring_stiffness>
        </dynamics>
      </axis>
    </joint>
    <link name='right_elv_part1_link'>
      <pose relative_to='blimp_body_right_elv_part1_joint'>0 0 0 0 -0 0</pose>
      <inertial>
        <pose>0 0 0 0 -0 0</pose>
        <mass>0.58</mass>
        <inertia>
          <ixx>0.0111553</ixx>
          <ixy>0</ixy>
          <ixz>0</ixz>
          <iyy>0.0257568</iyy>
          <iyz>0</iyz>
          <izz>0.0146402</izz>
        </inertia>
      </inertial>
      <collision name='right_elv_part1_link_collision'>
        <pose>0 0 0 0 -0 0</pose>
        <geometry>
          <mesh>
            <scale>1 1 1</scale>
            <uri>model://rblimp/meshes/blimp_fin/blimp_top_rud_part1_v3.dae</uri>
          </mesh>
        </geometry>
        <surface>
          <contact>
            <ode>
              <kp>1e+06</kp>
              <kd>1e+06</kd>
            </ode>
          </contact>
          <friction>
            <ode>
              <mu>10</mu>
              <mu2>10</mu2>
            </ode>
          </friction>
        </surface>
      </collision>
      <visual name='right_elv_part1_link_visual'>
        <pose>0 0 0 0 -0 0</pose>
        <geometry>
          <mesh>
            <scale>1 1 1</scale>
            <uri>model://rblimp/meshes/blimp_fin/blimp_top_rud_part1_v3.dae</uri>
          </mesh>
        </geometry>
      </visual>
    </link>
    <joint name='right_elv_part1_right_elv_joint_link_joint' type='revolute'>
      <pose relative_to='right_elv_part1_link'>-0.28 0 0 0 -0 0</pose>
      <parent>right_elv_part1_link</parent>
      <child>right_elv_joint_link</child>
      <axis>
        <xyz>0 0 -1</xyz>
        <limit>
          <lower>-1.0472</lower>
          <upper>1.0472</upper>
          <effort>500</effort>
          <velocity>2</velocity>
        </limit>
        <dynamics>
          <spring_reference>0</spring_reference>
          <spring_stiffness>0</spring_stiffness>
        </dynamics>
      </axis>
    </joint>
    <link name='right_elv_joint_link'>
      <pose relative_to='right_elv_part1_right_elv_joint_link_joint'>0 0 0 0 -0 0</pose>
      <inertial>
        <pose>-0.125 0 0 0 -0 0</pose>
        <mass>0.113</mass>
        <inertia>
          <ixx>0.00217337</ixx>
          <ixy>0</ixy>
          <ixz>0</ixz>
          <iyy>0.0030171</iyy>
          <iyz>0</iyz>
          <izz>0.000851266</izz>
        </inertia>
      </inertial>
      <collision name='right_elv_joint_link_fixed_joint_lump__right_elv_part2_link_collision'>
        <pose>-0.125 0 0 0 -0 0</pose>
        <geometry>
          <mesh>
            <scale>1 1 1</scale>
            <uri>model://rblimp/meshes/blimp_fin/blimp_top_rud_part2_v5.dae</uri>
          </mesh>
        </geometry>
        <surface>
          <contact>
            <ode>
              <kp>1e+06</kp>
              <kd>1e+06</kd>
            </ode>
          </contact>
          <friction>
            <ode>
              <mu>10</mu>
              <mu2>10</mu2>
            </ode>
          </friction>
        </surface>
      </collision>
      <visual name='right_elv_joint_link_visual'>
        <pose>0 0 0 0 -0 0</pose>
        <geometry>
          <cylinder>
            <length>0.3</length>
            <radius>0.01</radius>
          </cylinder>
        </geometry>
      </visual>
      <visual name='right_elv_joint_link_fixed_joint_lump__right_elv_part2_link_visual_1'>
        <pose>-0.125 0 0 0 -0 0</pose>
        <geometry>
          <mesh>
            <scale>1 1 1</scale>
            <uri>model://rblimp/meshes/blimp_fin/blimp_top_rud_part2_v5.dae</uri>
          </mesh>
        </geometry>
      </visual>
    </link>
    <joint name='blimp/top_rud_base_joint_link_joint0' type='revolute'>
      <pose relative_to='blimp_body_link'>-0.59 0 -1.5 3.14159 -1.5708 0</pose>
      <parent>blimp_body_link</parent>
      <!-- <child>top_rud_base_joint_link0</child> -->
      <child>top_rud_part1_link</child>
      <axis>
        <xyz>1 0 0</xyz>
        <limit>
          <lower>0</lower>
          <upper>0</upper>
          <effort>-1</effort>
          <velocity>-1</velocity>
        </limit>
        <dynamics>
          <damping>0.5</damping>
          <friction>0</friction>
          <spring_reference>0</spring_reference>
          <spring_stiffness>0</spring_stiffness>
        </dynamics>
      </axis>
      <physics>
        <ode>
          <limit>
            <cfm>1</cfm>
            <erp>0.2</erp>
          </limit>
        </ode>
      </physics>
    </joint>
    <link name='top_rud_base_joint_link0'>
      <pose relative_to='blimp/top_rud_base_joint_link_joint0'>0 0 0 0 -0 0</pose>
      <inertial>
        <pose>0 0 0 0 -0 0</pose>
        <mass>0.0001</mass>
        <inertia>
          <ixx>0.01</ixx>
          <ixy>0</ixy>
          <ixz>0</ixz>
          <iyy>0.01</iyy>
          <iyz>0</iyz>
          <izz>0.01</izz>
        </inertia>
      </inertial>
    </link>
    <joint name='blimp/top_rud_base_joint_link_joint1' type='revolute'>
      <pose relative_to='top_rud_base_joint_link0'>0 0 0 0 -0 0</pose>
      <parent>top_rud_base_joint_link0</parent>
      <child>top_rud_base_joint_link1</child>
      <axis>
        <xyz>0 1 0</xyz>
        <limit>
          <lower>0</lower>
          <upper>0</upper>
          <effort>-1</effort>
          <velocity>-1</velocity>
        </limit>
        <dynamics>
          <damping>0.5</damping>
          <friction>0</friction>
          <spring_reference>0</spring_reference>
          <spring_stiffness>0</spring_stiffness>
        </dynamics>
      </axis>
      <physics>
        <ode>
          <limit>
            <cfm>0.2</cfm>
            <erp>0.2</erp>
          </limit>
        </ode>
      </physics>
    </joint>
    <link name='top_rud_base_joint_link1'>
      <pose relative_to='blimp/top_rud_base_joint_link_joint1'>0 0 0 0 -0 0</pose>
      <inertial>
        <pose>0 0 0 0 -0 0</pose>
        <mass>0.0001</mass>
        <inertia>
          <ixx>0.01</ixx>
          <ixy>0</ixy>
          <ixz>0</ixz>
          <iyy>0.01</iyy>
          <iyz>0</iyz>
          <izz>0.01</izz>
        </inertia>
      </inertial>
    </link>
    <joint name='blimp/top_rud_base_joint_link_joint' type='revolute'>
      <pose relative_to='top_rud_base_joint_link1'>0 0 0 0 -0 0</pose>
      <parent>top_rud_base_joint_link1</parent>
      <child>top_rud_base_joint_link</child>
      <axis>
        <xyz>0 0 1</xyz>
        <limit>
          <lower>0</lower>
          <upper>0</upper>
          <effort>-1</effort>
          <velocity>-1</velocity>
        </limit>
        <dynamics>
          <damping>0.5</damping>
          <friction>0</friction>
          <spring_reference>0</spring_reference>
          <spring_stiffness>0</spring_stiffness>
        </dynamics>
      </axis>
      <physics>
        <ode>
          <limit>
            <cfm>0.1</cfm>
            <erp>0.2</erp>
          </limit>
        </ode>
      </physics>
    </joint>
    <link name='top_rud_base_joint_link'>
      <pose relative_to='blimp/top_rud_base_joint_link_joint'>0 0 0 0 -0 0</pose>
      <inertial>
        <pose>0 0 0 0 -0 0</pose>
        <mass>0.0001</mass>
        <inertia>
          <ixx>0.01</ixx>
          <ixy>0</ixy>
          <ixz>0</ixz>
          <iyy>0.01</iyy>
          <iyz>0</iyz>
          <izz>0.01</izz>
        </inertia>
      </inertial>
      <visual name='top_rud_base_joint_link_visual'>
        <pose>0 0 0 0 -0 0</pose>
        <geometry>
          <cylinder>
            <length>0.3</length>
            <radius>0.01</radius>
          </cylinder>
        </geometry>
      </visual>
    </link>
    <joint name='blimp_body_top_rud_part1_joint' type='revolute'>
      <pose relative_to='top_rud_base_joint_link'>0 0 -0.24 0 -0 0</pose>
      <parent>top_rud_base_joint_link</parent>
      <child>top_rud_part1_link</child>
      <axis>
        <xyz>1 0 0</xyz>
        <limit>
          <lower>0</lower>
          <upper>0</upper>
          <effort>1000</effort>
          <velocity>1000</velocity>
        </limit>
        <dynamics>
          <spring_reference>0</spring_reference>
          <spring_stiffness>0</spring_stiffness>
        </dynamics>
      </axis>
    </joint>
    <link name='top_rud_part1_link'>
      <pose relative_to='blimp_body_top_rud_part1_joint'>0 0 0 0 -0 0</pose>
      <inertial>
        <pose>0 0 0 0 -0 0</pose>
        <mass>0.58</mass>
        <inertia>
          <ixx>0.0111553</ixx>
          <ixy>0</ixy>
          <ixz>0</ixz>
          <iyy>0.0257568</iyy>
          <iyz>0</iyz>
          <izz>0.0146402</izz>
        </inertia>
      </inertial>
      <collision name='top_rud_part1_link_collision'>
        <pose>0 0 0 0 -0 0</pose>
        <geometry>
          <mesh>
            <scale>1 1 1</scale>
            <uri>model://rblimp/meshes/blimp_fin/blimp_top_rud_part1_v3.dae</uri>
          </mesh>
        </geometry>
        <surface>
          <contact>
            <ode>
              <kp>1e+06</kp>
              <kd>1e+06</kd>
            </ode>
          </contact>
          <friction>
            <ode>
              <mu>10</mu>
              <mu2>10</mu2>
            </ode>
          </friction>
        </surface>
      </collision>
      <visual name='top_rud_part1_link_visual'>
        <pose>0 0 0 0 -0 0</pose>
        <geometry>
          <mesh>
            <scale>1 1 1</scale>
            <uri>model://rblimp/meshes/blimp_fin/blimp_top_rud_part1_v3.dae</uri>
          </mesh>
        </geometry>
      </visual>
    </link>

    <include>
      <uri>model://gps</uri>
      <pose>0 0 0 0 0 0</pose>
      <name>gps</name>
    </include>
    <joint name='gps_joint' type='fixed'>
      <child>gps::link</child>
      <parent>base_link</parent>
    </joint>

    <!-- <joint name='imutail_joint' type='revolute'>
      <pose relative_to='top_rud_part1_link'>0 0 0 3.14159 -0 0</pose>
      <parent>top_rud_part1_link</parent>
      <child>imutail_link</child>
      <axis>
        <xyz>1 0 0</xyz>
        <limit>
          <lower>0</lower>
          <upper>0</upper>
          <effort>0</effort>
          <velocity>0</velocity>
        </limit>
        <dynamics>
          <spring_reference>0</spring_reference>
          <spring_stiffness>0</spring_stiffness>
        </dynamics>
      </axis>
    </joint>
    <link name='imutail_link'>
      <pose relative_to='imutail_joint'>0 0 0 0 -0 0</pose>
      <inertial>
        <pose>0 0 0 0 -0 0</pose>
        <mass>1e-05</mass>
        <inertia>
          <ixx>1e-05</ixx>
          <ixy>0</ixy>
          <ixz>0</ixz>
          <iyy>1e-05</iyy>
          <iyz>0</iyz>
          <izz>1e-05</izz>
        </inertia>
      </inertial>
    </link> -->
    <!-- <joint name='odometry_sensortail_joint' type='revolute'>
      <pose relative_to='top_rud_part1_link'>0 0 0 3.14159 -0 0</pose>
      <parent>top_rud_part1_link</parent>
      <child>odometry_sensortail_link</child>
      <axis>
        <xyz>1 0 0</xyz>
        <limit>
          <lower>0</lower>
          <upper>0</upper>
          <effort>0</effort>
          <velocity>0</velocity>
        </limit>
        <dynamics>
          <spring_reference>0</spring_reference>
          <spring_stiffness>0</spring_stiffness>
        </dynamics>
      </axis>
    </joint> -->
    <!-- <link name='odometry_sensortail_link'>
      <pose relative_to='odometry_sensortail_joint'>0 0 0 0 -0 0</pose>
      <inertial>
        <pose>0 0 0 0 -0 0</pose>
        <mass>1e-05</mass>
        <inertia>
          <ixx>1e-05</ixx>
          <ixy>0</ixy>
          <ixz>0</ixz>
          <iyy>1e-05</iyy>
          <iyz>0</iyz>
          <izz>1e-05</izz>
        </inertia>
      </inertial>
    </link> -->
    <joint name='top_rud_part1_top_rud_joint_link_joint' type='revolute'>
      <pose relative_to='top_rud_part1_link'>-0.28 0 0 0 -0 0</pose>
      <parent>top_rud_part1_link</parent>
      <child>top_rud_joint_link</child>
      <axis>
        <xyz>0 0 -1</xyz>
        <limit>
          <lower>-1.0472</lower>
          <upper>1.0472</upper>
          <effort>500</effort>
          <velocity>2</velocity>
        </limit>
        <dynamics>
          <spring_reference>0</spring_reference>
          <spring_stiffness>0</spring_stiffness>
        </dynamics>
      </axis>
    </joint>
    <link name='top_rud_joint_link'>
      <pose relative_to='top_rud_part1_top_rud_joint_link_joint'>0 0 0 0 -0 0</pose>
      <inertial>
        <pose>-0.125 0 0 0 -0 0</pose>
        <mass>0.113</mass>
        <inertia>
          <ixx>0.00217337</ixx>
          <ixy>0</ixy>
          <ixz>0</ixz>
          <iyy>0.0030171</iyy>
          <iyz>0</iyz>
          <izz>0.000851266</izz>
        </inertia>
      </inertial>
      <collision name='top_rud_joint_link_fixed_joint_lump__top_rud_part2_link_collision'>
        <pose>-0.125 0 0 0 -0 0</pose>
        <geometry>
          <mesh>
            <scale>1 1 1</scale>
            <uri>model://rblimp/meshes/blimp_fin/blimp_top_rud_part2_v5.dae</uri>
          </mesh>
        </geometry>
        <surface>
          <contact>
            <ode>
              <kp>1e+06</kp>
              <kd>1e+06</kd>
            </ode>
          </contact>
          <friction>
            <ode>
              <mu>10</mu>
              <mu2>10</mu2>
            </ode>
          </friction>
        </surface>
      </collision>
      <visual name='top_rud_joint_link_visual'>
        <pose>0 0 0 0 -0 0</pose>
        <geometry>
          <cylinder>
            <length>0.3</length>
            <radius>0.01</radius>
          </cylinder>
        </geometry>
      </visual>
      <visual name='top_rud_joint_link_fixed_joint_lump__top_rud_part2_link_visual_1'>
        <pose>-0.125 0 0 0 -0 0</pose>
        <geometry>
          <mesh>
            <scale>1 1 1</scale>
            <uri>model://rblimp/meshes/blimp_fin/blimp_top_rud_part2_v5.dae</uri>
          </mesh>
        </geometry>
      </visual>
    </link>
    <joint name='blimp_body_aft_lift_joint' type='revolute'>
      <pose relative_to='blimp_body_link'>0 0 -0.3 1.5708 -1.5708 0</pose>
      <parent>blimp_body_link</parent>
      <child>aft_lift_joint_link</child>
      <axis>
        <xyz>1 0 0</xyz>
        <limit>
          <lower>0</lower>
          <upper>0</upper>
          <effort>1000</effort>
          <velocity>1000</velocity>
        </limit>
        <dynamics>
          <spring_reference>0</spring_reference>
          <spring_stiffness>0</spring_stiffness>
        </dynamics>
      </axis>
    </joint>
    <link name='aft_lift_joint_link'>
      <pose relative_to='blimp_body_aft_lift_joint'>0 0 0 0 -0 0</pose>
      <inertial>
        <pose>0 0 0 0 -0 0</pose>
        <mass>0.001</mass>
        <inertia>
          <ixx>0</ixx>
          <ixy>0</ixy>
          <ixz>0</ixz>
          <iyy>0</iyy>
          <iyz>0</iyz>
          <izz>0</izz>
        </inertia>
      </inertial>
      <visual name='aft_lift_joint_link_visual'>
        <pose>0 0 0 0 -0 0</pose>
        <geometry>
          <cylinder>
            <length>0.3</length>
            <radius>0.01</radius>
          </cylinder>
        </geometry>
      </visual>
    </link>
    <joint name='blimp_body_forward_lift_joint' type='revolute'>
      <pose relative_to='blimp_body_link'>0 0 2 1.5708 -1.5708 0</pose>
      <parent>blimp_body_link</parent>
      <child>forward_lift_joint_link</child>
      <axis>
        <xyz>1 0 0</xyz>
        <limit>
          <lower>0</lower>
          <upper>0</upper>
          <effort>1000</effort>
          <velocity>1000</velocity>
        </limit>
        <dynamics>
          <spring_reference>0</spring_reference>
          <spring_stiffness>0</spring_stiffness>
        </dynamics>
      </axis>
    </joint>
    <link name='forward_lift_joint_link'>
      <pose relative_to='blimp_body_forward_lift_joint'>0 0 0 0 -0 0</pose>
      <inertial>
        <pose>0 0 0 0 -0 0</pose>
        <mass>0.001</mass>
        <inertia>
          <ixx>0</ixx>
          <ixy>0</ixy>
          <ixz>0</ixz>
          <iyy>0</iyy>
          <iyz>0</iyz>
          <izz>0</izz>
        </inertia>
      </inertial>
      <visual name='forward_lift_joint_link_visual'>
        <pose>0 0 0 0 -0 0</pose>
        <geometry>
          <cylinder>
            <length>0.3</length>
            <radius>0.01</radius>
          </cylinder>
        </geometry>
      </visual>
    </link>
    <joint name='blimp_body_front_ballast_joint' type='revolute'>
      <pose relative_to='blimp_body_link'>0 0 2.5 0 -0 0</pose>
      <parent>blimp_body_link</parent>
      <child>front_ballast_joint_link</child>
      <axis>
        <xyz>1 0 0</xyz>
        <limit>
          <lower>0</lower>
          <upper>0</upper>
          <effort>1000</effort>
          <velocity>1000</velocity>
        </limit>
        <dynamics>
          <spring_reference>0</spring_reference>
          <spring_stiffness>0</spring_stiffness>
        </dynamics>
      </axis>
    </joint>
    <link name='front_ballast_joint_link'>
      <pose relative_to='blimp_body_front_ballast_joint'>0 0 0 0 -0 0</pose>
      <inertial>
        <pose>0 0 0 0 -0 0</pose>
        <mass>0.6</mass>
        <inertia>
          <ixx>0.00014</ixx>
          <ixy>0</ixy>
          <ixz>0</ixz>
          <iyy>0.00014</iyy>
          <iyz>0</iyz>
          <izz>3e-05</izz>
        </inertia>
      </inertial>
      <collision name='front_ballast_joint_link_collision'>
        <pose>0 0 0 0 -0 0</pose>
        <geometry>
          <cylinder>
            <length>0.05</length>
            <radius>0.01</radius>
          </cylinder>
        </geometry>
        <surface>
          <contact>
            <ode>
              <kp>1e+06</kp>
              <kd>1e+06</kd>
            </ode>
          </contact>
          <friction>
            <ode>
              <mu>10</mu>
              <mu2>10</mu2>
            </ode>
          </friction>
        </surface>
      </collision>
      <visual name='front_ballast_joint_link_visual'>
        <pose>0 0 0 0 -0 0</pose>
        <geometry>
          <cylinder>
            <length>0.05</length>
            <radius>0.01</radius>
          </cylinder>
        </geometry>
      </visual>
    </link>
    <joint name='base_stick_joint' type='revolute'>
      <pose relative_to='base_link'>-0.08 0 0.03 1.5708 -0 0</pose>
      <parent>base_link</parent>
      <child>stick_link</child>
      <axis>
        <!-- <xyz>0 1 0</xyz> -->
        <xyz>0 0 -1</xyz>
        <limit>
          <!-- <lower>-3.141592653589793</lower> -->
          <!-- <upper>3.141592653589793</upper> -->
          <!-- <lower>-1.5707963267948966</lower> -->
          <lower>0</lower>
          <!-- <upper>1.5707963267948966</upper> -->
          <lower>3.141592653589793</lower>
          <!-- <lower>-1.74533</lower> -->
          <!-- <upper>1.74533</upper> -->
          <!-- <effort>10000</effort> -->
          <effort>10</effort>
          <velocity>2</velocity>
        </limit>
        <!-- <physics>
          <ode>
            <implicit_spring_damper>1</implicit_spring_damper>
          </ode>
        </physics> -->
        <dynamics>
          <spring_reference>0</spring_reference>
          <spring_stiffness>0</spring_stiffness>
        </dynamics>
      </axis>
    </joint>
    <link name='stick_link'>
      <pose relative_to='base_stick_joint'>0 0 0 0 -0 0</pose>
      <inertial>
        <pose>0 0.01173 0 0 -0 0</pose>
        <mass>1.705</mass>
        <inertia>
          <ixx>0.195486</ixx>
          <ixy>0</ixy>
          <ixz>0</ixz>
          <iyy>0.216802</iyy>
          <iyz>6.07153e-18</iyz>
          <izz>0.0218319</izz>
        </inertia>
      </inertial>
      <collision name='stick_link_collision'>
        <pose>0 0 0 0 -0 0</pose>
        <geometry>
          <mesh>
            <scale>1 1 1</scale>
            <uri>model://rblimp/meshes/blimp_wing/blimp_stick_v2.dae</uri>
          </mesh>
        </geometry>
        <surface>
          <contact>
            <ode>
              <kp>1e+06</kp>
              <kd>1e+06</kd>
            </ode>
          </contact>
          <friction>
            <ode>
              <mu>10</mu>
              <mu2>10</mu2>
            </ode>
          </friction>
        </surface>
      </collision>
      <collision name='stick_link_fixed_joint_lump__left_wing_link_collision_1'>
        <pose>0 0.02 -0.375 -1.5708 0 0</pose>
        <geometry>
          <mesh>
            <scale>1 1 1</scale>
            <uri>model://rblimp/meshes/blimp_wing/blimp_wing_v2.dae</uri>
          </mesh>
        </geometry>
        <surface>
          <contact>
            <ode>
              <kp>1e+06</kp>
              <kd>1e+06</kd>
            </ode>
          </contact>
          <friction>
            <ode>
              <mu>10</mu>
              <mu2>10</mu2>
            </ode>
          </friction>
        </surface>
      </collision>
      <collision name='stick_link_fixed_joint_lump__right_wing_link_collision_2'>
        <pose>0 0.02 0.375 -1.5708 0 0</pose>
        <geometry>
          <mesh>
            <scale>1 1 1</scale>
            <uri>model://rblimp/meshes/blimp_wing/blimp_wing_v2.dae</uri>
          </mesh>
        </geometry>
        <surface>
          <contact>
            <ode>
              <kp>1e+06</kp>
              <kd>1e+06</kd>
            </ode>
          </contact>
          <friction>
            <ode>
              <mu>10</mu>
              <mu2>10</mu2>
            </ode>
          </friction>
        </surface>
      </collision>
      <visual name='stick_link_visual'>
        <pose>0 0 0 0 -0 0</pose>
        <geometry>
          <mesh>
            <scale>1 1 1</scale>
            <uri>model://rblimp/meshes/blimp_wing/blimp_stick_v2.dae</uri>
          </mesh>
        </geometry>
      </visual>
      <visual name='stick_link_fixed_joint_lump__left_wing_link_visual_1'>
        <pose>0 0.02 -0.375 -1.5708 0 0</pose>
        <geometry>
          <mesh>
            <scale>1 1 1</scale>
            <uri>model://rblimp/meshes/blimp_wing/blimp_wing_v2.dae</uri>
          </mesh>
        </geometry>
      </visual>
      <visual name='stick_link_fixed_joint_lump__right_wing_link_visual_2'>
        <pose>0 0.02 0.375 -1.5708 0 0</pose>
        <geometry>
          <mesh>
            <scale>1 1 1</scale>
            <uri>model://rblimp/meshes/blimp_wing/blimp_wing_v2.dae</uri>
          </mesh>
        </geometry>
      </visual>
    </link>

    <joint name='stick_left_blade_joint' type='revolute'>
      <pose relative_to='stick_link'>0 0.025 -0.375 -1.5708 0 0</pose>
      <parent>stick_link</parent>
      <child>left_blade

      </child>
      <axis>
        <xyz>0 0 1</xyz>
        <limit>
          <lower>-1e+16</lower>
          <upper>1e+16</upper>
        </limit>
        <dynamics>
          <spring_reference>0</spring_reference>
          <spring_stiffness>0</spring_stiffness>
        </dynamics>
      </axis>
    </joint>

    <link name='left_blade'>
      <pose relative_to='stick_left_blade_joint'>0 0 0 0 -0 0</pose>
      <inertial>
        <pose>0 0 0 1.5708 -0 0</pose>
        <mass>0.05</mass>
        <inertia>
          <ixx>0.000635</ixx>
          <ixy>0</ixy>
          <ixz>0</ixz>
          <iyy>0.000635</iyy>
          <iyz>0</iyz>
          <izz>2.5e-06</izz>
        </inertia>
      </inertial>
      <collision name='left_blade_collision'>
        <pose>0 0 0 1.5708 -0 0</pose>
        <geometry>
          <mesh>
            <scale>1 1 1</scale>
            <uri>model://rblimp/meshes/blimp_propeller/blimp_left_propeller_ccw_v3.dae</uri>
            <!-- <uri>model://cloudship/meshes/prop_ccw.dae</uri> -->
          </mesh>
        </geometry>
        <surface>
          <contact>
            <ode>
              <kp>1e+06</kp>
              <kd>1e+06</kd>
            </ode>
          </contact>
          <friction>
            <ode>
              <mu>10</mu>
              <mu2>10</mu2>
            </ode>
          </friction>
        </surface>
      </collision>
      <visual name='left_blade_link_visual'>
        <pose>0 0 0 1.5708 -0 0</pose>
        <geometry>
          <mesh>
            <scale>1 1 1</scale>
            <uri>model://rblimp/meshes/blimp_propeller/blimp_left_propeller_ccw_v3.dae</uri>
            <!-- <uri>model://cloudship/meshes/prop_ccw.dae</uri> -->
          </mesh>
        </geometry>
      </visual>
    </link>

    <joint name='stick_right_blade_joint' type='revolute'>
      <pose relative_to='stick_link'>0 0.025 0.375 -1.5708 0 0</pose>
      <parent>stick_link</parent>
      <child>right_blade</child>
      <axis>
        <xyz>0 0 1</xyz>
        <limit>
          <lower>-1e+16</lower>
          <upper>1e+16</upper>
        </limit>
        <dynamics>
          <spring_reference>0</spring_reference>
          <spring_stiffness>0</spring_stiffness>
        </dynamics>
      </axis>
    </joint>

    <link name='right_blade'>
      <pose relative_to='stick_right_blade_joint'>0 0 0 0 -0 0</pose>
      <inertial>
        <pose>0 0 0 1.5708 -0 0</pose>
        <mass>0.05</mass>
        <inertia>
          <ixx>0.000635</ixx>
          <ixy>0</ixy>
          <ixz>0</ixz>
          <iyy>0.000635</iyy>
          <iyz>0</iyz>
          <izz>2.5e-06</izz>
        </inertia>
      </inertial>
      <collision name='right_blade_collision'>
        <pose>0 0 0 1.5708 -0 0</pose>
        <geometry>
          <mesh>
            <scale>1 1 1</scale>
            <uri>model://rblimp/meshes/blimp_propeller/blimp_right_propeller_cw_v3.dae</uri>
            <!-- <uri>model://cloudship/meshes/prop_cw.dae</uri> -->
          </mesh>
        </geometry>
        <surface>
          <contact>
            <ode>
              <kp>1e+06</kp>
              <kd>1e+06</kd>
            </ode>
          </contact>
          <friction>
            <ode>
              <mu>10</mu>
              <mu2>10</mu2>
            </ode>
          </friction>
        </surface>
      </collision>
      <visual name='right_blade_visual'>
        <pose>0 0 0 1.5708 -0 0</pose>
        <geometry>
          <mesh>
            <scale>1 1 1</scale>
            <uri>model://rblimp/meshes/blimp_propeller/blimp_right_propeller_cw_v3.dae</uri>
            <!-- <uri>model://cloudship/meshes/prop_cw.dae</uri> -->
          </mesh>
        </geometry>
      </visual>
    </link>
    <joint name='imugt_joint' type='revolute'>
      <pose relative_to='base_link'>0 0 0 0 -0 0</pose>
      <parent>base_link</parent>
      <child>imugt_link</child>
      <axis>
        <xyz>1 0 0</xyz>
        <limit>
          <lower>0</lower>
          <upper>0</upper>
          <effort>0</effort>
          <velocity>0</velocity>
        </limit>
        <dynamics>
          <spring_reference>0</spring_reference>
          <spring_stiffness>0</spring_stiffness>
        </dynamics>
      </axis>
    </joint>
    <link name='imugt_link'>
      <pose relative_to='imugt_joint'>0 0 0 0 -0 0</pose>
      <inertial>
        <pose>0 0 0 0 -0 0</pose>
        <mass>1e-05</mass>
        <inertia>
          <ixx>1e-05</ixx>
          <ixy>0</ixy>
          <ixz>0</ixz>
          <iyy>1e-05</iyy>
          <iyz>0</iyz>
          <izz>1e-05</izz>
        </inertia>
      </inertial>
    </link>
    <joint name='odometry_sensorgt_joint' type='revolute'>
      <pose relative_to='base_link'>0 0 0 0 -0 0</pose>
      <parent>base_link</parent>
      <child>odometry_sensorgt_link</child>
      <axis>
        <xyz>1 0 0</xyz>
        <limit>
          <lower>0</lower>
          <upper>0</upper>
          <effort>0</effort>
          <velocity>0</velocity>
        </limit>
        <dynamics>
          <spring_reference>0</spring_reference>
          <spring_stiffness>0</spring_stiffness>
        </dynamics>
      </axis>
    </joint>
    <link name='odometry_sensorgt_link'>
      <pose relative_to='odometry_sensorgt_joint'>0 0 0 0 -0 0</pose>
      <inertial>
        <pose>0 0 0 0 -0 0</pose>
        <mass>1e-05</mass>
        <inertia>
          <ixx>1e-05</ixx>
          <ixy>0</ixy>
          <ixz>0</ixz>
          <iyy>1e-05</iyy>
          <iyz>0</iyz>
          <izz>1e-05</izz>
        </inertia>
      </inertial>
    </link>


    <!-- <plugin name='gazebo_ros_control' filename='libgazebo_ros_control.so'>
      <robotNamespace>/blimp</robotNamespace>
    </plugin> -->

    <!-- <plugin name='left_blade_link_motor_model' filename='librotors_gazebo_motor_model.so'> -->

    <!-- <plugin name='odometry_sensorgt' filename='librotors_gazebo_odometry_plugin.so'>
      <linkName>odometry_sensorgt_link</linkName>
      <robotNamespace>blimp</robotNamespace>
      <poseTopic>ground_truth/pose</poseTopic>
      <poseWithCovarianceTopic>ground_truth/pose_with_covariance</poseWithCovarianceTopic>
      <positionTopic>ground_truth/position</positionTopic>
      <transformTopic>ground_truth/transform</transformTopic>
      <odometryTopic>ground_truth/odometry</odometryTopic>
      <parentFrameId>world</parentFrameId>
      <childFrameId>base_link</childFrameId>
      <measurementDivisor>1</measurementDivisor>
      <measurementDelay>0</measurementDelay>
      <unknownDelay>0.0</unknownDelay>
      <noiseNormalPosition>0 0 0</noiseNormalPosition>
      <noiseNormalQuaternion>0 0 0</noiseNormalQuaternion>
      <noiseNormalLinearVelocity>0 0 0</noiseNormalLinearVelocity>
      <noiseNormalAngularVelocity>0 0 0</noiseNormalAngularVelocity>
      <noiseUniformPosition>0 0 0</noiseUniformPosition>
      <noiseUniformQuaternion>0 0 0</noiseUniformQuaternion>
      <noiseUniformLinearVelocity>0 0 0</noiseUniformLinearVelocity>
      <noiseUniformAngularVelocity>0 0 0</noiseUniformAngularVelocity>
    </plugin> -->

    <!-- <plugin name='rotors_gazebo_imutail_plugin' filename='librotors_gazebo_imu_plugin.so'> -->

    <!-- <plugin name='rotors_gazebo_imutail_plugin' filename='libgazebo_imu_plugin.so'>
      <robotNamespace/>
      <linkName>imutail_link</linkName>
      <imuTopic>tail/imu</imuTopic>
      <gyroscopeNoiseDensity>0.0</gyroscopeNoiseDensity>
      <gyroscopeRandomWalk>0.0</gyroscopeRandomWalk>
      <gyroscopeBiasCorrelationTime>1000.0</gyroscopeBiasCorrelationTime>
      <gyroscopeTurnOnBiasSigma>0.0</gyroscopeTurnOnBiasSigma>
      <accelerometerNoiseDensity>0.0</accelerometerNoiseDensity>
      <accelerometerRandomWalk>0.0</accelerometerRandomWalk>
      <accelerometerBiasCorrelationTime>300.0</accelerometerBiasCorrelationTime>
      <accelerometerTurnOnBiasSigma>0.0</accelerometerTurnOnBiasSigma>
    </plugin> -->

    <!-- <plugin name='odometry_sensortail' filename='librotors_gazebo_odometry_plugin.so'>
      <linkName>odometry_sensortail_link</linkName>
      <robotNamespace>blimp</robotNamespace>
      <poseTopic>tail/pose</poseTopic>
      <poseWithCovarianceTopic>tail/pose_with_covariance</poseWithCovarianceTopic>
      <positionTopic>tail/position</positionTopic>
      <transformTopic>tail/transform</transformTopic>
      <odometryTopic>tail/odometry</odometryTopic>
      <parentFrameId>world</parentFrameId>
      <childFrameId>top_rud_part1_link</childFrameId>
      <measurementDivisor>1</measurementDivisor>
      <measurementDelay>0</measurementDelay>
      <unknownDelay>0.0</unknownDelay>
      <noiseNormalPosition>0 0 0</noiseNormalPosition>
      <noiseNormalQuaternion>0 0 0</noiseNormalQuaternion>
      <noiseNormalLinearVelocity>0 0 0</noiseNormalLinearVelocity>
      <noiseNormalAngularVelocity>0 0 0</noiseNormalAngularVelocity>
      <noiseUniformPosition>0 0 0</noiseUniformPosition>
      <noiseUniformQuaternion>0 0 0</noiseUniformQuaternion>
      <noiseUniformLinearVelocity>0 0 0</noiseUniformLinearVelocity>
      <noiseUniformAngularVelocity>0 0 0</noiseUniformAngularVelocity>
    </plugin> -->

    <!-- <plugin name='forward_lift_joint_link_finliftdrag' filename='libfinliftdrag_plugin.so'>
      <robotNamespace/>
      <link_name>forward_lift_joint_link</link_name>
      <air_density>1.2041</air_density>
      <cw0>0.08</cw0>
      <cw1>0.6</cw1>
      <cw2>1.2</cw2>
      <cl0>0</cl0>
      <cl1>1.2</cl1>
      <cl2>0</cl2>
      <alpha_stall>0.3839724354387525</alpha_stall>
      <a0>0</a0>
      <area>1.57</area>
      <radial_symmetry>1</radial_symmetry>
      <upward>0 1 0</upward>
      <forward>1 0 0</forward>
      <cp>0 0 0</cp>
    </plugin> -->
    <!-- <plugin name='aft_lift_joint_link_finliftdrag' filename='libfinliftdrag_plugin.so'>
      <robotNamespace/>
      <link_name>aft_lift_joint_link</link_name>
      <air_density>1.2041</air_density>
      <cw0>0</cw0>
      <cw1>0.6</cw1>
      <cw2>1.2</cw2>
      <cl0>0</cl0>
      <cl1>1.2</cl1>
      <cl2>0</cl2>
      <alpha_stall>0.3839724354387525</alpha_stall>
      <a0>0</a0>
      <area>1.57</area>
      <radial_symmetry>1</radial_symmetry>
      <upward>0 1 0</upward>
      <forward>1 0 0</forward>
      <cp>0 0 0</cp>
    </plugin> -->
    <!-- <plugin name='bot_rud_part1_link_finliftdrag' filename='libfinliftdrag_plugin.so'>
      <robotNamespace/>
      <link_name>bot_rud_part1_link</link_name>
      <air_density>1.2041</air_density>
      <cw0>0.075</cw0>
      <cw1>0.6375</cw1>
      <cw2>1.2</cw2>
      <cl0>0</cl0>
      <cl1>0.6</cl1>
      <cl2>0</cl2>
      <alpha_stall>0.3839724354387525</alpha_stall>
      <a0>0</a0>
      <area>0.16</area>
      <radial_symmetry>0</radial_symmetry>
      <upward>0 -1 0</upward>
      <forward>1 0 0</forward>
      <cp>0 0 0</cp>
    </plugin>
    <plugin name='top_rud_part1_link_finliftdrag' filename='libfinliftdrag_plugin.so'>
      <robotNamespace/>
      <link_name>top_rud_part1_link</link_name>
      <air_density>1.2041</air_density>
      <cw0>0.075</cw0>
      <cw1>0.6375</cw1>
      <cw2>1.2</cw2>
      <cl0>0</cl0>
      <cl1>0.6</cl1>
      <cl2>0</cl2>
      <alpha_stall>0.3839724354387525</alpha_stall>
      <a0>0</a0>
      <area>0.16</area>
      <airspeedPubTopic>tail/indicatedAirspeed</airspeedPubTopic>
      <radial_symmetry>0</radial_symmetry>
      <upward>0 1 0</upward>
      <forward>1 0 0</forward>
      <cp>0 0 0</cp>
    </plugin> -->
    <!-- <plugin name='left_elv_part1_link_finliftdrag' filename='libfinliftdrag_plugin.so'>
      <robotNamespace/>
      <link_name>left_elv_part1_link</link_name>
      <air_density>1.2041</air_density>
      <cw0>0.075</cw0>
      <cw1>0.6375</cw1>
      <cw2>1.2</cw2>
      <cl0>0</cl0>
      <cl1>0.6</cl1>
      <cl2>0</cl2>
      <alpha_stall>0.3839724354387525</alpha_stall>
      <a0>0</a0>
      <area>0.16</area>
      <radial_symmetry>0</radial_symmetry>
      <upward>0 1 0</upward>
      <forward>1 0 0</forward>
      <cp>0 0 0</cp>
    </plugin> -->
    <!-- <plugin name='right_elv_part1_link_finliftdrag' filename='libfinliftdrag_plugin.so'>
      <robotNamespace/>
      <link_name>right_elv_part1_link</link_name>
      <air_density>1.2041</air_density>
      <cw0>0.075</cw0>
      <cw1>0.6375</cw1>
      <cw2>1.2</cw2>
      <cl0>0</cl0>
      <cl1>0.6</cl1>
      <cl2>0</cl2>
      <alpha_stall>0.3839724354387525</alpha_stall>
      <a0>0</a0>
      <area>0.16</area>
      <radial_symmetry>0</radial_symmetry>
      <upward>0 -1 0</upward>
      <forward>1 0 0</forward>
      <cp>0 0 0</cp>
    </plugin> -->
    <!-- <plugin name='bot_rud_joint_link_finliftdrag' filename='libfinliftdrag_plugin.so'>
      <robotNamespace/>
      <link_name>bot_rud_joint_link</link_name>
      <air_density>1.2041</air_density>
      <cw0>0</cw0>
      <cw1>0.6</cw1>
      <cw2>1.2</cw2>
      <cl0>0</cl0>
      <cl1>2.0</cl1>
      <cl2>0</cl2>
      <alpha_stall>0.3839724354387525</alpha_stall>
      <a0>0</a0>
      <area>0.16</area>
      <radial_symmetry>0</radial_symmetry>
      <upward>0 -1 0</upward>
      <forward>1 0 0</forward>
      <cp>0 0 0</cp>
    </plugin> -->
    <!-- <plugin name='top_rud_joint_link_finliftdrag' filename='libfinliftdrag_plugin.so'>
      <robotNamespace/>
      <link_name>top_rud_joint_link</link_name>
      <air_density>1.2041</air_density>
      <cw0>0</cw0>
      <cw1>0.6</cw1>
      <cw2>1.2</cw2>
      <cl0>0</cl0>
      <cl1>2.0</cl1>
      <cl2>0</cl2>
      <alpha_stall>0.3839724354387525</alpha_stall>
      <a0>0</a0>
      <area>0.16</area>
      <radial_symmetry>0</radial_symmetry>
      <upward>0 1 0</upward>
      <forward>1 0 0</forward>
      <cp>0 0 0</cp>
    </plugin> -->
    <!-- <plugin name='left_elv_joint_link_finliftdrag' filename='libfinliftdrag_plugin.so'>
      <robotNamespace/>
      <link_name>left_elv_joint_link</link_name>
      <air_density>1.2041</air_density>
      <cw0>0</cw0>
      <cw1>0.6</cw1>
      <cw2>1.2</cw2>
      <cl0>0</cl0>
      <cl1>2.0</cl1>
      <cl2>0</cl2>
      <alpha_stall>0.3839724354387525</alpha_stall>
      <a0>0</a0>
      <area>0.16</area>
      <radial_symmetry>0</radial_symmetry>
      <upward>0 1 0</upward>
      <forward>1 0 0</forward>
      <cp>0 0 0</cp>
    </plugin> -->
    <!-- <plugin name='right_elv_joint_link_finliftdrag' filename='libfinliftdrag_plugin.so'>
      <robotNamespace/>
      <link_name>right_elv_joint_link</link_name>
      <air_density>1.2041</air_density>
      <cw0>0</cw0>
      <cw1>0.6</cw1>
      <cw2>1.2</cw2>
      <cl0>0</cl0>
      <cl1>2.0</cl1>
      <cl2>0</cl2>
      <alpha_stall>0.3839724354387525</alpha_stall>
      <a0>0</a0>
      <area>0.16</area>
      <radial_symmetry>0</radial_symmetry>
      <upward>0 -1 0</upward>
      <forward>1 0 0</forward>
      <cp>0 0 0</cp>
    </plugin> -->

    <!-- This plugin is good -->
    <plugin name='dynamicvolume_plugin' filename='libdynamicvolume_plugin.so'>
      <robotNamespace/>
      <linkName>blimp_body_link</linkName>
      <dynamicvolumetopic>dynamicvolumetopic</dynamicvolumetopic>
      <heliummasstopic>heliummasstopic</heliummasstopic>
      <heliummass>1.723</heliummass>
      <reference_altitude>341.0</reference_altitude>
    </plugin>
    <frame name='base_gondola_body_joint' attached_to='base_link'>
      <pose>0 0 0.1 0 -0 0</pose>
    </frame>
    <frame name='gondola_body_link' attached_to='base_gondola_body_joint'/>
    <frame name='bot_rud_joint_link_bot_rud_part2_joint' attached_to='bot_rud_joint_link'>
      <pose>-0.125 0 0 0 -0 0</pose>
    </frame>
    <frame name='bot_rud_part2_link' attached_to='bot_rud_joint_link_bot_rud_part2_joint'/>
    <frame name='left_elv_joint_link_left_elv_part2_joint' attached_to='left_elv_joint_link'>
      <pose>-0.125 0 0 0 -0 0</pose>
    </frame>
    <frame name='left_elv_part2_link' attached_to='left_elv_joint_link_left_elv_part2_joint'/>
    <frame name='right_elv_joint_link_right_elv_part2_joint' attached_to='right_elv_joint_link'>
      <pose>-0.125 0 0 0 -0 0</pose>
    </frame>
    <frame name='right_elv_part2_link' attached_to='right_elv_joint_link_right_elv_part2_joint'/>
    <frame name='top_rud_joint_link_top_rud_part2_joint' attached_to='top_rud_joint_link'>
      <pose>-0.125 0 0 0 -0 0</pose>
    </frame>
    <frame name='top_rud_part2_link' attached_to='top_rud_joint_link_top_rud_part2_joint'/>
    <frame name='base_gondola_left_support_joint' attached_to='base_link'>
      <pose>0 0.1 -0.085 0.4 -0 0</pose>
    </frame>
    <frame name='gondola_left_support_link' attached_to='base_gondola_left_support_joint'/>
    <frame name='base_gondola_right_support_joint' attached_to='base_link'>
      <pose>0 -0.1 -0.085 0.4 0 3.14159</pose>
    </frame>
    <frame name='gondola_right_support_link' attached_to='base_gondola_right_support_joint'/>
    <frame name='stick_left_wing_joint' attached_to='stick_link'>
      <pose>0 0.02 -0.375 -1.5708 0 0</pose>
    </frame>
    <frame name='left_wing_link' attached_to='stick_left_wing_joint'/>
    <frame name='stick_right_wing_joint' attached_to='stick_link'>
      <pose>0 0.02 0.375 -1.5708 0 0</pose>
    </frame>
    <frame name='right_wing_link' attached_to='stick_right_wing_joint'/>

    <plugin name='magnetometer_plugin' filename='libgazebo_magnetometer_plugin.so'>
      <robotNamespace/>
      <pubRate>20</pubRate>
      <noiseDensity>0.0004</noiseDensity>
      <randomWalk>6.4e-06</randomWalk>
      <biasCorrelationTime>600</biasCorrelationTime>
      <magTopic>/mag</magTopic>
    </plugin>

    <plugin name='barometer_plugin' filename='libgazebo_barometer_plugin.so'>
      <robotNamespace/>
      <pubRate>10</pubRate>
      <baroTopic>/baro</baroTopic>
    </plugin>

    <plugin name='left_blade_link_motor_model' filename='libgazebo_motor_model.so'>
      <robotNamespace/>
      <jointName>stick_left_blade_joint</jointName>
      <linkName>left_blade</linkName>
      <turningDirection>ccw</turningDirection>
      <reversible>False</reversible>
      <timeConstantUp>1</timeConstantUp>
      <timeConstantUp>0.05</timeConstantUp>
      <timeConstantDown>1</timeConstantDown>
      <timeConstantDown>0.05</timeConstantDown>
      <maxRotVelocity>879.23</maxRotVelocity>
      <motorConstant>0.00371178707</motorConstant>
      <momentConstant>0.016</momentConstant>
      <commandSubTopic>/gazebo/command/motor_speed</commandSubTopic>
      <motorNumber>0</motorNumber>
      <rotorDragCoefficient>8.06428e-05</rotorDragCoefficient>
      <rollingMomentCoefficient>1e-06</rollingMomentCoefficient>
      <motorSpeedPubTopic>/motor_speed/0</motorSpeedPubTopic>
      <rotorVelocitySlowdownSim>1</rotorVelocitySlowdownSim>
      <rotorVelocitySlowdownSim>10</rotorVelocitySlowdownSim>
    </plugin>

    <plugin name='right_blade_motor_model' filename='libgazebo_motor_model.so'>
      <robotNamespace/>
      <jointName>stick_right_blade_joint</jointName>
      <linkName>right_blade</linkName>
      <turningDirection>cw</turningDirection>
      <reversible>False</reversible>
      <timeConstantUp>1</timeConstantUp>
      <timeConstantUp>0.05</timeConstantUp>
      <timeConstantDown>1</timeConstantDown>
      <timeConstantDown>0.05</timeConstantDown>
      <maxRotVelocity>879.23</maxRotVelocity>
      <motorConstant>0.00371178707</motorConstant>
      <momentConstant>0.016</momentConstant>
      <commandSubTopic>/gazebo/command/motor_speed</commandSubTopic>
      <motorNumber>1</motorNumber>
      <rotorDragCoefficient>8.06428e-05</rotorDragCoefficient>
      <rollingMomentCoefficient>1e-06</rollingMomentCoefficient>
      <motorSpeedPubTopic>/motor_speed/1</motorSpeedPubTopic>
      <rotorVelocitySlowdownSim>1</rotorVelocitySlowdownSim>
      <rotorVelocitySlowdownSim>10</rotorVelocitySlowdownSim>
    </plugin>

    <plugin name='bot_rud_motor_link_motor_model' filename='libgazebo_motor_model.so'>
      <robotNamespace/>
      <jointName>bot_rud_part1_bot_rud_motor_joint</jointName>
      <linkName>bot_rud_motor_link</linkName>
      <reversible>True</reversible>
      <turningDirection>ccw</turningDirection>
      <timeConstantUp>1</timeConstantUp>
      <timeConstantDown>1</timeConstantDown>
      <maxRotVelocity>879.23</maxRotVelocity>
      <motorConstant>0.00371178707</motorConstant>
      <momentConstant>0.016</momentConstant>
      <commandSubTopic>/gazebo/command/motor_speed</commandSubTopic>
      <motorNumber>2</motorNumber>
      <rotorDragCoefficient>8.06428e-05</rotorDragCoefficient>
      <rollingMomentCoefficient>1e-06</rollingMomentCoefficient>
      <motorSpeedPubTopic>/motor_speed/2</motorSpeedPubTopic>
      <rotorVelocitySlowdownSim>1</rotorVelocitySlowdownSim>
    </plugin>

    <!-- <plugin name='rotors_gazebo_imugt_plugin' filename='libgazebo_imu_plugin.so'>
      <robotNamespace/>
      <linkName>imugt_link</linkName>
      <imuTopic>/imu</imuTopic>
      <gyroscopeNoiseDensity>0.0</gyroscopeNoiseDensity>
      <gyroscopeRandomWalk>0.0</gyroscopeRandomWalk>
      <gyroscopeBiasCorrelationTime>1000.0</gyroscopeBiasCorrelationTime>
      <gyroscopeTurnOnBiasSigma>0.0</gyroscopeTurnOnBiasSigma>
      <accelerometerNoiseDensity>0.0</accelerometerNoiseDensity>
      <accelerometerRandomWalk>0.0</accelerometerRandomWalk>
      <accelerometerBiasCorrelationTime>300.0</accelerometerBiasCorrelationTime>
      <accelerometerTurnOnBiasSigma>0.0</accelerometerTurnOnBiasSigma>
    </plugin> -->

    <plugin name='mavlink_interface' filename='libgazebo_mavlink_interface.so'>
      <robotNamespace/>
      <imuSubTopic>/imu</imuSubTopic>
      <gpsSubTopic>rblimp/gps/link/gps</gpsSubTopic>
      <magSubTopic>/mag</magSubTopic>
      <baroSubTopic>/baro</baroSubTopic>

      <mavlink_addr>INADDR_ANY</mavlink_addr>
      <mavlink_udp_port>14560</mavlink_udp_port>
      <mavlink_tcp_port>4560</mavlink_tcp_port>
      <serialEnabled>false</serialEnabled>
      <serialDevice>/dev/ttyACM0</serialDevice>
      <baudRate>921600</baudRate>
      <qgc_addr>INADDR_ANY</qgc_addr>
      <qgc_udp_port>14550</qgc_udp_port>

      <hil_mode>false</hil_mode>
      <hil_state_level>false</hil_state_level>
      <enable_lockstep>true</enable_lockstep>
      <use_tcp>true</use_tcp>

      <send_vision_estimation>false</send_vision_estimation>
      <send_odometry>false</send_odometry>

      <control_channels>
        <channel name='left_blade'>
          <input_index>0</input_index>
          <input_offset>0</input_offset>
          <!-- <input_scaling>879.23</input_scaling> -->
          <input_scaling>100</input_scaling>
          <zero_position_disarmed>0</zero_position_disarmed>
          <zero_position_armed>0</zero_position_armed>
          <joint_control_type>velocity</joint_control_type>
          <joint_name>stick_left_blade_joint</joint_name>
        </channel>
        <channel name='right_blade'>
          <input_index>1</input_index>
          <input_offset>0</input_offset>
          <!-- <input_scaling>879.23</input_scaling> -->
          <input_scaling>100</input_scaling>
          <zero_position_disarmed>0</zero_position_disarmed>
          <zero_position_armed>0</zero_position_armed>
          <joint_control_type>velocity</joint_control_type>
          <joint_name>stick_right_blade_joint</joint_name>
        </channel>
        <channel name='bot_rud_blade'> <!--YAW -->
          <input_index>2</input_index>
          <input_offset>0</input_offset>
          <!-- <input_scaling>879.23</input_scaling> -->
          <!-- <input_scaling>0</input_scaling> -->
          <input_scaling>-60</input_scaling> <!-- '-' due to inverse orientation of motor-->
          <zero_position_disarmed>0</zero_position_disarmed>
          <zero_position_armed>0</zero_position_armed>
          <joint_control_type>velocity</joint_control_type>
          <joint_name>bot_rud_part1_bot_rud_motor_joint</joint_name>
        </channel>
        <channel name="thrusters_rod">
          <input_index>3</input_index>
          <input_offset>0</input_offset>
          <!-- <input_offset>1.5707963267948966</input_offset> -->
          <!-- <input_scaling>-20.356194490192345</input_scaling> -->
          <!-- <input_scaling>10</input_scaling> -->
          <input_scaling>1</input_scaling>
          <zero_position_disarmed>0</zero_position_disarmed>
          <zero_position_armed>1.5707963267948966</zero_position_armed>
          <joint_control_type>position</joint_control_type>
          <joint_control_pid>
            <!-- <p>40</p> -->
            <p>80</p>
            <i>0</i>
            <d>0</d>
            <iMax>0.0</iMax>
            <iMin>0.0</iMin>
            <!-- <cmdMax>2.1780972450961724</cmdMax> -->
            <cmdMax>1.1780972450961724</cmdMax>
            <cmdMin>-1.1780972450961724</cmdMin>
          </joint_control_pid>
          <joint_name>base_stick_joint</joint_name>
        </channel>
        <channel name="tail_top_rod">
          <input_index>4</input_index>
          <input_offset>0</input_offset>
          <!-- <input_scaling>1</input_scaling> -->
          <input_scaling>0</input_scaling>
          <zero_position_disarmed>0</zero_position_disarmed>
          <zero_position_armed>0</zero_position_armed>
          <joint_control_type>position_kinematic</joint_control_type>
          <joint_control_pid>
          </joint_control_pid>
          <joint_name>top_rud_part1_top_rud_joint_link_joint</joint_name>
        </channel>
        <channel name="tail_bot_rod">
          <input_index>5</input_index>
          <input_offset>0</input_offset>
          <!-- <input_scaling>1</input_scaling> -->
          <input_scaling>0</input_scaling>
          <zero_position_disarmed>0</zero_position_disarmed>
          <zero_position_armed>0</zero_position_armed>
          <joint_control_type>position_kinematic</joint_control_type>
          <joint_control_pid>
          </joint_control_pid>
          <joint_name>bot_rud_part1_bot_rud_joint_link_joint</joint_name>
        </channel>
        <channel name="left_elev_tail">
          <input_index>6</input_index>
          <input_offset>0</input_offset>
          <input_scaling>1</input_scaling>
          <zero_position_disarmed>0</zero_position_disarmed>
          <zero_position_armed>0</zero_position_armed>
          <joint_control_type>position_kinematic</joint_control_type>
          <joint_control_pid>
          </joint_control_pid>
          <joint_name>left_elv_part1_left_elv_joint_link_joint</joint_name>
        </channel>
        <channel name="right_elev_tail">
          <input_index>7</input_index>
          <input_offset>0</input_offset>
          <input_scaling>1</input_scaling>
          <zero_position_disarmed>0</zero_position_disarmed>
          <zero_position_armed>0</zero_position_armed>
          <joint_control_type>position_kinematic</joint_control_type>
          <joint_control_pid>
          </joint_control_pid>
          <joint_name>right_elv_part1_right_elv_joint_link_joint</joint_name>
        </channel>
      </control_channels>
    </plugin>
  </model>
</sdf>
