<?xml version="1.0" ?>
<!-- =================================================================================== -->
<!-- |    This document was autogenerated by xacro from blimp_base.xacro               | -->
<!-- |    EDITING THIS FILE BY HAND IS NOT RECOMMENDED                                 | -->
<!-- =================================================================================== -->
<robot name="blimp">
  <!--[kg/m^3] Temperature 20celsius: 1.2041-->
  <!--default: 0.6 -->
  <!-- [m] -->
  <!--<xacro:property name="time_constant_up" value="0.0125" /> -->
  <!-- [s] -->
  <!--<xacro:property name="time_constant_down" value="0.025" /> -->
  <!-- [s] -->
  --&gt;
	
  <!-- [m^2] -->
  <!-- joint origin [m] [m] [m] [rad] [rad] [rad] -->
  <!--***************** link description	*****************-->
  <link name="base_link"/>
  <link name="gondola_body_link">
    <inertial>
      <mass value="1.105"/>
      <origin rpy="0  0  0" xyz="0  0  0"/>
      <inertia ixx="0.0060406642504000005" ixy="0.0" ixz="0.0" iyy="0.019926825362599997" iyz="0.0" izz="0.018600825892999998"/>
    </inertial>
    <collision>
      <origin rpy="0  0  0" xyz="0  0  0"/>
      <geometry>
        <mesh filename="package://rblimp/meshes/blimp_gondola/blimp_gondola_v4.dae" scale="1 1 1"/>
      </geometry>
    </collision>
    <visual>
      <origin rpy="0  0  0" xyz="0  0  0"/>
      <geometry>
        <mesh filename="package://rblimp/meshes/blimp_gondola/blimp_gondola_v4.dae" scale="1 1 1"/>
      </geometry>
    </visual>
  </link>
  <gazebo reference="gondola_body_link">
    <kp>1000000.0</kp>
    <kd>1000000.0</kd>
    <mu1>10.0</mu1>
    <mu2>10.0</mu2>
  </gazebo>
  <joint name="base_gondola_body_joint" type="fixed">
    <origin rpy="0 0 0" xyz="0 0 0.10"/>
    <parent link="base_link"/>
    <child link="gondola_body_link"/>
  </joint>
  <gazebo reference="base_gondola_body_joint">
    <preserveFixedJoint>true</preserveFixedJoint>
  </gazebo>
  <link name="gondola_left_support_link">
    <inertial>
      <mass value="0.2"/>
      <origin rpy="0  0  0" xyz="0  0  0"/>
      <inertia ixx="0.0006733330640000001" ixy="0.0" ixz="0.0" iyy="0.0036066652239999998" iyz="0.0" izz="0.0029466654879999996"/>
    </inertial>
    <collision>
      <origin rpy="0  0  0" xyz="0  0  0"/>
      <geometry>
        <mesh filename="package://rblimp/meshes/blimp_support/blimp_support_v5.dae" scale="1 1 1"/>
      </geometry>
    </collision>
    <visual>
      <origin rpy="0  0  0" xyz="0  0  0"/>
      <geometry>
        <mesh filename="package://rblimp/meshes/blimp_support/blimp_support_v5.dae" scale="1 1 1"/>
      </geometry>
    </visual>
  </link>
  <gazebo reference="gondola_left_support_link">
    <kp>1000000.0</kp>
    <kd>1000000.0</kd>
    <mu1>10.0</mu1>
    <mu2>10.0</mu2>
  </gazebo>
  <joint name="base_gondola_left_support_joint" type="fixed">
    <origin rpy="0.4 0.0 0.0" xyz="0.0 0.1 -0.085"/>
    <parent link="base_link"/>
    <child link="gondola_left_support_link"/>
  </joint>
  <gazebo reference="base_gondola_left_support_joint">
    <preserveFixedJoint>true</preserveFixedJoint>
  </gazebo>
  <link name="gondola_right_support_link">
    <inertial>
      <mass value="0.2"/>
      <origin rpy="0  0  0" xyz="0  0  0"/>
      <inertia ixx="0.0006733330640000001" ixy="0.0" ixz="0.0" iyy="0.0036066652239999998" iyz="0.0" izz="0.0029466654879999996"/>
    </inertial>
    <collision>
      <origin rpy="0  0  0" xyz="0  0  0"/>
      <geometry>
        <mesh filename="package://rblimp/meshes/blimp_support/blimp_support_v5.dae" scale="1 1 1"/>
      </geometry>
    </collision>
    <visual>
      <origin rpy="0  0  0" xyz="0  0  0"/>
      <geometry>
        <mesh filename="package://rblimp/meshes/blimp_support/blimp_support_v5.dae" scale="1 1 1"/>
      </geometry>
    </visual>
  </link>
  <gazebo reference="gondola_right_support_link">
    <kp>1000000.0</kp>
    <kd>1000000.0</kd>
    <mu1>10.0</mu1>
    <mu2>10.0</mu2>
  </gazebo>
  <joint name="base_gondola_right_support_joint" type="fixed">
    <origin rpy="0.4 0.0 3.141592653589793" xyz="0.0 -0.1 -0.085"/>
    <parent link="base_link"/>
    <child link="gondola_right_support_link"/>
  </joint>
  <gazebo reference="base_gondola_right_support_joint">
    <preserveFixedJoint>true</preserveFixedJoint>
  </gazebo>
  <link name="gondola_body_joint_link0">
    <inertial>
      <mass value="0.0001"/>
      <!-- MUST be non zero or the link will be pruned by gazebo and can not accept any forces -->
      <inertia ixx="0.01" ixy="0.0" ixz="0.0" iyy="0.01" iyz="0.0" izz="0.01"/>
    </inertial>
  </link>
  <link name="gondola_body_joint_link1">
    <inertial>
      <mass value="0.0001"/>
      <!-- MUST be non zero or the link will be pruned by gazebo and can not accept any forces -->
      <inertia ixx="0.01" ixy="0.0" ixz="0.0" iyy="0.01" iyz="0.0" izz="0.01"/>
    </inertial>
  </link>
  <link name="gondola_body_joint_link">
    <inertial>
      <mass value="0.0001"/>
      <!-- MUST be non zero or the link will be pruned by gazebo and can not accept any forces -->
      <inertia ixx="0.01" ixy="0.0" ixz="0.0" iyy="0.01" iyz="0.0" izz="0.01"/>
    </inertial>
    <visual>
      <geometry>
        <cylinder length="0.3" radius="0.01"/>
      </geometry>
    </visual>
  </link>
  <joint name="blimp/gondola_body_joint_link_joint0" type="revolute">
    <origin rpy="0.0 0.0 0.0" xyz="0.0 0.0 0.0"/>
    <axis xyz="1.0 0.0 0.0"/>
    <parent link="gondola_body_link"/>
    <child link="gondola_body_joint_link0"/>
    <limit effort="-1" lower="0" upper="0" velocity="-1"/>
    <dynamics damping="0.5" friction="0"/>
  </joint>
  <joint name="blimp/gondola_body_joint_link_joint1" type="revolute">
    <origin rpy="0 0 0" xyz="0 0 0"/>
    <axis xyz="0.0 1.0 0.0"/>
    <parent link="gondola_body_joint_link0"/>
    <child link="gondola_body_joint_link1"/>
    <limit effort="-1" lower="0" upper="0" velocity="-1"/>
    <dynamics damping="0.5" friction="0"/>
  </joint>
  <joint name="blimp/gondola_body_joint_link_joint" type="revolute">
    <origin rpy="0 0 0" xyz="0 0 0"/>
    <axis xyz="0.0 0.0 1.0"/>
    <parent link="gondola_body_joint_link1"/>
    <child link="gondola_body_joint_link"/>
    <limit effort="-1" lower="0" upper="0" velocity="-1"/>
    <dynamics damping="0.5" friction="0"/>
  </joint>
  <gazebo reference="blimp/gondola_body_joint_link_joint0">
    <stopCfm>0.5</stopCfm>
    <stopErp>0.2</stopErp>
  </gazebo>
  <gazebo reference="blimp/gondola_body_joint_link_joint1">
    <stopCfm>0.1</stopCfm>
    <stopErp>0.2</stopErp>
  </gazebo>
  <gazebo reference="blimp/gondola_body_joint_link_joint">
    <stopCfm>0.05</stopCfm>
    <stopErp>0.2</stopErp>
  </gazebo>
  <link name="blimp_body_link">
    <inertial>
      <mass value="4.622"/>
      <origin rpy="0  0  0" xyz="0  0  0"/>
      <inertia ixx="7.491373699115988" ixy="0.0" ixz="0.0" iyy="7.491373699115988" iyz="0.0" izz="2.899420058"/>
    </inertial>
    <collision>
      <origin rpy="0  0  0" xyz="0  0  0"/>
      <geometry>
        <mesh filename="package://rblimp/meshes/blimp_body/blimp_body_v4.dae" scale="1 1 1"/>
      </geometry>
    </collision>
    <visual>
      <origin rpy="0  0  0" xyz="0  0  0"/>
      <geometry>
        <mesh filename="package://rblimp/meshes/blimp_body/blimp_body_v4.dae" scale="1 1 1"/>
      </geometry>
    </visual>
  </link>
  <gazebo reference="blimp_body_link">
    <kp>1000000.0</kp>
    <kd>1000000.0</kd>
    <mu1>10.0</mu1>
    <mu2>10.0</mu2>
  </gazebo>
  <joint name="gondola_joint_blimb_body_joint" type="revolute">
    <origin rpy="0.0 1.5707963267948966 0.0" xyz="-1.00 0.0 1.05"/>
    <parent link="gondola_body_joint_link"/>
    <child link="blimp_body_link"/>
    <limit effort="1000" lower="0" upper="0" velocity="1000"/>
  </joint>
  <link name="stick_link">
    <inertial>
      <mass value="0.705"/>
      <origin rpy="0  0  0" xyz="0  0  0"/>
      <inertia ixx="0.03306448677419999" ixy="0.0" ixz="0.0" iyy="0.03306448677419999" iyz="0.0" izz="3.525e-05"/>
    </inertial>
    <collision>
      <origin rpy="0  0  0" xyz="0  0  0"/>
      <geometry>
        <mesh filename="package://rblimp/meshes/blimp_wing/blimp_stick_v2.dae" scale="1 1 1"/>
      </geometry>
    </collision>
    <visual>
      <origin rpy="0  0  0" xyz="0  0  0"/>
      <geometry>
        <mesh filename="package://rblimp/meshes/blimp_wing/blimp_stick_v2.dae" scale="1 1 1"/>
      </geometry>
    </visual>
  </link>
  <gazebo reference="stick_link">
    <kp>1000000.0</kp>
    <kd>1000000.0</kd>
    <mu1>10.0</mu1>
    <mu2>10.0</mu2>
  </gazebo>
  <joint name="base_stick_joint" type="revolute">
    <origin rpy="1.5707963267948966 0.0 0.0" xyz="-0.08 0 0.03"/>
    <parent link="base_link"/>
    <child link="stick_link"/>
    <axis xyz="0 0 -1"/>
    <limit effort="1000" lower="-1.7453292519943295" upper="1.7453292519943295" velocity="2"/>
  </joint>
  <link name="left_wing_link">
    <inertial>
      <mass value="0.5"/>
      <origin rpy="0  0  0" xyz="0  0  0"/>
      <inertia ixx="0.01081562067375" ixy="0.0" ixz="0.0" iyy="0.01081562067375" iyz="0.0" izz="0.02155625"/>
    </inertial>
    <collision>
      <origin rpy="0  0  0" xyz="0  0  0"/>
      <geometry>
        <mesh filename="package://rblimp/meshes/blimp_wing/blimp_wing_v2.dae" scale="1 1 1"/>
      </geometry>
    </collision>
    <visual>
      <origin rpy="0  0  0" xyz="0  0  0"/>
      <geometry>
        <mesh filename="package://rblimp/meshes/blimp_wing/blimp_wing_v2.dae" scale="1 1 1"/>
      </geometry>
    </visual>
  </link>
  <gazebo reference="left_wing_link">
    <kp>1000000.0</kp>
    <kd>1000000.0</kd>
    <mu1>10.0</mu1>
    <mu2>10.0</mu2>
  </gazebo>
  <joint name="stick_left_wing_joint" type="fixed">
    <origin rpy="-1.5707963267948966 0.0 0.0" xyz="0.0 0.02 -0.375"/>
    <parent link="stick_link"/>
    <child link="left_wing_link"/>
  </joint>
  <gazebo reference="stick_left_wing_joint">
    <preserveFixedJoint>true</preserveFixedJoint>
  </gazebo>
  <link name="right_wing_link">
    <inertial>
      <mass value="0.5"/>
      <origin rpy="0  0  0" xyz="0  0  0"/>
      <inertia ixx="0.01081562067375" ixy="0.0" ixz="0.0" iyy="0.01081562067375" iyz="0.0" izz="0.02155625"/>
    </inertial>
    <collision>
      <origin rpy="0  0  0" xyz="0  0  0"/>
      <geometry>
        <mesh filename="package://rblimp/meshes/blimp_wing/blimp_wing_v2.dae" scale="1 1 1"/>
      </geometry>
    </collision>
    <visual>
      <origin rpy="0  0  0" xyz="0  0  0"/>
      <geometry>
        <mesh filename="package://rblimp/meshes/blimp_wing/blimp_wing_v2.dae" scale="1 1 1"/>
      </geometry>
    </visual>
  </link>
  <gazebo reference="right_wing_link">
    <kp>1000000.0</kp>
    <kd>1000000.0</kd>
    <mu1>10.0</mu1>
    <mu2>10.0</mu2>
  </gazebo>
  <joint name="stick_right_wing_joint" type="fixed">
    <origin rpy="-1.5707963267948966 0.0 0.0" xyz="0.0 0.02 0.375"/>
    <parent link="stick_link"/>
    <child link="right_wing_link"/>
  </joint>
  <gazebo reference="stick_right_wing_joint">
    <preserveFixedJoint>true</preserveFixedJoint>
  </gazebo>
  <link name="left_blade_link">
    <inertial>
      <mass value="0.05"/>
      <origin rpy="1.5707963267948966  0  0" xyz="0  0  0"/>
      <inertia ixx="0.0006349997460000001" ixy="0.0" ixz="0.0" iyy="0.0006349997460000001" iyz="0.0" izz="2.5e-06"/>
    </inertial>
    <collision>
      <origin rpy="1.5707963267948966  0  0" xyz="0  0  0"/>
      <geometry>
        <mesh filename="package://rblimp/meshes/blimp_propeller/blimp_left_propeller_ccw_v3.dae" scale="1 1 1"/>
      </geometry>
    </collision>
    <visual>
      <origin rpy="1.5707963267948966  0  0" xyz="0  0  0"/>
      <geometry>
        <mesh filename="package://rblimp/meshes/blimp_propeller/blimp_left_propeller_ccw_v3.dae" scale="1 1 1"/>
      </geometry>
    </visual>
  </link>
  <gazebo reference="left_blade_link">
    <kp>1000000.0</kp>
    <kd>1000000.0</kd>
    <mu1>10.0</mu1>
    <mu2>10.0</mu2>
  </gazebo>
  <joint name="stick_left_blade_joint" type="continuous">
    <origin rpy="-1.5707963267948966 0.0 0.0" xyz="0.0 0.025 -0.375"/>
    <parent link="stick_link"/>
    <child link="left_blade_link"/>
    <axis xyz="0 0 1"/>
  </joint>
  <link name="right_blade_link">
    <inertial>
      <mass value="0.05"/>
      <origin rpy="1.5707963267948966  0  0" xyz="0  0  0"/>
      <inertia ixx="0.0006349997460000001" ixy="0.0" ixz="0.0" iyy="0.0006349997460000001" iyz="0.0" izz="2.5e-06"/>
    </inertial>
    <collision>
      <origin rpy="1.5707963267948966  0  0" xyz="0  0  0"/>
      <geometry>
        <mesh filename="package://rblimp/meshes/blimp_propeller/blimp_right_propeller_cw_v3.dae" scale="1 1 1"/>
      </geometry>
    </collision>
    <visual>
      <origin rpy="1.5707963267948966  0  0" xyz="0  0  0"/>
      <geometry>
        <mesh filename="package://rblimp/meshes/blimp_propeller/blimp_right_propeller_cw_v3.dae" scale="1 1 1"/>
      </geometry>
    </visual>
  </link>
  <gazebo reference="right_blade_link">
    <kp>1000000.0</kp>
    <kd>1000000.0</kd>
    <mu1>10.0</mu1>
    <mu2>10.0</mu2>
  </gazebo>
  <joint name="stick_right_blade_joint" type="continuous">
    <origin rpy="-1.5707963267948966 0.0 3.141592653589793" xyz="0.0 0.025 0.375"/>
    <parent link="stick_link"/>
    <child link="right_blade_link"/>
    <axis xyz="0 0 1"/>
  </joint>
  <link name="front_ballast_joint_link">
    <inertial>
      <mass value="0.6"/>
      <origin rpy="0  0  0" xyz="0  0  0"/>
      <inertia ixx="0.00013999994400000002" ixy="0.0" ixz="0.0" iyy="0.00013999994400000002" iyz="0.0" izz="3e-05"/>
    </inertial>
    <collision>
      <origin rpy="0  0  0" xyz="0  0  0"/>
      <geometry>
        <cylinder length="0.05" radius="0.01"/>
        <!-- [m] [m] [m] -->
      </geometry>
    </collision>
    <visual>
      <origin rpy="0  0  0" xyz="0  0  0"/>
      <geometry>
        <cylinder length="0.05" radius="0.01"/>
        <!-- [m] [m] [m] -->
      </geometry>
    </visual>
  </link>
  <gazebo reference="front_ballast_joint_link">
    <kp>1000000.0</kp>
    <kd>1000000.0</kd>
    <mu1>10.0</mu1>
    <mu2>10.0</mu2>
  </gazebo>
  <joint name="blimp_body_front_ballast_joint" type="revolute">
    <origin rpy="0.0 0.0 0.0" xyz="0.0 0.0 2.5"/>
    <parent link="blimp_body_link"/>
    <child link="front_ballast_joint_link"/>
    <limit effort="1000" lower="0" upper="0" velocity="1000"/>
  </joint>
  <link name="forward_lift_joint_link">
    <inertial>
      <mass value="1e-3"/>
      <!-- MUST be non zero or the link will be pruned by gazebo and can not accept any forces -->
      <inertia ixx="0.0" ixy="0.0" ixz="0.0" iyy="0.0" iyz="0.0" izz="0.0"/>
    </inertial>
    <visual>
      <geometry>
        <cylinder length="0.3" radius="0.01"/>
      </geometry>
    </visual>
  </link>
  <joint name="blimp_body_forward_lift_joint" type="revolute">
    <origin rpy="0.0 -1.5707963267948966 1.5707963267948966" xyz="0 0 2.0"/>
    <parent link="blimp_body_link"/>
    <child link="forward_lift_joint_link"/>
    <limit effort="1000" lower="0" upper="0" velocity="1000"/>
  </joint>
  <link name="aft_lift_joint_link">
    <inertial>
      <mass value="1e-3"/>
      <!-- MUST be non zero or the link will be pruned by gazebo and can not accept any forces -->
      <inertia ixx="0.0" ixy="0.0" ixz="0.0" iyy="0.0" iyz="0.0" izz="0.0"/>
    </inertial>
    <visual>
      <geometry>
        <cylinder length="0.3" radius="0.01"/>
      </geometry>
    </visual>
  </link>
  <joint name="blimp_body_aft_lift_joint" type="revolute">
    <origin rpy="0.0 -1.5707963267948966 1.5707963267948966" xyz="0 0 -0.3"/>
    <parent link="blimp_body_link"/>
    <child link="aft_lift_joint_link"/>
    <limit effort="1000" lower="0" upper="0" velocity="1000"/>
  </joint>
  <link name="top_rud_base_joint_link0">
    <inertial>
      <mass value="0.0001"/>
      <!-- MUST be non zero or the link will be pruned by gazebo and can not accept any forces -->
      <inertia ixx="0.01" ixy="0.0" ixz="0.0" iyy="0.01" iyz="0.0" izz="0.01"/>
    </inertial>
  </link>
  <link name="top_rud_base_joint_link1">
    <inertial>
      <mass value="0.0001"/>
      <!-- MUST be non zero or the link will be pruned by gazebo and can not accept any forces -->
      <inertia ixx="0.01" ixy="0.0" ixz="0.0" iyy="0.01" iyz="0.0" izz="0.01"/>
    </inertial>
  </link>
  <link name="top_rud_base_joint_link">
    <inertial>
      <mass value="0.0001"/>
      <!-- MUST be non zero or the link will be pruned by gazebo and can not accept any forces -->
      <inertia ixx="0.01" ixy="0.0" ixz="0.0" iyy="0.01" iyz="0.0" izz="0.01"/>
    </inertial>
    <visual>
      <geometry>
        <cylinder length="0.3" radius="0.01"/>
      </geometry>
    </visual>
  </link>
  <joint name="blimp/top_rud_base_joint_link_joint0" type="revolute">
    <origin rpy="3.141592653589793 -1.5707963267948966 0.0" xyz="-0.59 0.0 -1.5"/>
    <axis xyz="1.0 0.0 0.0"/>
    <parent link="blimp_body_link"/>
    <child link="top_rud_base_joint_link0"/>
    <limit effort="-1" lower="0" upper="0" velocity="-1"/>
    <dynamics damping="0.5" friction="0"/>
  </joint>
  <joint name="blimp/top_rud_base_joint_link_joint1" type="revolute">
    <origin rpy="0 0 0" xyz="0 0 0"/>
    <axis xyz="0.0 1.0 0.0"/>
    <parent link="top_rud_base_joint_link0"/>
    <child link="top_rud_base_joint_link1"/>
    <limit effort="-1" lower="0" upper="0" velocity="-1"/>
    <dynamics damping="0.5" friction="0"/>
  </joint>
  <joint name="blimp/top_rud_base_joint_link_joint" type="revolute">
    <origin rpy="0 0 0" xyz="0 0 0"/>
    <axis xyz="0.0 0.0 1.0"/>
    <parent link="top_rud_base_joint_link1"/>
    <child link="top_rud_base_joint_link"/>
    <limit effort="-1" lower="0" upper="0" velocity="-1"/>
    <dynamics damping="0.5" friction="0"/>
  </joint>
  <gazebo reference="blimp/top_rud_base_joint_link_joint0">
    <stopCfm>1.0</stopCfm>
    <stopErp>0.2</stopErp>
  </gazebo>
  <gazebo reference="blimp/top_rud_base_joint_link_joint1">
    <stopCfm>0.2</stopCfm>
    <stopErp>0.2</stopErp>
  </gazebo>
  <gazebo reference="blimp/top_rud_base_joint_link_joint">
    <stopCfm>0.1</stopCfm>
    <stopErp>0.2</stopErp>
  </gazebo>
  <link name="top_rud_part1_link">
    <inertial>
      <mass value="0.58"/>
      <origin rpy="0  0  0" xyz="0  0  0"/>
      <inertia ixx="0.011155328871199998" ixy="0.0" ixz="0.0" iyy="0.0257568230306" iyz="0.0" izz="0.014640160810600001"/>
    </inertial>
    <collision>
      <origin rpy="0  0  0" xyz="0  0  0"/>
      <geometry>
        <mesh filename="package://rblimp/meshes/blimp_fin/blimp_top_rud_part1_v3.dae" scale="1 1 1"/>
      </geometry>
    </collision>
    <visual>
      <origin rpy="0  0  0" xyz="0  0  0"/>
      <geometry>
        <mesh filename="package://rblimp/meshes/blimp_fin/blimp_top_rud_part1_v3.dae" scale="1 1 1"/>
      </geometry>
    </visual>
  </link>
  <gazebo reference="top_rud_part1_link">
    <kp>1000000.0</kp>
    <kd>1000000.0</kd>
    <mu1>10.0</mu1>
    <mu2>10.0</mu2>
  </gazebo>
  <joint name="blimp_body_top_rud_part1_joint" type="revolute">
    <origin rpy="0.0 0.0 0.0" xyz="0.0 0.0 -0.24"/>
    <parent link="top_rud_base_joint_link"/>
    <child link="top_rud_part1_link"/>
    <limit effort="1000" lower="0" upper="0" velocity="1000"/>
  </joint>
  <link name="top_rud_joint_link">
    <visual>
      <geometry>
        <cylinder length="0.3" radius="0.01"/>
      </geometry>
    </visual>
  </link>
  <joint name="top_rud_part1_top_rud_joint_link_joint" type="revolute">
    <origin rpy="0.0 0.0 0.0" xyz="-0.28 0.0 0.0"/>
    <parent link="top_rud_part1_link"/>
    <child link="top_rud_joint_link"/>
    <axis xyz="0 0 -1"/>
    <limit effort="500" lower="-1.0471975511965976" upper="1.0471975511965976" velocity="2"/>
  </joint>
  <link name="top_rud_part2_link">
    <inertial>
      <mass value="0.113"/>
      <origin rpy="0  0  0" xyz="0  0  0"/>
      <inertia ixx="0.0021733657973200004" ixy="0.0" ixz="0.0" iyy="0.0030170987931600005" iyz="0.0" izz="0.00085126632616"/>
    </inertial>
    <collision>
      <origin rpy="0  0  0" xyz="0  0  0"/>
      <geometry>
        <mesh filename="package://rblimp/meshes/blimp_fin/blimp_top_rud_part2_v5.dae" scale="1 1 1"/>
      </geometry>
    </collision>
    <visual>
      <origin rpy="0  0  0" xyz="0  0  0"/>
      <geometry>
        <mesh filename="package://rblimp/meshes/blimp_fin/blimp_top_rud_part2_v5.dae" scale="1 1 1"/>
      </geometry>
    </visual>
  </link>
  <gazebo reference="top_rud_part2_link">
    <kp>1000000.0</kp>
    <kd>1000000.0</kd>
    <mu1>10.0</mu1>
    <mu2>10.0</mu2>
  </gazebo>
  <joint name="top_rud_joint_link_top_rud_part2_joint" type="fixed">
    <origin rpy="0.0 0.0 0.0" xyz="-0.125 0.0 0.0"/>
    <parent link="top_rud_joint_link"/>
    <child link="top_rud_part2_link"/>
  </joint>
  <gazebo reference="top_rud_joint_link_top_rud_part2_joint">
    <preserveFixedJoint>true</preserveFixedJoint>
  </gazebo>
  <link name="bot_rud_base_joint_link0">
    <inertial>
      <mass value="0.0001"/>
      <!-- MUST be non zero or the link will be pruned by gazebo and can not accept any forces -->
      <inertia ixx="0.01" ixy="0.0" ixz="0.0" iyy="0.01" iyz="0.0" izz="0.01"/>
    </inertial>
  </link>
  <link name="bot_rud_base_joint_link1">
    <inertial>
      <mass value="0.0001"/>
      <!-- MUST be non zero or the link will be pruned by gazebo and can not accept any forces -->
      <inertia ixx="0.01" ixy="0.0" ixz="0.0" iyy="0.01" iyz="0.0" izz="0.01"/>
    </inertial>
  </link>
  <link name="bot_rud_base_joint_link">
    <inertial>
      <mass value="0.0001"/>
      <!-- MUST be non zero or the link will be pruned by gazebo and can not accept any forces -->
      <inertia ixx="0.01" ixy="0.0" ixz="0.0" iyy="0.01" iyz="0.0" izz="0.01"/>
    </inertial>
    <visual>
      <geometry>
        <cylinder length="0.3" radius="0.01"/>
      </geometry>
    </visual>
  </link>
  <joint name="blimp/bot_rud_base_joint_link_joint0" type="revolute">
    <origin rpy="0.0 -1.5707963267948966 0.0" xyz="0.59 0.0 -1.5"/>
    <axis xyz="1.0 0.0 0.0"/>
    <parent link="blimp_body_link"/>
    <child link="bot_rud_base_joint_link0"/>
    <limit effort="-1" lower="0" upper="0" velocity="-1"/>
    <dynamics damping="0.5" friction="0"/>
  </joint>
  <joint name="blimp/bot_rud_base_joint_link_joint1" type="revolute">
    <origin rpy="0 0 0" xyz="0 0 0"/>
    <axis xyz="0.0 1.0 0.0"/>
    <parent link="bot_rud_base_joint_link0"/>
    <child link="bot_rud_base_joint_link1"/>
    <limit effort="-1" lower="0" upper="0" velocity="-1"/>
    <dynamics damping="0.5" friction="0"/>
  </joint>
  <joint name="blimp/bot_rud_base_joint_link_joint" type="revolute">
    <origin rpy="0 0 0" xyz="0 0 0"/>
    <axis xyz="0.0 0.0 1.0"/>
    <parent link="bot_rud_base_joint_link1"/>
    <child link="bot_rud_base_joint_link"/>
    <limit effort="-1" lower="0" upper="0" velocity="-1"/>
    <dynamics damping="0.5" friction="0"/>
  </joint>
  <gazebo reference="blimp/bot_rud_base_joint_link_joint0">
    <stopCfm>1.0</stopCfm>
    <stopErp>0.2</stopErp>
  </gazebo>
  <gazebo reference="blimp/bot_rud_base_joint_link_joint1">
    <stopCfm>0.2</stopCfm>
    <stopErp>0.2</stopErp>
  </gazebo>
  <gazebo reference="blimp/bot_rud_base_joint_link_joint">
    <stopCfm>0.1</stopCfm>
    <stopErp>0.2</stopErp>
  </gazebo>
  <link name="bot_rud_part1_link">
    <inertial>
      <mass value="0.41"/>
      <origin rpy="0  0  0" xyz="0  0  0"/>
      <inertia ixx="0.011155328871199998" ixy="0.0" ixz="0.0" iyy="0.0257568230306" iyz="0.0" izz="0.014640160810600001"/>
    </inertial>
    <collision>
      <origin rpy="0  0  0" xyz="0  0  0"/>
      <geometry>
        <mesh filename="package://rblimp/meshes/blimp_fin/blimp_bot_rud_part1_v3.dae" scale="1 1 1"/>
      </geometry>
    </collision>
    <visual>
      <origin rpy="0  0  0" xyz="0  0  0"/>
      <geometry>
        <mesh filename="package://rblimp/meshes/blimp_fin/blimp_bot_rud_part1_v3.dae" scale="1 1 1"/>
      </geometry>
    </visual>
  </link>
  <gazebo reference="bot_rud_part1_link">
    <kp>1000000.0</kp>
    <kd>1000000.0</kd>
    <mu1>10.0</mu1>
    <mu2>10.0</mu2>
  </gazebo>
  <joint name="blimp_body_bot_rud_part1_joint" type="revolute">
    <origin rpy="0.0 0.0 0.0" xyz="0.0 0.0 -0.24"/>
    <parent link="bot_rud_base_joint_link"/>
    <child link="bot_rud_part1_link"/>
    <limit effort="1000" lower="0" upper="0" velocity="1000"/>
  </joint>
  <link name="bot_rud_joint_link">
    <visual>
      <geometry>
        <cylinder length="0.3" radius="0.01"/>
      </geometry>
    </visual>
  </link>
  <joint name="bot_rud_part1_bot_rud_joint_link_joint" type="revolute">
    <origin rpy="0.0 0.0 0.0" xyz="-0.28 0.0 0.0"/>
    <parent link="bot_rud_part1_link"/>
    <child link="bot_rud_joint_link"/>
    <axis xyz="0 0 1"/>
    <limit effort="500" lower="-1.0471975511965976" upper="1.0471975511965976" velocity="2"/>
  </joint>
  <link name="bot_rud_part2_link">
    <inertial>
      <mass value="0.113"/>
      <origin rpy="0  0  0" xyz="0  0  0"/>
      <inertia ixx="0.0021733657973200004" ixy="0.0" ixz="0.0" iyy="0.0030170987931600005" iyz="0.0" izz="0.00085126632616"/>
    </inertial>
    <collision>
      <origin rpy="0  0  0" xyz="0  0  0"/>
      <geometry>
        <mesh filename="package://rblimp/meshes/blimp_fin/blimp_top_rud_part2_v5.dae" scale="1 1 1"/>
      </geometry>
    </collision>
    <visual>
      <origin rpy="0  0  0" xyz="0  0  0"/>
      <geometry>
        <mesh filename="package://rblimp/meshes/blimp_fin/blimp_top_rud_part2_v5.dae" scale="1 1 1"/>
      </geometry>
    </visual>
  </link>
  <gazebo reference="bot_rud_part2_link">
    <kp>1000000.0</kp>
    <kd>1000000.0</kd>
    <mu1>10.0</mu1>
    <mu2>10.0</mu2>
  </gazebo>
  <joint name="bot_rud_joint_link_bot_rud_part2_joint" type="fixed">
    <origin rpy="0.0 0.0 0.0" xyz="-0.125 0.0 0.0"/>
    <parent link="bot_rud_joint_link"/>
    <child link="bot_rud_part2_link"/>
  </joint>
  <gazebo reference="bot_rud_joint_link_bot_rud_part2_joint">
    <preserveFixedJoint>true</preserveFixedJoint>
  </gazebo>
  <link name="bot_rud_motor_link">
    <inertial>
      <mass value="0.127"/>
      <origin rpy="0  0  0" xyz="0  0  0"/>
      <inertia ixx="0.0006622518184325" ixy="0.0" ixz="0.0" iyy="0.0006622518184325" iyz="0.0" izz="1.5875e-06"/>
    </inertial>
    <collision>
      <origin rpy="0  0  0" xyz="0  0  0"/>
      <geometry>
        <mesh filename="package://rblimp/meshes/blimp_propeller/blimp_bot_propeller_cw_v3.dae" scale="1 1 1"/>
      </geometry>
    </collision>
    <visual>
      <origin rpy="0  0  0" xyz="0  0  0"/>
      <geometry>
        <mesh filename="package://rblimp/meshes/blimp_propeller/blimp_bot_propeller_cw_v3.dae" scale="1 1 1"/>
      </geometry>
    </visual>
  </link>
  <gazebo reference="bot_rud_motor_link">
    <kp>1000000.0</kp>
    <kd>1000000.0</kd>
    <mu1>10.0</mu1>
    <mu2>10.0</mu2>
  </gazebo>
  <joint name="bot_rud_part1_bot_rud_motor_joint" type="continuous">
    <origin rpy="-1.5707963267948966 0.0 0.0" xyz="-0.065 0.01 -0.025"/>
    <parent link="bot_rud_part1_link"/>
    <child link="bot_rud_motor_link"/>
    <axis xyz="0 0 -1"/>
  </joint>
  <link name="left_elv_base_joint_link0">
    <inertial>
      <mass value="0.0001"/>
      <!-- MUST be non zero or the link will be pruned by gazebo and can not accept any forces -->
      <inertia ixx="0.01" ixy="0.0" ixz="0.0" iyy="0.01" iyz="0.0" izz="0.01"/>
    </inertial>
  </link>
  <link name="left_elv_base_joint_link1">
    <inertial>
      <mass value="0.0001"/>
      <!-- MUST be non zero or the link will be pruned by gazebo and can not accept any forces -->
      <inertia ixx="0.01" ixy="0.0" ixz="0.0" iyy="0.01" iyz="0.0" izz="0.01"/>
    </inertial>
  </link>
  <link name="left_elv_base_joint_link">
    <inertial>
      <mass value="0.0001"/>
      <!-- MUST be non zero or the link will be pruned by gazebo and can not accept any forces -->
      <inertia ixx="0.01" ixy="0.0" ixz="0.0" iyy="0.01" iyz="0.0" izz="0.01"/>
    </inertial>
    <visual>
      <geometry>
        <cylinder length="0.3" radius="0.01"/>
      </geometry>
    </visual>
  </link>
  <joint name="blimp/left_elv_base_joint_link_joint0" type="revolute">
    <origin rpy="0.0 -1.5707963267948966 1.5707963267948966" xyz="0.0 0.59 -1.5"/>
    <axis xyz="1.0 0.0 0.0"/>
    <parent link="blimp_body_link"/>
    <child link="left_elv_base_joint_link0"/>
    <limit effort="-1" lower="0" upper="0" velocity="-1"/>
    <dynamics damping="0.5" friction="0"/>
  </joint>
  <joint name="blimp/left_elv_base_joint_link_joint1" type="revolute">
    <origin rpy="0 0 0" xyz="0 0 0"/>
    <axis xyz="0.0 1.0 0.0"/>
    <parent link="left_elv_base_joint_link0"/>
    <child link="left_elv_base_joint_link1"/>
    <limit effort="-1" lower="0" upper="0" velocity="-1"/>
    <dynamics damping="0.5" friction="0"/>
  </joint>
  <joint name="blimp/left_elv_base_joint_link_joint" type="revolute">
    <origin rpy="0 0 0" xyz="0 0 0"/>
    <axis xyz="0.0 0.0 1.0"/>
    <parent link="left_elv_base_joint_link1"/>
    <child link="left_elv_base_joint_link"/>
    <limit effort="-1" lower="0" upper="0" velocity="-1"/>
    <dynamics damping="0.5" friction="0"/>
  </joint>
  <gazebo reference="blimp/left_elv_base_joint_link_joint0">
    <stopCfm>1.0</stopCfm>
    <stopErp>0.2</stopErp>
  </gazebo>
  <gazebo reference="blimp/left_elv_base_joint_link_joint1">
    <stopCfm>0.2</stopCfm>
    <stopErp>0.2</stopErp>
  </gazebo>
  <gazebo reference="blimp/left_elv_base_joint_link_joint">
    <stopCfm>0.1</stopCfm>
    <stopErp>0.2</stopErp>
  </gazebo>
  <link name="left_elv_part1_link">
    <inertial>
      <mass value="0.58"/>
      <origin rpy="0  0  0" xyz="0  0  0"/>
      <inertia ixx="0.011155328871199998" ixy="0.0" ixz="0.0" iyy="0.0257568230306" iyz="0.0" izz="0.014640160810600001"/>
    </inertial>
    <collision>
      <origin rpy="0  0  0" xyz="0  0  0"/>
      <geometry>
        <mesh filename="package://rblimp/meshes/blimp_fin/blimp_top_rud_part1_v3.dae" scale="1 1 1"/>
      </geometry>
    </collision>
    <visual>
      <origin rpy="0  0  0" xyz="0  0  0"/>
      <geometry>
        <mesh filename="package://rblimp/meshes/blimp_fin/blimp_top_rud_part1_v3.dae" scale="1 1 1"/>
      </geometry>
    </visual>
  </link>
  <gazebo reference="left_elv_part1_link">
    <kp>1000000.0</kp>
    <kd>1000000.0</kd>
    <mu1>10.0</mu1>
    <mu2>10.0</mu2>
  </gazebo>
  <joint name="blimp_body_left_elv_part1_joint" type="revolute">
    <origin rpy="0.0 0.0 0.0" xyz="0.0 0.0 -0.24"/>
    <parent link="left_elv_base_joint_link"/>
    <child link="left_elv_part1_link"/>
    <limit effort="1000" lower="0" upper="0" velocity="1000"/>
  </joint>
  <link name="left_elv_joint_link">
    <visual>
      <geometry>
        <cylinder length="0.3" radius="0.01"/>
      </geometry>
    </visual>
  </link>
  <joint name="left_elv_part1_left_elv_joint_link_joint" type="revolute">
    <origin rpy="0.0 0.0 0.0" xyz="-0.28 0.0 0.0"/>
    <parent link="left_elv_part1_link"/>
    <child link="left_elv_joint_link"/>
    <axis xyz="0 0 1"/>
    <limit effort="500" lower="-1.0471975511965976" upper="1.0471975511965976" velocity="2"/>
  </joint>
  <link name="left_elv_part2_link">
    <inertial>
      <mass value="0.113"/>
      <origin rpy="0  0  0" xyz="0  0  0"/>
      <inertia ixx="0.0021733657973200004" ixy="0.0" ixz="0.0" iyy="0.0030170987931600005" iyz="0.0" izz="0.00085126632616"/>
    </inertial>
    <collision>
      <origin rpy="0  0  0" xyz="0  0  0"/>
      <geometry>
        <mesh filename="package://rblimp/meshes/blimp_fin/blimp_top_rud_part2_v5.dae" scale="1 1 1"/>
      </geometry>
    </collision>
    <visual>
      <origin rpy="0  0  0" xyz="0  0  0"/>
      <geometry>
        <mesh filename="package://rblimp/meshes/blimp_fin/blimp_top_rud_part2_v5.dae" scale="1 1 1"/>
      </geometry>
    </visual>
  </link>
  <gazebo reference="left_elv_part2_link">
    <kp>1000000.0</kp>
    <kd>1000000.0</kd>
    <mu1>10.0</mu1>
    <mu2>10.0</mu2>
  </gazebo>
  <joint name="left_elv_joint_link_left_elv_part2_joint" type="fixed">
    <origin rpy="0.0 0.0 0.0" xyz="-0.125 0.0 0.0"/>
    <parent link="left_elv_joint_link"/>
    <child link="left_elv_part2_link"/>
  </joint>
  <gazebo reference="left_elv_joint_link_left_elv_part2_joint">
    <preserveFixedJoint>true</preserveFixedJoint>
  </gazebo>
  <link name="right_elv_base_joint_link0">
    <inertial>
      <mass value="0.0001"/>
      <!-- MUST be non zero or the link will be pruned by gazebo and can not accept any forces -->
      <inertia ixx="0.01" ixy="0.0" ixz="0.0" iyy="0.01" iyz="0.0" izz="0.01"/>
    </inertial>
  </link>
  <link name="right_elv_base_joint_link1">
    <inertial>
      <mass value="0.0001"/>
      <!-- MUST be non zero or the link will be pruned by gazebo and can not accept any forces -->
      <inertia ixx="0.01" ixy="0.0" ixz="0.0" iyy="0.01" iyz="0.0" izz="0.01"/>
    </inertial>
  </link>
  <link name="right_elv_base_joint_link">
    <inertial>
      <mass value="0.0001"/>
      <!-- MUST be non zero or the link will be pruned by gazebo and can not accept any forces -->
      <inertia ixx="0.01" ixy="0.0" ixz="0.0" iyy="0.01" iyz="0.0" izz="0.01"/>
    </inertial>
    <visual>
      <geometry>
        <cylinder length="0.3" radius="0.01"/>
      </geometry>
    </visual>
  </link>
  <joint name="blimp/right_elv_base_joint_link_joint0" type="revolute">
    <origin rpy="0.0 -1.5707963267948966 -1.5707963267948966" xyz="0.0 -0.59 -1.5"/>
    <axis xyz="1.0 0.0 0.0"/>
    <parent link="blimp_body_link"/>
    <child link="right_elv_base_joint_link0"/>
    <limit effort="-1" lower="0" upper="0" velocity="-1"/>
    <dynamics damping="0.5" friction="0"/>
  </joint>
  <joint name="blimp/right_elv_base_joint_link_joint1" type="revolute">
    <origin rpy="0 0 0" xyz="0 0 0"/>
    <axis xyz="0.0 1.0 0.0"/>
    <parent link="right_elv_base_joint_link0"/>
    <child link="right_elv_base_joint_link1"/>
    <limit effort="-1" lower="0" upper="0" velocity="-1"/>
    <dynamics damping="0.5" friction="0"/>
  </joint>
  <joint name="blimp/right_elv_base_joint_link_joint" type="revolute">
    <origin rpy="0 0 0" xyz="0 0 0"/>
    <axis xyz="0.0 0.0 1.0"/>
    <parent link="right_elv_base_joint_link1"/>
    <child link="right_elv_base_joint_link"/>
    <limit effort="-1" lower="0" upper="0" velocity="-1"/>
    <dynamics damping="0.5" friction="0"/>
  </joint>
  <gazebo reference="blimp/right_elv_base_joint_link_joint0">
    <stopCfm>1.0</stopCfm>
    <stopErp>0.2</stopErp>
  </gazebo>
  <gazebo reference="blimp/right_elv_base_joint_link_joint1">
    <stopCfm>0.2</stopCfm>
    <stopErp>0.2</stopErp>
  </gazebo>
  <gazebo reference="blimp/right_elv_base_joint_link_joint">
    <stopCfm>0.1</stopCfm>
    <stopErp>0.2</stopErp>
  </gazebo>
  <link name="right_elv_part1_link">
    <inertial>
      <mass value="0.58"/>
      <origin rpy="0  0  0" xyz="0  0  0"/>
      <inertia ixx="0.011155328871199998" ixy="0.0" ixz="0.0" iyy="0.0257568230306" iyz="0.0" izz="0.014640160810600001"/>
    </inertial>
    <collision>
      <origin rpy="0  0  0" xyz="0  0  0"/>
      <geometry>
        <mesh filename="package://rblimp/meshes/blimp_fin/blimp_top_rud_part1_v3.dae" scale="1 1 1"/>
      </geometry>
    </collision>
    <visual>
      <origin rpy="0  0  0" xyz="0  0  0"/>
      <geometry>
        <mesh filename="package://rblimp/meshes/blimp_fin/blimp_top_rud_part1_v3.dae" scale="1 1 1"/>
      </geometry>
    </visual>
  </link>
  <gazebo reference="right_elv_part1_link">
    <kp>1000000.0</kp>
    <kd>1000000.0</kd>
    <mu1>10.0</mu1>
    <mu2>10.0</mu2>
  </gazebo>
  <joint name="blimp_body_right_elv_part1_joint" type="revolute">
    <origin rpy="0.0 0.0 0.0" xyz="0.0 0.0 -0.24"/>
    <parent link="right_elv_base_joint_link"/>
    <child link="right_elv_part1_link"/>
    <limit effort="1000" lower="0" upper="0" velocity="1000"/>
  </joint>
  <link name="right_elv_joint_link">
    <visual>
      <geometry>
        <cylinder length="0.3" radius="0.01"/>
      </geometry>
    </visual>
  </link>
  <joint name="right_elv_part1_right_elv_joint_link_joint" type="revolute">
    <origin rpy="0.0 0.0 0.0" xyz="-0.28 0.0 0.0"/>
    <parent link="right_elv_part1_link"/>
    <child link="right_elv_joint_link"/>
    <axis xyz="0 0 -1"/>
    <limit effort="500" lower="-1.0471975511965976" upper="1.0471975511965976" velocity="2"/>
  </joint>
  <link name="right_elv_part2_link">
    <inertial>
      <mass value="0.113"/>
      <origin rpy="0  0  0" xyz="0  0  0"/>
      <inertia ixx="0.0021733657973200004" ixy="0.0" ixz="0.0" iyy="0.0030170987931600005" iyz="0.0" izz="0.00085126632616"/>
    </inertial>
    <collision>
      <origin rpy="0  0  0" xyz="0  0  0"/>
      <geometry>
        <mesh filename="package://rblimp/meshes/blimp_fin/blimp_top_rud_part2_v5.dae" scale="1 1 1"/>
      </geometry>
    </collision>
    <visual>
      <origin rpy="0  0  0" xyz="0  0  0"/>
      <geometry>
        <mesh filename="package://rblimp/meshes/blimp_fin/blimp_top_rud_part2_v5.dae" scale="1 1 1"/>
      </geometry>
    </visual>
  </link>
  <gazebo reference="right_elv_part2_link">
    <kp>1000000.0</kp>
    <kd>1000000.0</kd>
    <mu1>10.0</mu1>
    <mu2>10.0</mu2>
  </gazebo>
  <joint name="right_elv_joint_link_right_elv_part2_joint" type="fixed">
    <origin rpy="0.0 0.0 0.0" xyz="-0.125 0.0 0.0"/>
    <parent link="right_elv_joint_link"/>
    <child link="right_elv_part2_link"/>
  </joint>
  <gazebo reference="right_elv_joint_link_right_elv_part2_joint">
    <preserveFixedJoint>true</preserveFixedJoint>
  </gazebo>
  <gazebo>
    <plugin filename="librotors_gazebo_controller_interface.so" name="controller_interface">
      <robotNamespace>blimp</robotNamespace>
      <commandAttitudeThrustSubTopic>command/attitude</commandAttitudeThrustSubTopic>
      <commandRateThrustSubTopic>command/rate</commandRateThrustSubTopic>
      <commandMotorSpeedSubTopic>command/motor_speed</commandMotorSpeedSubTopic>
      <imuSubTopic>imu</imuSubTopic>
      <motorSpeedCommandPubTopic>gazebo/command/motor_speed</motorSpeedCommandPubTopic>
    </plugin>
  </gazebo>
  <gazebo>
    <plugin filename="libgazebo_ros_control.so" name="gazebo_ros_control">
      <robotNamespace>/blimp</robotNamespace>
    </plugin>
  </gazebo>
  <gazebo>
    <plugin filename="librotors_gazebo_mavlink_interface.so" name="mavlink_interface">
      <robotNamespace>blimp</robotNamespace>
      <mavlinkControlSubTopic>/mavlink/from</mavlinkControlSubTopic>
      <imuSubTopic>imu</imuSubTopic>
      <mavlinkHilSensorPubTopic>/mavlink/to</mavlinkHilSensorPubTopic>
      <motorSpeedsPubTopic>gazebo/command/motor_speed</motorSpeedsPubTopic>
      <gpsUpdateFreq>5.0</gpsUpdateFreq>
      <!-- Frequency of HIL GPS messages [Hz] -->
      <rotorCount>3</rotorCount>
      <!-- [Gauss] Below are the North, East, and Down components of the Earth's magnetic field at the reference location.
				The default reference location is Zurich (lat=+47.3667degN, lon=+8.5500degE, h=+500m, WGS84).
				You can obtain the magnetic field strength for your location using the World Magnetic Model: 
				https://www.ngdc.noaa.gov/geomag/WMM/calculators.shtml -->
      <referenceMagNorth>0.21475</referenceMagNorth>
      <referenceMagEast>0.00797</referenceMagEast>
      <referenceMagDown>0.42817</referenceMagDown>
      <referenceLatitude>47.3667</referenceLatitude>
      <!-- the initial latitude [degrees [-90, 90]] -->
      <referenceLongitude>8.55</referenceLongitude>
      <!-- the initial longitude [degrees [-180, 180]] -->
      <referenceAltitude>500.0</referenceAltitude>
      <!-- the initial altitude [m] -->
    </plugin>
  </gazebo>
  <gazebo>
    <plugin filename="librotors_gazebo_motor_model.so" name="left_blade_link_motor_model">
      <robotNamespace>blimp</robotNamespace>
      <jointName>stick_left_blade_joint</jointName>
      <linkName>left_blade_link</linkName>
      <turningDirection>ccw</turningDirection>
      <timeConstantUp>1</timeConstantUp>
      <timeConstantDown>1</timeConstantDown>
      <maxRotVelocity>879.23</maxRotVelocity>
      <motorConstant>0.00371178707</motorConstant>
      <momentConstant>0.016</momentConstant>
      <commandSubTopic>gazebo/command/motor_speed</commandSubTopic>
      <motorNumber>0</motorNumber>
      <rotorDragCoefficient>8.06428e-05</rotorDragCoefficient>
      <rollingMomentCoefficient>1e-06</rollingMomentCoefficient>
      <motorSpeedPubTopic>motor_speed/0</motorSpeedPubTopic>
      <rotorVelocitySlowdownSim>1</rotorVelocitySlowdownSim>
    </plugin>
  </gazebo>
  <gazebo>
    <plugin filename="librotors_gazebo_motor_model.so" name="right_blade_link_motor_model">
      <robotNamespace>blimp</robotNamespace>
      <jointName>stick_right_blade_joint</jointName>
      <linkName>right_blade_link</linkName>
      <turningDirection>cw</turningDirection>
      <timeConstantUp>1</timeConstantUp>
      <timeConstantDown>1</timeConstantDown>
      <maxRotVelocity>879.23</maxRotVelocity>
      <motorConstant>0.00371178707</motorConstant>
      <momentConstant>0.016</momentConstant>
      <commandSubTopic>gazebo/command/motor_speed</commandSubTopic>
      <motorNumber>1</motorNumber>
      <rotorDragCoefficient>8.06428e-05</rotorDragCoefficient>
      <rollingMomentCoefficient>1e-06</rollingMomentCoefficient>
      <motorSpeedPubTopic>motor_speed/1</motorSpeedPubTopic>
      <rotorVelocitySlowdownSim>1</rotorVelocitySlowdownSim>
    </plugin>
  </gazebo>
  <gazebo>
    <plugin filename="librotors_gazebo_motor_model.so" name="bot_rud_motor_link_motor_model">
      <robotNamespace>blimp</robotNamespace>
      <jointName>bot_rud_part1_bot_rud_motor_joint</jointName>
      <linkName>bot_rud_motor_link</linkName>
      <turningDirection>cw</turningDirection>
      <timeConstantUp>1</timeConstantUp>
      <timeConstantDown>1</timeConstantDown>
      <maxRotVelocity>879.23</maxRotVelocity>
      <motorConstant>0.00371178707</motorConstant>
      <momentConstant>0.016</momentConstant>
      <commandSubTopic>gazebo/command/motor_speed</commandSubTopic>
      <motorNumber>2</motorNumber>
      <rotorDragCoefficient>8.06428e-05</rotorDragCoefficient>
      <rollingMomentCoefficient>1e-06</rollingMomentCoefficient>
      <motorSpeedPubTopic>motor_speed/2</motorSpeedPubTopic>
      <rotorVelocitySlowdownSim>1</rotorVelocitySlowdownSim>
    </plugin>
  </gazebo>
  <transmission name="tran1">
    <type>transmission_interface/SimpleTransmission</type>
    <joint name="base_stick_joint">
      <hardwareInterface>hardware_interface/PositionJointInterface</hardwareInterface>
    </joint>
    <actuator name="motor1">
      <mechanicalReduction>1</mechanicalReduction>
    </actuator>
  </transmission>
  <transmission name="tran2">
    <type>transmission_interface/SimpleTransmission</type>
    <joint name="bot_rud_part1_bot_rud_joint_link_joint">
      <hardwareInterface>hardware_interface/PositionJointInterface</hardwareInterface>
    </joint>
    <actuator name="motor2">
      <mechanicalReduction>1</mechanicalReduction>
    </actuator>
  </transmission>
  <transmission name="tran3">
    <type>transmission_interface/SimpleTransmission</type>
    <joint name="top_rud_part1_top_rud_joint_link_joint">
      <hardwareInterface>hardware_interface/PositionJointInterface</hardwareInterface>
    </joint>
    <actuator name="motor3">
      <mechanicalReduction>1</mechanicalReduction>
    </actuator>
  </transmission>
  <transmission name="tran4">
    <type>transmission_interface/SimpleTransmission</type>
    <joint name="left_elv_part1_left_elv_joint_link_joint">
      <hardwareInterface>hardware_interface/PositionJointInterface</hardwareInterface>
    </joint>
    <actuator name="motor4">
      <mechanicalReduction>1</mechanicalReduction>
    </actuator>
  </transmission>
  <transmission name="tran5">
    <type>transmission_interface/SimpleTransmission</type>
    <joint name="right_elv_part1_right_elv_joint_link_joint">
      <hardwareInterface>hardware_interface/PositionJointInterface</hardwareInterface>
    </joint>
    <actuator name="motor5">
      <mechanicalReduction>1</mechanicalReduction>
    </actuator>
  </transmission>
  <!--TODO: add compass -->
  <!--TODO: add Gimbo Camera -->
  <!-- IMU link -->
  <link name="imugt_link">
    <inertial>
      <inertia ixx="0.00001" ixy="0.0" ixz="0.0" iyy="0.00001" iyz="0.0" izz="0.00001"/>
      <mass value="1e-05"/>
      <!-- [kg] -->
      <origin rpy="0 0 0" xyz="0 0 0"/>
    </inertial>
  </link>
  <!-- IMU joint -->
  <joint name="imugt_joint" type="revolute">
    <origin rpy="0 0 0" xyz="0 0 0"/>
    <parent link="base_link"/>
    <child link="imugt_link"/>
    <limit effort="0" lower="0" upper="0" velocity="0"/>
  </joint>
  <gazebo>
    <plugin filename="librotors_gazebo_imu_plugin.so" name="rotors_gazebo_imugt_plugin">
      <!-- A good description of the IMU parameters can be found in the kalibr documentation:
           https://github.com/ethz-asl/kalibr/wiki/IMU-Noise-Model-and-Intrinsics -->
      <robotNamespace>blimp</robotNamespace>
      <!-- (string, required): ros namespace in which the messages are published -->
      <linkName>imugt_link</linkName>
      <!-- (string, required): name of the body which holds the IMU sensor -->
      <imuTopic>ground_truth/imu</imuTopic>
      <!-- (string): name of the sensor output topic and prefix of service names (defaults to imu) -->
      <gyroscopeNoiseDensity>0.0</gyroscopeNoiseDensity>
      <!-- Gyroscope noise density (two-sided spectrum) [rad/s/sqrt(Hz)] -->
      <gyroscopeRandomWalk>0.0</gyroscopeRandomWalk>
      <!-- Gyroscope bias random walk [rad/s/s/sqrt(Hz)] -->
      <gyroscopeBiasCorrelationTime>1000.0</gyroscopeBiasCorrelationTime>
      <!-- Gyroscope bias correlation time constant [s] -->
      <gyroscopeTurnOnBiasSigma>0.0</gyroscopeTurnOnBiasSigma>
      <!-- Gyroscope turn on bias standard deviation [rad/s] -->
      <accelerometerNoiseDensity>0.0</accelerometerNoiseDensity>
      <!-- Accelerometer noise density (two-sided spectrum) [m/s^2/sqrt(Hz)] -->
      <accelerometerRandomWalk>0.0</accelerometerRandomWalk>
      <!-- Accelerometer bias random walk. [m/s^2/s/sqrt(Hz)] -->
      <accelerometerBiasCorrelationTime>300.0</accelerometerBiasCorrelationTime>
      <!-- Accelerometer bias correlation time constant [s] -->
      <accelerometerTurnOnBiasSigma>0.0</accelerometerTurnOnBiasSigma>
      <!-- Accelerometer turn on bias standard deviation [m/s^2] -->
    </plugin>
  </gazebo>
  <!-- odometry link -->
  <link name="odometry_sensorgt_link">
    <inertial>
      <inertia ixx="0.00001" ixy="0.0" ixz="0.0" iyy="0.00001" iyz="0.0" izz="0.00001"/>
      <mass value="1e-05"/>
      <!-- [kg] -->
    </inertial>
  </link>
  <!-- odometry joint -->
  <joint name="odometry_sensorgt_joint" type="revolute">
    <parent link="base_link"/>
    <origin rpy="0.0 0.0 0.0" xyz="0.0 0.0 0.0"/>
    <child link="odometry_sensorgt_link"/>
    <limit effort="0" lower="0" upper="0" velocity="0"/>
  </joint>
  <gazebo>
    <plugin filename="librotors_gazebo_odometry_plugin.so" name="odometry_sensorgt">
      <linkName>odometry_sensorgt_link</linkName>
      <robotNamespace>blimp</robotNamespace>
      <poseTopic>ground_truth/pose</poseTopic>
      <poseWithCovarianceTopic>ground_truth/pose_with_covariance</poseWithCovarianceTopic>
      <positionTopic>ground_truth/position</positionTopic>
      <transformTopic>ground_truth/transform</transformTopic>
      <odometryTopic>ground_truth/odometry</odometryTopic>
      <parentFrameId>world</parentFrameId>
      <!-- Use the scoped link name here. e.g. Model::link. -->
      <childFrameId>base_link</childFrameId>
      <measurementDivisor>1</measurementDivisor>
      <!-- only every (seq % measurementDivisor) == 0 measurement is published [int] -->
      <measurementDelay>0</measurementDelay>
      <!-- time that measurement gets held back before it's published in [simulation cycles (int)] -->
      <unknownDelay>0.0</unknownDelay>
      <!-- additional delay, that just gets added to the timestamp [s] -->
      <noiseNormalPosition>0 0 0</noiseNormalPosition>
      <!-- standard deviation of additive white gaussian noise [m] -->
      <noiseNormalQuaternion>0 0 0</noiseNormalQuaternion>
      <!-- standard deviation white gaussian noise [rad]: q_m = q*quaternionFromSmallAngleApproximation(noiseNormalQ) -->
      <noiseNormalLinearVelocity>0 0 0</noiseNormalLinearVelocity>
      <!-- standard deviation of additive white gaussian noise [m/s] -->
      <noiseNormalAngularVelocity>0 0 0</noiseNormalAngularVelocity>
      <!-- standard deviation of additive white gaussian noise [rad/s] -->
      <noiseUniformPosition>0 0 0</noiseUniformPosition>
      <!-- symmetric bounds of uniform noise [m] -->
      <noiseUniformQuaternion>0 0 0</noiseUniformQuaternion>
      <!-- symmetric bounds of uniform noise [rad], computation see above -->
      <noiseUniformLinearVelocity>0 0 0</noiseUniformLinearVelocity>
      <!-- symmetric bounds of uniform noise [m/s] -->
      <noiseUniformAngularVelocity>0 0 0</noiseUniformAngularVelocity>
    </plugin>
  </gazebo>
  <!-- GPS link -->
  <link name="gps_blimp_link">
    <inertial>
      <inertia ixx="0.00001" ixy="0.0" ixz="0.0" iyy="0.00001" iyz="0.0" izz="0.00001"/>
      <mass value="0.015"/>
      <!-- [kg] -->
      <origin rpy="0 0 0" xyz="0 0 0"/>
    </inertial>
  </link>
  <!-- GPS joint -->
  <joint name="gps_blimp_joint" type="revolute">
    <origin rpy="0 0 0" xyz="0 0 0"/>
    <parent link="top_rud_part1_link"/>
    <child link="gps_blimp_link"/>
    <limit effort="0" lower="0" upper="0" velocity="0"/>
  </joint>
  <gazebo reference="gps_blimp_link">
    <sensor name="blimp_gps_blimp" type="gps">
      <pose>0 0 0 0 0 0</pose>
      <visualize>0</visualize>
      <always_on>1</always_on>
      <update_rate>1000</update_rate>
      <gps>
        <position_sensing>
          <horizontal>
            <noise type="gaussian">
              <mean>0.0</mean>
              <stddev>0.0</stddev>
              <bias_mean>0.0</bias_mean>
              <bias_stddev>0.0</bias_stddev>
            </noise>
          </horizontal>
          <vertical>
            <noise type="gaussian">
              <mean>0.0</mean>
              <stddev>0.0</stddev>
              <bias_mean>0.0</bias_mean>
              <bias_stddev>0.0</bias_stddev>
            </noise>
          </vertical>
        </position_sensing>
        <velocity_sensing>
          <horizontal>
            <noise type="gaussian">
              <mean>0.0</mean>
              <stddev>0.0</stddev>
              <bias_mean>0.0</bias_mean>
              <bias_stddev>0.0</bias_stddev>
            </noise>
          </horizontal>
          <vertical>
            <noise type="gaussian">
              <mean>0.0</mean>
              <stddev>0.0</stddev>
              <bias_mean>0.0</bias_mean>
              <bias_stddev>0.0</bias_stddev>
            </noise>
          </vertical>
        </velocity_sensing>
      </gps>
      <plugin filename="librotors_gazebo_gps_plugin.so" name="rotors_gazebo_gps_blimp_plugin">
        <robotNamespace>blimp</robotNamespace>
        <!-- (string, required): ros namespace in which the messages are published -->
        <linkName>gps_blimp_link</linkName>
        <!-- (string, required): name of the body which holds the GPS sensor -->
        <gpsTopic>gps</gpsTopic>
        <!-- (string): name of the sensor output topic and prefix of service names (defaults to 'gps') -->
        <groundSpeedTopic>ground_speed</groundSpeedTopic>
        <!-- (string): name of the ground speed output topic (defaults to 'ground_speed') -->
        <horPosStdDev>0.0</horPosStdDev>
        <!-- standard deviation for horizontal position noise [m] -->
        <verPosStdDev>0.0</verPosStdDev>
        <!-- standard deviation for vertical position noise [m] -->
        <horVelStdDev>0.0</horVelStdDev>
        <!-- standard deviation for horizontal speed noise [m/s] -->
        <verVelStdDev>0.0</verVelStdDev>
        <!-- standard deviation for vertical speed noise [m/s] -->
      </plugin>
    </sensor>
  </gazebo>
  <!-- IMU link -->
  <link name="imutail_link">
    <inertial>
      <inertia ixx="0.00001" ixy="0.0" ixz="0.0" iyy="0.00001" iyz="0.0" izz="0.00001"/>
      <mass value="1e-05"/>
      <!-- [kg] -->
      <origin rpy="0 0 0" xyz="0 0 0"/>
    </inertial>
  </link>
  <!-- IMU joint -->
  <joint name="imutail_joint" type="revolute">
    <origin rpy="3.141592653589793 0 0" xyz="0 0 0"/>
    <parent link="top_rud_part1_link"/>
    <child link="imutail_link"/>
    <limit effort="0" lower="0" upper="0" velocity="0"/>
  </joint>
  <gazebo>
    <plugin filename="librotors_gazebo_imu_plugin.so" name="rotors_gazebo_imutail_plugin">
      <!-- A good description of the IMU parameters can be found in the kalibr documentation:
           https://github.com/ethz-asl/kalibr/wiki/IMU-Noise-Model-and-Intrinsics -->
      <robotNamespace>blimp</robotNamespace>
      <!-- (string, required): ros namespace in which the messages are published -->
      <linkName>imutail_link</linkName>
      <!-- (string, required): name of the body which holds the IMU sensor -->
      <imuTopic>tail/imu</imuTopic>
      <!-- (string): name of the sensor output topic and prefix of service names (defaults to imu) -->
      <gyroscopeNoiseDensity>0.0</gyroscopeNoiseDensity>
      <!-- Gyroscope noise density (two-sided spectrum) [rad/s/sqrt(Hz)] -->
      <gyroscopeRandomWalk>0.0</gyroscopeRandomWalk>
      <!-- Gyroscope bias random walk [rad/s/s/sqrt(Hz)] -->
      <gyroscopeBiasCorrelationTime>1000.0</gyroscopeBiasCorrelationTime>
      <!-- Gyroscope bias correlation time constant [s] -->
      <gyroscopeTurnOnBiasSigma>0.0</gyroscopeTurnOnBiasSigma>
      <!-- Gyroscope turn on bias standard deviation [rad/s] -->
      <accelerometerNoiseDensity>0.0</accelerometerNoiseDensity>
      <!-- Accelerometer noise density (two-sided spectrum) [m/s^2/sqrt(Hz)] -->
      <accelerometerRandomWalk>0.0</accelerometerRandomWalk>
      <!-- Accelerometer bias random walk. [m/s^2/s/sqrt(Hz)] -->
      <accelerometerBiasCorrelationTime>300.0</accelerometerBiasCorrelationTime>
      <!-- Accelerometer bias correlation time constant [s] -->
      <accelerometerTurnOnBiasSigma>0.0</accelerometerTurnOnBiasSigma>
      <!-- Accelerometer turn on bias standard deviation [m/s^2] -->
    </plugin>
  </gazebo>
  <!-- odometry link -->
  <link name="odometry_sensortail_link">
    <inertial>
      <inertia ixx="0.00001" ixy="0.0" ixz="0.0" iyy="0.00001" iyz="0.0" izz="0.00001"/>
      <mass value="1e-05"/>
      <!-- [kg] -->
    </inertial>
  </link>
  <!-- odometry joint -->
  <joint name="odometry_sensortail_joint" type="revolute">
    <parent link="top_rud_part1_link"/>
    <origin rpy="3.141592653589793 0.0 0.0" xyz="0.0 0.0 0.0"/>
    <child link="odometry_sensortail_link"/>
    <limit effort="0" lower="0" upper="0" velocity="0"/>
  </joint>
  <gazebo>
    <plugin filename="librotors_gazebo_odometry_plugin.so" name="odometry_sensortail">
      <linkName>odometry_sensortail_link</linkName>
      <robotNamespace>blimp</robotNamespace>
      <poseTopic>tail/pose</poseTopic>
      <poseWithCovarianceTopic>tail/pose_with_covariance</poseWithCovarianceTopic>
      <positionTopic>tail/position</positionTopic>
      <transformTopic>tail/transform</transformTopic>
      <odometryTopic>tail/odometry</odometryTopic>
      <parentFrameId>world</parentFrameId>
      <!-- Use the scoped link name here. e.g. Model::link. -->
      <childFrameId>top_rud_part1_link</childFrameId>
      <measurementDivisor>1</measurementDivisor>
      <!-- only every (seq % measurementDivisor) == 0 measurement is published [int] -->
      <measurementDelay>0</measurementDelay>
      <!-- time that measurement gets held back before it's published in [simulation cycles (int)] -->
      <unknownDelay>0.0</unknownDelay>
      <!-- additional delay, that just gets added to the timestamp [s] -->
      <noiseNormalPosition>0 0 0</noiseNormalPosition>
      <!-- standard deviation of additive white gaussian noise [m] -->
      <noiseNormalQuaternion>0 0 0</noiseNormalQuaternion>
      <!-- standard deviation white gaussian noise [rad]: q_m = q*quaternionFromSmallAngleApproximation(noiseNormalQ) -->
      <noiseNormalLinearVelocity>0 0 0</noiseNormalLinearVelocity>
      <!-- standard deviation of additive white gaussian noise [m/s] -->
      <noiseNormalAngularVelocity>0 0 0</noiseNormalAngularVelocity>
      <!-- standard deviation of additive white gaussian noise [rad/s] -->
      <noiseUniformPosition>0 0 0</noiseUniformPosition>
      <!-- symmetric bounds of uniform noise [m] -->
      <noiseUniformQuaternion>0 0 0</noiseUniformQuaternion>
      <!-- symmetric bounds of uniform noise [rad], computation see above -->
      <noiseUniformLinearVelocity>0 0 0</noiseUniformLinearVelocity>
      <!-- symmetric bounds of uniform noise [m/s] -->
      <noiseUniformAngularVelocity>0 0 0</noiseUniformAngularVelocity>
    </plugin>
  </gazebo>
  <!--<xacro:vi_sensor_camera_macro 
			namespace="${namespace}" 
			parent_link="gondola_body_link" 
			mass="0.425" 
			camera_suffix="1"
			frame_rate="60">
			<xacro:insert_block name="origin_camera" />
		</xacro:vi_sensor_camera_macro>-->
  <!--<xacro:include filename="$(find blimp_description)/urdf/asus_camera.urdf.xacro" />
		<xacro:asus_camera
		    name="xtion"
		    parent="gondola_body_link">
		    <origin xyz="0.18 0.0 0.07" rpy="0 0.7853 0"/>
		</xacro:asus_camera>-->
  <gazebo>
    <plugin filename="libfinliftdrag_plugin.so" name="forward_lift_joint_link_finliftdrag">
      <robotNamespace>blimp</robotNamespace>
      <link_name>forward_lift_joint_link</link_name>
      <air_density>1.2041</air_density>
      <cw0>0.08</cw0>
      <cw1>0.6</cw1>
      <cw2>1.2</cw2>
      <cl0>0</cl0>
      <cl1>1.2</cl1>
      <cl2>0</cl2>
      <alpha_stall>0.3839724354387525</alpha_stall>
      <a0>0</a0>
      <area>1.57</area>
      <radial_symmetry>True</radial_symmetry>
      <upward>0 1 0</upward>
      <forward>1 0 0</forward>
      <cp>0 0 0</cp>
    </plugin>
  </gazebo>
  <gazebo>
    <plugin filename="libfinliftdrag_plugin.so" name="aft_lift_joint_link_finliftdrag">
      <robotNamespace>blimp</robotNamespace>
      <link_name>aft_lift_joint_link</link_name>
      <air_density>1.2041</air_density>
      <cw0>0</cw0>
      <cw1>0.6</cw1>
      <cw2>1.2</cw2>
      <cl0>0</cl0>
      <cl1>1.2</cl1>
      <cl2>0</cl2>
      <alpha_stall>0.3839724354387525</alpha_stall>
      <a0>0</a0>
      <area>1.57</area>
      <radial_symmetry>True</radial_symmetry>
      <upward>0 1 0</upward>
      <forward>1 0 0</forward>
      <cp>0 0 0</cp>
    </plugin>
  </gazebo>
  <gazebo>
    <plugin filename="libfinliftdrag_plugin.so" name="bot_rud_part1_link_finliftdrag">
      <robotNamespace>blimp</robotNamespace>
      <link_name>bot_rud_part1_link</link_name>
      <air_density>1.2041</air_density>
      <cw0>0.075</cw0>
      <cw1>0.6375</cw1>
      <cw2>1.2</cw2>
      <cl0>0</cl0>
      <cl1>0.6</cl1>
      <cl2>0</cl2>
      <alpha_stall>0.3839724354387525</alpha_stall>
      <a0>0</a0>
      <area>0.16</area>
      <radial_symmetry>False</radial_symmetry>
      <upward>0 -1 0</upward>
      <forward>1 0 0</forward>
      <cp>0 0 0</cp>
    </plugin>
  </gazebo>
  <gazebo>
    <plugin filename="libfinliftdrag_plugin.so" name="top_rud_part1_link_finliftdrag">
      <robotNamespace>blimp</robotNamespace>
      <link_name>top_rud_part1_link</link_name>
      <air_density>1.2041</air_density>
      <cw0>0.075</cw0>
      <cw1>0.6375</cw1>
      <cw2>1.2</cw2>
      <cl0>0</cl0>
      <cl1>0.6</cl1>
      <cl2>0</cl2>
      <alpha_stall>0.3839724354387525</alpha_stall>
      <a0>0</a0>
      <area>0.16</area>
      <airspeedPubTopic>tail/indicatedAirspeed</airspeedPubTopic>
      <radial_symmetry>False</radial_symmetry>
      <upward>0 1 0</upward>
      <forward>1 0 0</forward>
      <cp>0 0 0</cp>
    </plugin>
  </gazebo>
  <gazebo>
    <plugin filename="libfinliftdrag_plugin.so" name="left_elv_part1_link_finliftdrag">
      <robotNamespace>blimp</robotNamespace>
      <link_name>left_elv_part1_link</link_name>
      <air_density>1.2041</air_density>
      <cw0>0.075</cw0>
      <cw1>0.6375</cw1>
      <cw2>1.2</cw2>
      <cl0>0</cl0>
      <cl1>0.6</cl1>
      <cl2>0</cl2>
      <alpha_stall>0.3839724354387525</alpha_stall>
      <a0>0</a0>
      <area>0.16</area>
      <radial_symmetry>False</radial_symmetry>
      <upward>0 1 0</upward>
      <forward>1 0 0</forward>
      <cp>0 0 0</cp>
    </plugin>
  </gazebo>
  <gazebo>
    <plugin filename="libfinliftdrag_plugin.so" name="right_elv_part1_link_finliftdrag">
      <robotNamespace>blimp</robotNamespace>
      <link_name>right_elv_part1_link</link_name>
      <air_density>1.2041</air_density>
      <cw0>0.075</cw0>
      <cw1>0.6375</cw1>
      <cw2>1.2</cw2>
      <cl0>0</cl0>
      <cl1>0.6</cl1>
      <cl2>0</cl2>
      <alpha_stall>0.3839724354387525</alpha_stall>
      <a0>0</a0>
      <area>0.16</area>
      <radial_symmetry>False</radial_symmetry>
      <upward>0 -1 0</upward>
      <forward>1 0 0</forward>
      <cp>0 0 0</cp>
    </plugin>
  </gazebo>
  <gazebo>
    <plugin filename="libfinliftdrag_plugin.so" name="bot_rud_joint_link_finliftdrag">
      <robotNamespace>blimp</robotNamespace>
      <link_name>bot_rud_joint_link</link_name>
      <air_density>1.2041</air_density>
      <cw0>0</cw0>
      <cw1>0.6</cw1>
      <cw2>1.2</cw2>
      <cl0>0</cl0>
      <cl1>2.0</cl1>
      <cl2>0</cl2>
      <alpha_stall>0.3839724354387525</alpha_stall>
      <a0>0</a0>
      <area>0.16</area>
      <radial_symmetry>False</radial_symmetry>
      <upward>0 -1 0</upward>
      <forward>1 0 0</forward>
      <cp>0 0 0</cp>
    </plugin>
  </gazebo>
  <gazebo>
    <plugin filename="libfinliftdrag_plugin.so" name="top_rud_joint_link_finliftdrag">
      <robotNamespace>blimp</robotNamespace>
      <link_name>top_rud_joint_link</link_name>
      <air_density>1.2041</air_density>
      <cw0>0</cw0>
      <cw1>0.6</cw1>
      <cw2>1.2</cw2>
      <cl0>0</cl0>
      <cl1>2.0</cl1>
      <cl2>0</cl2>
      <alpha_stall>0.3839724354387525</alpha_stall>
      <a0>0</a0>
      <area>0.16</area>
      <radial_symmetry>False</radial_symmetry>
      <upward>0 1 0</upward>
      <forward>1 0 0</forward>
      <cp>0 0 0</cp>
    </plugin>
  </gazebo>
  <gazebo>
    <plugin filename="libfinliftdrag_plugin.so" name="left_elv_joint_link_finliftdrag">
      <robotNamespace>blimp</robotNamespace>
      <link_name>left_elv_joint_link</link_name>
      <air_density>1.2041</air_density>
      <cw0>0</cw0>
      <cw1>0.6</cw1>
      <cw2>1.2</cw2>
      <cl0>0</cl0>
      <cl1>2.0</cl1>
      <cl2>0</cl2>
      <alpha_stall>0.3839724354387525</alpha_stall>
      <a0>0</a0>
      <area>0.16</area>
      <radial_symmetry>False</radial_symmetry>
      <upward>0 1 0</upward>
      <forward>1 0 0</forward>
      <cp>0 0 0</cp>
    </plugin>
  </gazebo>
  <gazebo>
    <plugin filename="libfinliftdrag_plugin.so" name="right_elv_joint_link_finliftdrag">
      <robotNamespace>blimp</robotNamespace>
      <link_name>right_elv_joint_link</link_name>
      <air_density>1.2041</air_density>
      <cw0>0</cw0>
      <cw1>0.6</cw1>
      <cw2>1.2</cw2>
      <cl0>0</cl0>
      <cl1>2.0</cl1>
      <cl2>0</cl2>
      <alpha_stall>0.3839724354387525</alpha_stall>
      <a0>0</a0>
      <area>0.16</area>
      <radial_symmetry>False</radial_symmetry>
      <upward>0 -1 0</upward>
      <forward>1 0 0</forward>
      <cp>0 0 0</cp>
    </plugin>
  </gazebo>
  <gazebo>
    <plugin filename="libdynamicvolume_plugin.so" name="dynamicvolume_plugin">
      <robotNamespace>blimp</robotNamespace>
      <linkName>blimp_body_link</linkName>
      <dynamicvolumetopic>dynamicvolumetopic</dynamicvolumetopic>
      <heliummasstopic>heliummasstopic</heliummasstopic>
      <heliummass>1.723</heliummass>
      <reference_altitude>341.0</reference_altitude>
    </plugin>
  </gazebo>
</robot>

