<sdf version='1.7'>
  <model name='blimp'>
    <link name='base_link'>
      <inertial>
        <pose>0 0 0.050831 0 -0 0</pose>
        <mass>1.505</mass>
        <inertia>
          <ixx>0.0214388</ixx>
          <ixy>3.46972e-19</ixy>
          <ixz>-2.89907e-20</ixz>
          <iyy>0.0369914</iyy>
          <iyz>2.1684e-19</iyz>
          <izz>0.0286943</izz>
        </inertia>
      </inertial>
      <collision name='base_link_fixed_joint_lump__gondola_body_link_collision'>
        <pose>0 0 0.1 0 -0 0</pose>
        <geometry>
          <mesh>
            <scale>1 1 1</scale>
            <uri>model://rblimp/meshes/blimp_gondola/blimp_gondola_v4.dae</uri>
          </mesh>
        </geometry>
        <surface>
          <contact>
            <ode>
              <kp>1e+06</kp>
              <kd>1e+06</kd>
            </ode>
          </contact>
          <friction>
            <ode>
              <mu>10</mu>
              <mu2>10</mu2>
            </ode>
          </friction>
        </surface>
      </collision>
      <collision name='base_link_fixed_joint_lump__gondola_left_support_link_collision_1'>
        <pose>0 0.1 -0.085 0.4 -0 0</pose>
        <geometry>
          <mesh>
            <scale>1 1 1</scale>
            <uri>model://rblimp/meshes/blimp_support/blimp_support_v5.dae</uri>
          </mesh>
        </geometry>
        <surface>
          <contact>
            <ode>
              <kp>1e+06</kp>
              <kd>1e+06</kd>
            </ode>
          </contact>
          <friction>
            <ode>
              <mu>10</mu>
              <mu2>10</mu2>
            </ode>
          </friction>
        </surface>
      </collision>
      <collision name='base_link_fixed_joint_lump__gondola_right_support_link_collision_2'>
        <pose>0 -0.1 -0.085 0.4 -0 3.14159</pose>
        <geometry>
          <mesh>
            <scale>1 1 1</scale>
            <uri>model://rblimp/meshes/blimp_support/blimp_support_v5.dae</uri>
          </mesh>
        </geometry>
        <surface>
          <contact>
            <ode>
              <kp>1e+06</kp>
              <kd>1e+06</kd>
            </ode>
          </contact>
          <friction>
            <ode>
              <mu>10</mu>
              <mu2>10</mu2>
            </ode>
          </friction>
        </surface>
      </collision>
      <visual name='base_link_fixed_joint_lump__gondola_body_link_visual'>
        <pose>0 0 0.1 0 -0 0</pose>
        <geometry>
          <mesh>
            <scale>1 1 1</scale>
            <uri>model://rblimp/meshes/blimp_gondola/blimp_gondola_v4.dae</uri>
          </mesh>
        </geometry>
      </visual>
      <visual name='base_link_fixed_joint_lump__gondola_left_support_link_visual_1'>
        <pose>0 0.1 -0.085 0.4 -0 0</pose>
        <geometry>
          <mesh>
            <scale>1 1 1</scale>
            <uri>model://rblimp/meshes/blimp_support/blimp_support_v5.dae</uri>
          </mesh>
        </geometry>
      </visual>
      <visual name='base_link_fixed_joint_lump__gondola_right_support_link_visual_2'>
        <pose>0 -0.1 -0.085 0.4 -0 3.14159</pose>
        <geometry>
          <mesh>
            <scale>1 1 1</scale>
            <uri>model://rblimp/meshes/blimp_support/blimp_support_v5.dae</uri>
          </mesh>
        </geometry>
      </visual>
    </link>
    <joint name='blimp/gondola_body_joint_link_joint0' type='revolute'>
      <pose relative_to='base_link'>0 0 0.1 0 -0 0</pose>
      <parent>base_link</parent>
      <child>gondola_body_joint_link0</child>
      <axis>
        <xyz>1 0 0</xyz>
        <limit>
          <lower>0</lower>
          <upper>0</upper>
          <effort>-1</effort>
          <velocity>-1</velocity>
        </limit>
        <dynamics>
          <damping>0.5</damping>
          <friction>0</friction>
          <spring_reference>0</spring_reference>
          <spring_stiffness>0</spring_stiffness>
        </dynamics>
      </axis>
      <physics>
        <ode>
          <limit>
            <cfm>0.5</cfm>
            <erp>0.2</erp>
          </limit>
        </ode>
      </physics>
    </joint>
    <link name='gondola_body_joint_link0'>
      <pose relative_to='blimp/gondola_body_joint_link_joint0'>0 0 0 0 -0 0</pose>
      <inertial>
        <pose>0 0 0 0 -0 0</pose>
        <mass>0.0001</mass>
        <inertia>
          <ixx>0.01</ixx>
          <ixy>0</ixy>
          <ixz>0</ixz>
          <iyy>0.01</iyy>
          <iyz>0</iyz>
          <izz>0.01</izz>
        </inertia>
      </inertial>
    </link>
    <joint name='blimp/gondola_body_joint_link_joint1' type='revolute'>
      <pose relative_to='gondola_body_joint_link0'>0 0 0 0 -0 0</pose>
      <parent>gondola_body_joint_link0</parent>
      <child>gondola_body_joint_link1</child>
      <axis>
        <xyz>0 1 0</xyz>
        <limit>
          <lower>0</lower>
          <upper>0</upper>
          <effort>-1</effort>
          <velocity>-1</velocity>
        </limit>
        <dynamics>
          <damping>0.5</damping>
          <friction>0</friction>
          <spring_reference>0</spring_reference>
          <spring_stiffness>0</spring_stiffness>
        </dynamics>
      </axis>
      <physics>
        <ode>
          <limit>
            <cfm>0.1</cfm>
            <erp>0.2</erp>
          </limit>
        </ode>
      </physics>
    </joint>
    <link name='gondola_body_joint_link1'>
      <pose relative_to='blimp/gondola_body_joint_link_joint1'>0 0 0 0 -0 0</pose>
      <inertial>
        <pose>0 0 0 0 -0 0</pose>
        <mass>0.0001</mass>
        <inertia>
          <ixx>0.01</ixx>
          <ixy>0</ixy>
          <ixz>0</ixz>
          <iyy>0.01</iyy>
          <iyz>0</iyz>
          <izz>0.01</izz>
        </inertia>
      </inertial>
    </link>
    <joint name='blimp/gondola_body_joint_link_joint' type='revolute'>
      <pose relative_to='gondola_body_joint_link1'>0 0 0 0 -0 0</pose>
      <parent>gondola_body_joint_link1</parent>
      <child>gondola_body_joint_link</child>
      <axis>
        <xyz>0 0 1</xyz>
        <limit>
          <lower>0</lower>
          <upper>0</upper>
          <effort>-1</effort>
          <velocity>-1</velocity>
        </limit>
        <dynamics>
          <damping>0.5</damping>
          <friction>0</friction>
          <spring_reference>0</spring_reference>
          <spring_stiffness>0</spring_stiffness>
        </dynamics>
      </axis>
      <physics>
        <ode>
          <limit>
            <cfm>0.05</cfm>
            <erp>0.2</erp>
          </limit>
        </ode>
      </physics>
    </joint>
    <link name='gondola_body_joint_link'>
      <pose relative_to='blimp/gondola_body_joint_link_joint'>0 0 0 0 -0 0</pose>
      <inertial>
        <pose>0 0 0 0 -0 0</pose>
        <mass>0.0001</mass>
        <inertia>
          <ixx>0.01</ixx>
          <ixy>0</ixy>
          <ixz>0</ixz>
          <iyy>0.01</iyy>
          <iyz>0</iyz>
          <izz>0.01</izz>
        </inertia>
      </inertial>
      <visual name='gondola_body_joint_link_visual'>
        <pose>0 0 0 0 -0 0</pose>
        <geometry>
          <cylinder>
            <length>0.3</length>
            <radius>0.01</radius>
          </cylinder>
        </geometry>
      </visual>
    </link>
    <joint name='gondola_joint_blimb_body_joint' type='revolute'>
      <pose relative_to='gondola_body_joint_link'>-1 0 1.05 0 1.5708 0</pose>
      <parent>gondola_body_joint_link</parent>
      <child>blimp_body_link</child>
      <axis>
        <xyz>1 0 0</xyz>
        <limit>
          <lower>0</lower>
          <upper>0</upper>
          <effort>1000</effort>
          <velocity>1000</velocity>
        </limit>
        <dynamics>
          <spring_reference>0</spring_reference>
          <spring_stiffness>0</spring_stiffness>
        </dynamics>
      </axis>
    </joint>
    <link name='blimp_body_link'>
      <pose relative_to='gondola_joint_blimb_body_joint'>0 0 0 0 -0 0</pose>
      <inertial>
        <pose>0 0 0 0 -0 0</pose>
        <mass>4.622</mass>
        <inertia>
          <ixx>7.49137</ixx>
          <ixy>0</ixy>
          <ixz>0</ixz>
          <iyy>7.49137</iyy>
          <iyz>0</iyz>
          <izz>2.89942</izz>
        </inertia>
      </inertial>
      <collision name='blimp_body_link_collision'>
        <pose>0 0 0 0 -0 0</pose>
        <geometry>
          <mesh>
            <scale>1 1 1</scale>
            <uri>model://rblimp/meshes/blimp_body/blimp_body_v4.dae</uri>
          </mesh>
        </geometry>
        <surface>
          <contact>
            <ode>
              <kp>1e+06</kp>
              <kd>1e+06</kd>
            </ode>
          </contact>
          <friction>
            <ode>
              <mu>10</mu>
              <mu2>10</mu2>
            </ode>
          </friction>
        </surface>
      </collision>
      <visual name='blimp_body_link_visual'>
        <pose>0 0 0 0 -0 0</pose>
        <geometry>
          <mesh>
            <scale>1 1 1</scale>
            <uri>model://rblimp/meshes/blimp_body/blimp_body_v4.dae</uri>
          </mesh>
        </geometry>
      </visual>
    </link>
    <joint name='blimp/bot_rud_base_joint_link_joint0' type='revolute'>
      <pose relative_to='blimp_body_link'>0.59 0 -1.5 0 -1.5708 0</pose>
      <parent>blimp_body_link</parent>
      <child>bot_rud_base_joint_link0</child>
      <axis>
        <xyz>1 0 0</xyz>
        <limit>
          <lower>0</lower>
          <upper>0</upper>
          <effort>-1</effort>
          <velocity>-1</velocity>
        </limit>
        <dynamics>
          <damping>0.5</damping>
          <friction>0</friction>
          <spring_reference>0</spring_reference>
          <spring_stiffness>0</spring_stiffness>
        </dynamics>
      </axis>
      <physics>
        <ode>
          <limit>
            <cfm>1</cfm>
            <erp>0.2</erp>
          </limit>
        </ode>
      </physics>
    </joint>
    <link name='bot_rud_base_joint_link0'>
      <pose relative_to='blimp/bot_rud_base_joint_link_joint0'>0 0 0 0 -0 0</pose>
      <inertial>
        <pose>0 0 0 0 -0 0</pose>
        <mass>0.0001</mass>
        <inertia>
          <ixx>0.01</ixx>
          <ixy>0</ixy>
          <ixz>0</ixz>
          <iyy>0.01</iyy>
          <iyz>0</iyz>
          <izz>0.01</izz>
        </inertia>
      </inertial>
    </link>
    <joint name='blimp/bot_rud_base_joint_link_joint1' type='revolute'>
      <pose relative_to='bot_rud_base_joint_link0'>0 0 0 0 -0 0</pose>
      <parent>bot_rud_base_joint_link0</parent>
      <child>bot_rud_base_joint_link1</child>
      <axis>
        <xyz>0 1 0</xyz>
        <limit>
          <lower>0</lower>
          <upper>0</upper>
          <effort>-1</effort>
          <velocity>-1</velocity>
        </limit>
        <dynamics>
          <damping>0.5</damping>
          <friction>0</friction>
          <spring_reference>0</spring_reference>
          <spring_stiffness>0</spring_stiffness>
        </dynamics>
      </axis>
      <physics>
        <ode>
          <limit>
            <cfm>0.2</cfm>
            <erp>0.2</erp>
          </limit>
        </ode>
      </physics>
    </joint>
    <link name='bot_rud_base_joint_link1'>
      <pose relative_to='blimp/bot_rud_base_joint_link_joint1'>0 0 0 0 -0 0</pose>
      <inertial>
        <pose>0 0 0 0 -0 0</pose>
        <mass>0.0001</mass>
        <inertia>
          <ixx>0.01</ixx>
          <ixy>0</ixy>
          <ixz>0</ixz>
          <iyy>0.01</iyy>
          <iyz>0</iyz>
          <izz>0.01</izz>
        </inertia>
      </inertial>
    </link>
    <joint name='blimp/bot_rud_base_joint_link_joint' type='revolute'>
      <pose relative_to='bot_rud_base_joint_link1'>0 0 0 0 -0 0</pose>
      <parent>bot_rud_base_joint_link1</parent>
      <child>bot_rud_base_joint_link</child>
      <axis>
        <xyz>0 0 1</xyz>
        <limit>
          <lower>0</lower>
          <upper>0</upper>
          <effort>-1</effort>
          <velocity>-1</velocity>
        </limit>
        <dynamics>
          <damping>0.5</damping>
          <friction>0</friction>
          <spring_reference>0</spring_reference>
          <spring_stiffness>0</spring_stiffness>
        </dynamics>
      </axis>
      <physics>
        <ode>
          <limit>
            <cfm>0.1</cfm>
            <erp>0.2</erp>
          </limit>
        </ode>
      </physics>
    </joint>
    <link name='bot_rud_base_joint_link'>
      <pose relative_to='blimp/bot_rud_base_joint_link_joint'>0 0 0 0 -0 0</pose>
      <inertial>
        <pose>0 0 0 0 -0 0</pose>
        <mass>0.0001</mass>
        <inertia>
          <ixx>0.01</ixx>
          <ixy>0</ixy>
          <ixz>0</ixz>
          <iyy>0.01</iyy>
          <iyz>0</iyz>
          <izz>0.01</izz>
        </inertia>
      </inertial>
      <visual name='bot_rud_base_joint_link_visual'>
        <pose>0 0 0 0 -0 0</pose>
        <geometry>
          <cylinder>
            <length>0.3</length>
            <radius>0.01</radius>
          </cylinder>
        </geometry>
      </visual>
    </link>
    <joint name='blimp_body_bot_rud_part1_joint' type='revolute'>
      <pose relative_to='bot_rud_base_joint_link'>0 0 -0.24 0 -0 0</pose>
      <parent>bot_rud_base_joint_link</parent>
      <child>bot_rud_part1_link</child>
      <axis>
        <xyz>1 0 0</xyz>
        <limit>
          <lower>0</lower>
          <upper>0</upper>
          <effort>1000</effort>
          <velocity>1000</velocity>
        </limit>
        <dynamics>
          <spring_reference>0</spring_reference>
          <spring_stiffness>0</spring_stiffness>
        </dynamics>
      </axis>
    </joint>
    <link name='bot_rud_part1_link'>
      <pose relative_to='blimp_body_bot_rud_part1_joint'>0 0 0 0 -0 0</pose>
      <inertial>
        <pose>0 0 0 0 -0 0</pose>
        <mass>0.41</mass>
        <inertia>
          <ixx>0.0111553</ixx>
          <ixy>0</ixy>
          <ixz>0</ixz>
          <iyy>0.0257568</iyy>
          <iyz>0</iyz>
          <izz>0.0146402</izz>
        </inertia>
      </inertial>
      <collision name='bot_rud_part1_link_collision'>
        <pose>0 0 0 0 -0 0</pose>
        <geometry>
          <mesh>
            <scale>1 1 1</scale>
            <uri>model://rblimp/meshes/blimp_fin/blimp_bot_rud_part1_v3.dae</uri>
          </mesh>
        </geometry>
        <surface>
          <contact>
            <ode>
              <kp>1e+06</kp>
              <kd>1e+06</kd>
            </ode>
          </contact>
          <friction>
            <ode>
              <mu>10</mu>
              <mu2>10</mu2>
            </ode>
          </friction>
        </surface>
      </collision>
      <visual name='bot_rud_part1_link_visual'>
        <pose>0 0 0 0 -0 0</pose>
        <geometry>
          <mesh>
            <scale>1 1 1</scale>
            <uri>model://rblimp/meshes/blimp_fin/blimp_bot_rud_part1_v3.dae</uri>
          </mesh>
        </geometry>
      </visual>
    </link>
    <joint name='bot_rud_part1_bot_rud_joint_link_joint' type='revolute'>
      <pose relative_to='bot_rud_part1_link'>-0.28 0 0 0 -0 0</pose>
      <parent>bot_rud_part1_link</parent>
      <child>bot_rud_joint_link</child>
      <axis>
        <xyz>0 0 1</xyz>
        <limit>
          <lower>-1.0472</lower>
          <upper>1.0472</upper>
          <effort>500</effort>
          <velocity>2</velocity>
        </limit>
        <dynamics>
          <spring_reference>0</spring_reference>
          <spring_stiffness>0</spring_stiffness>
        </dynamics>
      </axis>
    </joint>
    <link name='bot_rud_joint_link'>
      <pose relative_to='bot_rud_part1_bot_rud_joint_link_joint'>0 0 0 0 -0 0</pose>
      <inertial>
        <pose>-0.125 0 0 0 -0 0</pose>
        <mass>0.113</mass>
        <inertia>
          <ixx>0.00217337</ixx>
          <ixy>0</ixy>
          <ixz>0</ixz>
          <iyy>0.0030171</iyy>
          <iyz>0</iyz>
          <izz>0.000851266</izz>
        </inertia>
      </inertial>
      <collision name='bot_rud_joint_link_fixed_joint_lump__bot_rud_part2_link_collision'>
        <pose>-0.125 0 0 0 -0 0</pose>
        <geometry>
          <mesh>
            <scale>1 1 1</scale>
            <uri>model://rblimp/meshes/blimp_fin/blimp_top_rud_part2_v5.dae</uri>
          </mesh>
        </geometry>
        <surface>
          <contact>
            <ode>
              <kp>1e+06</kp>
              <kd>1e+06</kd>
            </ode>
          </contact>
          <friction>
            <ode>
              <mu>10</mu>
              <mu2>10</mu2>
            </ode>
          </friction>
        </surface>
      </collision>
      <visual name='bot_rud_joint_link_visual'>
        <pose>0 0 0 0 -0 0</pose>
        <geometry>
          <cylinder>
            <length>0.3</length>
            <radius>0.01</radius>
          </cylinder>
        </geometry>
      </visual>
      <visual name='bot_rud_joint_link_fixed_joint_lump__bot_rud_part2_link_visual_1'>
        <pose>-0.125 0 0 0 -0 0</pose>
        <geometry>
          <mesh>
            <scale>1 1 1</scale>
            <uri>model://rblimp/meshes/blimp_fin/blimp_top_rud_part2_v5.dae</uri>
          </mesh>
        </geometry>
      </visual>
    </link>
    <joint name='bot_rud_part1_bot_rud_motor_joint' type='revolute'>
      <pose relative_to='bot_rud_part1_link'>-0.065 0.01 -0.025 -1.5708 0 0</pose>
      <parent>bot_rud_part1_link</parent>
      <child>bot_rud_motor_link</child>
      <axis>
        <xyz>0 0 -1</xyz>
        <limit>
          <lower>-1e+16</lower>
          <upper>1e+16</upper>
        </limit>
        <dynamics>
          <spring_reference>0</spring_reference>
          <spring_stiffness>0</spring_stiffness>
        </dynamics>
      </axis>
    </joint>
    <link name='bot_rud_motor_link'>
      <pose relative_to='bot_rud_part1_bot_rud_motor_joint'>0 0 0 0 -0 0</pose>
      <inertial>
        <pose>0 0 0 0 -0 0</pose>
        <mass>0.127</mass>
        <inertia>
          <ixx>0.000662252</ixx>
          <ixy>0</ixy>
          <ixz>0</ixz>
          <iyy>0.000662252</iyy>
          <iyz>0</iyz>
          <izz>1.5875e-06</izz>
        </inertia>
      </inertial>
      <collision name='bot_rud_motor_link_collision'>
        <pose>0 0 0 0 -0 0</pose>
        <geometry>
          <mesh>
            <scale>1 1 1</scale>
            <uri>model://rblimp/meshes/blimp_propeller/blimp_bot_propeller_cw_v3.dae</uri>
          </mesh>
        </geometry>
        <surface>
          <contact>
            <ode>
              <kp>1e+06</kp>
              <kd>1e+06</kd>
            </ode>
          </contact>
          <friction>
            <ode>
              <mu>10</mu>
              <mu2>10</mu2>
            </ode>
          </friction>
        </surface>
      </collision>
      <visual name='bot_rud_motor_link_visual'>
        <pose>0 0 0 0 -0 0</pose>
        <geometry>
          <mesh>
            <scale>1 1 1</scale>
            <uri>model://rblimp/meshes/blimp_propeller/blimp_bot_propeller_cw_v3.dae</uri>
          </mesh>
        </geometry>
      </visual>
    </link>
    <joint name='blimp/left_elv_base_joint_link_joint0' type='revolute'>
      <pose relative_to='blimp_body_link'>0 0.59 -1.5 1.5708 -1.5708 0</pose>
      <parent>blimp_body_link</parent>
      <child>left_elv_base_joint_link0</child>
      <axis>
        <xyz>1 0 0</xyz>
        <limit>
          <lower>0</lower>
          <upper>0</upper>
          <effort>-1</effort>
          <velocity>-1</velocity>
        </limit>
        <dynamics>
          <damping>0.5</damping>
          <friction>0</friction>
          <spring_reference>0</spring_reference>
          <spring_stiffness>0</spring_stiffness>
        </dynamics>
      </axis>
      <physics>
        <ode>
          <limit>
            <cfm>1</cfm>
            <erp>0.2</erp>
          </limit>
        </ode>
      </physics>
    </joint>
    <link name='left_elv_base_joint_link0'>
      <pose relative_to='blimp/left_elv_base_joint_link_joint0'>0 0 0 0 -0 0</pose>
      <inertial>
        <pose>0 0 0 0 -0 0</pose>
        <mass>0.0001</mass>
        <inertia>
          <ixx>0.01</ixx>
          <ixy>0</ixy>
          <ixz>0</ixz>
          <iyy>0.01</iyy>
          <iyz>0</iyz>
          <izz>0.01</izz>
        </inertia>
      </inertial>
    </link>
    <joint name='blimp/left_elv_base_joint_link_joint1' type='revolute'>
      <pose relative_to='left_elv_base_joint_link0'>0 0 0 0 -0 0</pose>
      <parent>left_elv_base_joint_link0</parent>
      <child>left_elv_base_joint_link1</child>
      <axis>
        <xyz>0 1 0</xyz>
        <limit>
          <lower>0</lower>
          <upper>0</upper>
          <effort>-1</effort>
          <velocity>-1</velocity>
        </limit>
        <dynamics>
          <damping>0.5</damping>
          <friction>0</friction>
          <spring_reference>0</spring_reference>
          <spring_stiffness>0</spring_stiffness>
        </dynamics>
      </axis>
      <physics>
        <ode>
          <limit>
            <cfm>0.2</cfm>
            <erp>0.2</erp>
          </limit>
        </ode>
      </physics>
    </joint>
    <link name='left_elv_base_joint_link1'>
      <pose relative_to='blimp/left_elv_base_joint_link_joint1'>0 0 0 0 -0 0</pose>
      <inertial>
        <pose>0 0 0 0 -0 0</pose>
        <mass>0.0001</mass>
        <inertia>
          <ixx>0.01</ixx>
          <ixy>0</ixy>
          <ixz>0</ixz>
          <iyy>0.01</iyy>
          <iyz>0</iyz>
          <izz>0.01</izz>
        </inertia>
      </inertial>
    </link>
    <joint name='blimp/left_elv_base_joint_link_joint' type='revolute'>
      <pose relative_to='left_elv_base_joint_link1'>0 0 0 0 -0 0</pose>
      <parent>left_elv_base_joint_link1</parent>
      <child>left_elv_base_joint_link</child>
      <axis>
        <xyz>0 0 1</xyz>
        <limit>
          <lower>0</lower>
          <upper>0</upper>
          <effort>-1</effort>
          <velocity>-1</velocity>
        </limit>
        <dynamics>
          <damping>0.5</damping>
          <friction>0</friction>
          <spring_reference>0</spring_reference>
          <spring_stiffness>0</spring_stiffness>
        </dynamics>
      </axis>
      <physics>
        <ode>
          <limit>
            <cfm>0.1</cfm>
            <erp>0.2</erp>
          </limit>
        </ode>
      </physics>
    </joint>
    <link name='left_elv_base_joint_link'>
      <pose relative_to='blimp/left_elv_base_joint_link_joint'>0 0 0 0 -0 0</pose>
      <inertial>
        <pose>0 0 0 0 -0 0</pose>
        <mass>0.0001</mass>
        <inertia>
          <ixx>0.01</ixx>
          <ixy>0</ixy>
          <ixz>0</ixz>
          <iyy>0.01</iyy>
          <iyz>0</iyz>
          <izz>0.01</izz>
        </inertia>
      </inertial>
      <visual name='left_elv_base_joint_link_visual'>
        <pose>0 0 0 0 -0 0</pose>
        <geometry>
          <cylinder>
            <length>0.3</length>
            <radius>0.01</radius>
          </cylinder>
        </geometry>
      </visual>
    </link>
    <joint name='blimp_body_left_elv_part1_joint' type='revolute'>
      <pose relative_to='left_elv_base_joint_link'>0 0 -0.24 0 -0 0</pose>
      <parent>left_elv_base_joint_link</parent>
      <child>left_elv_part1_link</child>
      <axis>
        <xyz>1 0 0</xyz>
        <limit>
          <lower>0</lower>
          <upper>0</upper>
          <effort>1000</effort>
          <velocity>1000</velocity>
        </limit>
        <dynamics>
          <spring_reference>0</spring_reference>
          <spring_stiffness>0</spring_stiffness>
        </dynamics>
      </axis>
    </joint>
    <link name='left_elv_part1_link'>
      <pose relative_to='blimp_body_left_elv_part1_joint'>0 0 0 0 -0 0</pose>
      <inertial>
        <pose>0 0 0 0 -0 0</pose>
        <mass>0.58</mass>
        <inertia>
          <ixx>0.0111553</ixx>
          <ixy>0</ixy>
          <ixz>0</ixz>
          <iyy>0.0257568</iyy>
          <iyz>0</iyz>
          <izz>0.0146402</izz>
        </inertia>
      </inertial>
      <collision name='left_elv_part1_link_collision'>
        <pose>0 0 0 0 -0 0</pose>
        <geometry>
          <mesh>
            <scale>1 1 1</scale>
            <uri>model://rblimp/meshes/blimp_fin/blimp_top_rud_part1_v3.dae</uri>
          </mesh>
        </geometry>
        <surface>
          <contact>
            <ode>
              <kp>1e+06</kp>
              <kd>1e+06</kd>
            </ode>
          </contact>
          <friction>
            <ode>
              <mu>10</mu>
              <mu2>10</mu2>
            </ode>
          </friction>
        </surface>
      </collision>
      <visual name='left_elv_part1_link_visual'>
        <pose>0 0 0 0 -0 0</pose>
        <geometry>
          <mesh>
            <scale>1 1 1</scale>
            <uri>model://rblimp/meshes/blimp_fin/blimp_top_rud_part1_v3.dae</uri>
          </mesh>
        </geometry>
      </visual>
    </link>
    <joint name='left_elv_part1_left_elv_joint_link_joint' type='revolute'>
      <pose relative_to='left_elv_part1_link'>-0.28 0 0 0 -0 0</pose>
      <parent>left_elv_part1_link</parent>
      <child>left_elv_joint_link</child>
      <axis>
        <xyz>0 0 1</xyz>
        <limit>
          <lower>-1.0472</lower>
          <upper>1.0472</upper>
          <effort>500</effort>
          <velocity>2</velocity>
        </limit>
        <dynamics>
          <spring_reference>0</spring_reference>
          <spring_stiffness>0</spring_stiffness>
        </dynamics>
      </axis>
    </joint>
    <link name='left_elv_joint_link'>
      <pose relative_to='left_elv_part1_left_elv_joint_link_joint'>0 0 0 0 -0 0</pose>
      <inertial>
        <pose>-0.125 0 0 0 -0 0</pose>
        <mass>0.113</mass>
        <inertia>
          <ixx>0.00217337</ixx>
          <ixy>0</ixy>
          <ixz>0</ixz>
          <iyy>0.0030171</iyy>
          <iyz>0</iyz>
          <izz>0.000851266</izz>
        </inertia>
      </inertial>
      <collision name='left_elv_joint_link_fixed_joint_lump__left_elv_part2_link_collision'>
        <pose>-0.125 0 0 0 -0 0</pose>
        <geometry>
          <mesh>
            <scale>1 1 1</scale>
            <uri>model://rblimp/meshes/blimp_fin/blimp_top_rud_part2_v5.dae</uri>
          </mesh>
        </geometry>
        <surface>
          <contact>
            <ode>
              <kp>1e+06</kp>
              <kd>1e+06</kd>
            </ode>
          </contact>
          <friction>
            <ode>
              <mu>10</mu>
              <mu2>10</mu2>
            </ode>
          </friction>
        </surface>
      </collision>
      <visual name='left_elv_joint_link_visual'>
        <pose>0 0 0 0 -0 0</pose>
        <geometry>
          <cylinder>
            <length>0.3</length>
            <radius>0.01</radius>
          </cylinder>
        </geometry>
      </visual>
      <visual name='left_elv_joint_link_fixed_joint_lump__left_elv_part2_link_visual_1'>
        <pose>-0.125 0 0 0 -0 0</pose>
        <geometry>
          <mesh>
            <scale>1 1 1</scale>
            <uri>model://rblimp/meshes/blimp_fin/blimp_top_rud_part2_v5.dae</uri>
          </mesh>
        </geometry>
      </visual>
    </link>
    <joint name='blimp/right_elv_base_joint_link_joint0' type='revolute'>
      <pose relative_to='blimp_body_link'>0 -0.59 -1.5 -1.5708 -1.5708 0</pose>
      <parent>blimp_body_link</parent>
      <child>right_elv_base_joint_link0</child>
      <axis>
        <xyz>1 0 0</xyz>
        <limit>
          <lower>0</lower>
          <upper>0</upper>
          <effort>-1</effort>
          <velocity>-1</velocity>
        </limit>
        <dynamics>
          <damping>0.5</damping>
          <friction>0</friction>
          <spring_reference>0</spring_reference>
          <spring_stiffness>0</spring_stiffness>
        </dynamics>
      </axis>
      <physics>
        <ode>
          <limit>
            <cfm>1</cfm>
            <erp>0.2</erp>
          </limit>
        </ode>
      </physics>
    </joint>
    <link name='right_elv_base_joint_link0'>
      <pose relative_to='blimp/right_elv_base_joint_link_joint0'>0 0 0 0 -0 0</pose>
      <inertial>
        <pose>0 0 0 0 -0 0</pose>
        <mass>0.0001</mass>
        <inertia>
          <ixx>0.01</ixx>
          <ixy>0</ixy>
          <ixz>0</ixz>
          <iyy>0.01</iyy>
          <iyz>0</iyz>
          <izz>0.01</izz>
        </inertia>
      </inertial>
    </link>
    <joint name='blimp/right_elv_base_joint_link_joint1' type='revolute'>
      <pose relative_to='right_elv_base_joint_link0'>0 0 0 0 -0 0</pose>
      <parent>right_elv_base_joint_link0</parent>
      <child>right_elv_base_joint_link1</child>
      <axis>
        <xyz>0 1 0</xyz>
        <limit>
          <lower>0</lower>
          <upper>0</upper>
          <effort>-1</effort>
          <velocity>-1</velocity>
        </limit>
        <dynamics>
          <damping>0.5</damping>
          <friction>0</friction>
          <spring_reference>0</spring_reference>
          <spring_stiffness>0</spring_stiffness>
        </dynamics>
      </axis>
      <physics>
        <ode>
          <limit>
            <cfm>0.2</cfm>
            <erp>0.2</erp>
          </limit>
        </ode>
      </physics>
    </joint>
    <link name='right_elv_base_joint_link1'>
      <pose relative_to='blimp/right_elv_base_joint_link_joint1'>0 0 0 0 -0 0</pose>
      <inertial>
        <pose>0 0 0 0 -0 0</pose>
        <mass>0.0001</mass>
        <inertia>
          <ixx>0.01</ixx>
          <ixy>0</ixy>
          <ixz>0</ixz>
          <iyy>0.01</iyy>
          <iyz>0</iyz>
          <izz>0.01</izz>
        </inertia>
      </inertial>
    </link>
    <joint name='blimp/right_elv_base_joint_link_joint' type='revolute'>
      <pose relative_to='right_elv_base_joint_link1'>0 0 0 0 -0 0</pose>
      <parent>right_elv_base_joint_link1</parent>
      <child>right_elv_base_joint_link</child>
      <axis>
        <xyz>0 0 1</xyz>
        <limit>
          <lower>0</lower>
          <upper>0</upper>
          <effort>-1</effort>
          <velocity>-1</velocity>
        </limit>
        <dynamics>
          <damping>0.5</damping>
          <friction>0</friction>
          <spring_reference>0</spring_reference>
          <spring_stiffness>0</spring_stiffness>
        </dynamics>
      </axis>
      <physics>
        <ode>
          <limit>
            <cfm>0.1</cfm>
            <erp>0.2</erp>
          </limit>
        </ode>
      </physics>
    </joint>
    <link name='right_elv_base_joint_link'>
      <pose relative_to='blimp/right_elv_base_joint_link_joint'>0 0 0 0 -0 0</pose>
      <inertial>
        <pose>0 0 0 0 -0 0</pose>
        <mass>0.0001</mass>
        <inertia>
          <ixx>0.01</ixx>
          <ixy>0</ixy>
          <ixz>0</ixz>
          <iyy>0.01</iyy>
          <iyz>0</iyz>
          <izz>0.01</izz>
        </inertia>
      </inertial>
      <visual name='right_elv_base_joint_link_visual'>
        <pose>0 0 0 0 -0 0</pose>
        <geometry>
          <cylinder>
            <length>0.3</length>
            <radius>0.01</radius>
          </cylinder>
        </geometry>
      </visual>
    </link>
    <joint name='blimp_body_right_elv_part1_joint' type='revolute'>
      <pose relative_to='right_elv_base_joint_link'>0 0 -0.24 0 -0 0</pose>
      <parent>right_elv_base_joint_link</parent>
      <child>right_elv_part1_link</child>
      <axis>
        <xyz>1 0 0</xyz>
        <limit>
          <lower>0</lower>
          <upper>0</upper>
          <effort>1000</effort>
          <velocity>1000</velocity>
        </limit>
        <dynamics>
          <spring_reference>0</spring_reference>
          <spring_stiffness>0</spring_stiffness>
        </dynamics>
      </axis>
    </joint>
    <link name='right_elv_part1_link'>
      <pose relative_to='blimp_body_right_elv_part1_joint'>0 0 0 0 -0 0</pose>
      <inertial>
        <pose>0 0 0 0 -0 0</pose>
        <mass>0.58</mass>
        <inertia>
          <ixx>0.0111553</ixx>
          <ixy>0</ixy>
          <ixz>0</ixz>
          <iyy>0.0257568</iyy>
          <iyz>0</iyz>
          <izz>0.0146402</izz>
        </inertia>
      </inertial>
      <collision name='right_elv_part1_link_collision'>
        <pose>0 0 0 0 -0 0</pose>
        <geometry>
          <mesh>
            <scale>1 1 1</scale>
            <uri>model://rblimp/meshes/blimp_fin/blimp_top_rud_part1_v3.dae</uri>
          </mesh>
        </geometry>
        <surface>
          <contact>
            <ode>
              <kp>1e+06</kp>
              <kd>1e+06</kd>
            </ode>
          </contact>
          <friction>
            <ode>
              <mu>10</mu>
              <mu2>10</mu2>
            </ode>
          </friction>
        </surface>
      </collision>
      <visual name='right_elv_part1_link_visual'>
        <pose>0 0 0 0 -0 0</pose>
        <geometry>
          <mesh>
            <scale>1 1 1</scale>
            <uri>model://rblimp/meshes/blimp_fin/blimp_top_rud_part1_v3.dae</uri>
          </mesh>
        </geometry>
      </visual>
    </link>
    <joint name='right_elv_part1_right_elv_joint_link_joint' type='revolute'>
      <pose relative_to='right_elv_part1_link'>-0.28 0 0 0 -0 0</pose>
      <parent>right_elv_part1_link</parent>
      <child>right_elv_joint_link</child>
      <axis>
        <xyz>0 0 -1</xyz>
        <limit>
          <lower>-1.0472</lower>
          <upper>1.0472</upper>
          <effort>500</effort>
          <velocity>2</velocity>
        </limit>
        <dynamics>
          <spring_reference>0</spring_reference>
          <spring_stiffness>0</spring_stiffness>
        </dynamics>
      </axis>
    </joint>
    <link name='right_elv_joint_link'>
      <pose relative_to='right_elv_part1_right_elv_joint_link_joint'>0 0 0 0 -0 0</pose>
      <inertial>
        <pose>-0.125 0 0 0 -0 0</pose>
        <mass>0.113</mass>
        <inertia>
          <ixx>0.00217337</ixx>
          <ixy>0</ixy>
          <ixz>0</ixz>
          <iyy>0.0030171</iyy>
          <iyz>0</iyz>
          <izz>0.000851266</izz>
        </inertia>
      </inertial>
      <collision name='right_elv_joint_link_fixed_joint_lump__right_elv_part2_link_collision'>
        <pose>-0.125 0 0 0 -0 0</pose>
        <geometry>
          <mesh>
            <scale>1 1 1</scale>
            <uri>model://rblimp/meshes/blimp_fin/blimp_top_rud_part2_v5.dae</uri>
          </mesh>
        </geometry>
        <surface>
          <contact>
            <ode>
              <kp>1e+06</kp>
              <kd>1e+06</kd>
            </ode>
          </contact>
          <friction>
            <ode>
              <mu>10</mu>
              <mu2>10</mu2>
            </ode>
          </friction>
        </surface>
      </collision>
      <visual name='right_elv_joint_link_visual'>
        <pose>0 0 0 0 -0 0</pose>
        <geometry>
          <cylinder>
            <length>0.3</length>
            <radius>0.01</radius>
          </cylinder>
        </geometry>
      </visual>
      <visual name='right_elv_joint_link_fixed_joint_lump__right_elv_part2_link_visual_1'>
        <pose>-0.125 0 0 0 -0 0</pose>
        <geometry>
          <mesh>
            <scale>1 1 1</scale>
            <uri>model://rblimp/meshes/blimp_fin/blimp_top_rud_part2_v5.dae</uri>
          </mesh>
        </geometry>
      </visual>
    </link>
    <joint name='blimp/top_rud_base_joint_link_joint0' type='revolute'>
      <pose relative_to='blimp_body_link'>-0.59 0 -1.5 3.14159 -1.5708 0</pose>
      <parent>blimp_body_link</parent>
      <child>top_rud_base_joint_link0</child>
      <axis>
        <xyz>1 0 0</xyz>
        <limit>
          <lower>0</lower>
          <upper>0</upper>
          <effort>-1</effort>
          <velocity>-1</velocity>
        </limit>
        <dynamics>
          <damping>0.5</damping>
          <friction>0</friction>
          <spring_reference>0</spring_reference>
          <spring_stiffness>0</spring_stiffness>
        </dynamics>
      </axis>
      <physics>
        <ode>
          <limit>
            <cfm>1</cfm>
            <erp>0.2</erp>
          </limit>
        </ode>
      </physics>
    </joint>
    <link name='top_rud_base_joint_link0'>
      <pose relative_to='blimp/top_rud_base_joint_link_joint0'>0 0 0 0 -0 0</pose>
      <inertial>
        <pose>0 0 0 0 -0 0</pose>
        <mass>0.0001</mass>
        <inertia>
          <ixx>0.01</ixx>
          <ixy>0</ixy>
          <ixz>0</ixz>
          <iyy>0.01</iyy>
          <iyz>0</iyz>
          <izz>0.01</izz>
        </inertia>
      </inertial>
    </link>
    <joint name='blimp/top_rud_base_joint_link_joint1' type='revolute'>
      <pose relative_to='top_rud_base_joint_link0'>0 0 0 0 -0 0</pose>
      <parent>top_rud_base_joint_link0</parent>
      <child>top_rud_base_joint_link1</child>
      <axis>
        <xyz>0 1 0</xyz>
        <limit>
          <lower>0</lower>
          <upper>0</upper>
          <effort>-1</effort>
          <velocity>-1</velocity>
        </limit>
        <dynamics>
          <damping>0.5</damping>
          <friction>0</friction>
          <spring_reference>0</spring_reference>
          <spring_stiffness>0</spring_stiffness>
        </dynamics>
      </axis>
      <physics>
        <ode>
          <limit>
            <cfm>0.2</cfm>
            <erp>0.2</erp>
          </limit>
        </ode>
      </physics>
    </joint>
    <link name='top_rud_base_joint_link1'>
      <pose relative_to='blimp/top_rud_base_joint_link_joint1'>0 0 0 0 -0 0</pose>
      <inertial>
        <pose>0 0 0 0 -0 0</pose>
        <mass>0.0001</mass>
        <inertia>
          <ixx>0.01</ixx>
          <ixy>0</ixy>
          <ixz>0</ixz>
          <iyy>0.01</iyy>
          <iyz>0</iyz>
          <izz>0.01</izz>
        </inertia>
      </inertial>
    </link>
    <joint name='blimp/top_rud_base_joint_link_joint' type='revolute'>
      <pose relative_to='top_rud_base_joint_link1'>0 0 0 0 -0 0</pose>
      <parent>top_rud_base_joint_link1</parent>
      <child>top_rud_base_joint_link</child>
      <axis>
        <xyz>0 0 1</xyz>
        <limit>
          <lower>0</lower>
          <upper>0</upper>
          <effort>-1</effort>
          <velocity>-1</velocity>
        </limit>
        <dynamics>
          <damping>0.5</damping>
          <friction>0</friction>
          <spring_reference>0</spring_reference>
          <spring_stiffness>0</spring_stiffness>
        </dynamics>
      </axis>
      <physics>
        <ode>
          <limit>
            <cfm>0.1</cfm>
            <erp>0.2</erp>
          </limit>
        </ode>
      </physics>
    </joint>
    <link name='top_rud_base_joint_link'>
      <pose relative_to='blimp/top_rud_base_joint_link_joint'>0 0 0 0 -0 0</pose>
      <inertial>
        <pose>0 0 0 0 -0 0</pose>
        <mass>0.0001</mass>
        <inertia>
          <ixx>0.01</ixx>
          <ixy>0</ixy>
          <ixz>0</ixz>
          <iyy>0.01</iyy>
          <iyz>0</iyz>
          <izz>0.01</izz>
        </inertia>
      </inertial>
      <visual name='top_rud_base_joint_link_visual'>
        <pose>0 0 0 0 -0 0</pose>
        <geometry>
          <cylinder>
            <length>0.3</length>
            <radius>0.01</radius>
          </cylinder>
        </geometry>
      </visual>
    </link>
    <joint name='blimp_body_top_rud_part1_joint' type='revolute'>
      <pose relative_to='top_rud_base_joint_link'>0 0 -0.24 0 -0 0</pose>
      <parent>top_rud_base_joint_link</parent>
      <child>top_rud_part1_link</child>
      <axis>
        <xyz>1 0 0</xyz>
        <limit>
          <lower>0</lower>
          <upper>0</upper>
          <effort>1000</effort>
          <velocity>1000</velocity>
        </limit>
        <dynamics>
          <spring_reference>0</spring_reference>
          <spring_stiffness>0</spring_stiffness>
        </dynamics>
      </axis>
    </joint>
    <link name='top_rud_part1_link'>
      <pose relative_to='blimp_body_top_rud_part1_joint'>0 0 0 0 -0 0</pose>
      <inertial>
        <pose>0 0 0 0 -0 0</pose>
        <mass>0.58</mass>
        <inertia>
          <ixx>0.0111553</ixx>
          <ixy>0</ixy>
          <ixz>0</ixz>
          <iyy>0.0257568</iyy>
          <iyz>0</iyz>
          <izz>0.0146402</izz>
        </inertia>
      </inertial>
      <collision name='top_rud_part1_link_collision'>
        <pose>0 0 0 0 -0 0</pose>
        <geometry>
          <mesh>
            <scale>1 1 1</scale>
            <uri>model://rblimp/meshes/blimp_fin/blimp_top_rud_part1_v3.dae</uri>
          </mesh>
        </geometry>
        <surface>
          <contact>
            <ode>
              <kp>1e+06</kp>
              <kd>1e+06</kd>
            </ode>
          </contact>
          <friction>
            <ode>
              <mu>10</mu>
              <mu2>10</mu2>
            </ode>
          </friction>
        </surface>
      </collision>
      <visual name='top_rud_part1_link_visual'>
        <pose>0 0 0 0 -0 0</pose>
        <geometry>
          <mesh>
            <scale>1 1 1</scale>
            <uri>model://rblimp/meshes/blimp_fin/blimp_top_rud_part1_v3.dae</uri>
          </mesh>
        </geometry>
      </visual>
    </link>
    <joint name='gps_blimp_joint' type='revolute'>
      <pose relative_to='top_rud_part1_link'>0 0 0 0 -0 0</pose>
      <parent>top_rud_part1_link</parent>
      <child>gps_blimp_link</child>
      <axis>
        <xyz>1 0 0</xyz>
        <limit>
          <lower>0</lower>
          <upper>0</upper>
          <effort>0</effort>
          <velocity>0</velocity>
        </limit>
        <dynamics>
          <spring_reference>0</spring_reference>
          <spring_stiffness>0</spring_stiffness>
        </dynamics>
      </axis>
    </joint>
    <link name='gps_blimp_link'>
      <pose relative_to='gps_blimp_joint'>0 0 0 0 -0 0</pose>
      <inertial>
        <pose>0 0 0 0 -0 0</pose>
        <mass>0.015</mass>
        <inertia>
          <ixx>1e-05</ixx>
          <ixy>0</ixy>
          <ixz>0</ixz>
          <iyy>1e-05</iyy>
          <iyz>0</iyz>
          <izz>1e-05</izz>
        </inertia>
      </inertial>
      <sensor name='blimp_gps_blimp' type='gps'>
        <pose>0 0 0 0 -0 0</pose>
        <visualize>0</visualize>
        <always_on>1</always_on>
        <update_rate>1000</update_rate>
        <gps>
          <position_sensing>
            <horizontal>
              <noise type='gaussian'>
                <mean>0</mean>
                <stddev>0</stddev>
                <bias_mean>0</bias_mean>
                <bias_stddev>0</bias_stddev>
              </noise>
            </horizontal>
            <vertical>
              <noise type='gaussian'>
                <mean>0</mean>
                <stddev>0</stddev>
                <bias_mean>0</bias_mean>
                <bias_stddev>0</bias_stddev>
              </noise>
            </vertical>
          </position_sensing>
          <velocity_sensing>
            <horizontal>
              <noise type='gaussian'>
                <mean>0</mean>
                <stddev>0</stddev>
                <bias_mean>0</bias_mean>
                <bias_stddev>0</bias_stddev>
              </noise>
            </horizontal>
            <vertical>
              <noise type='gaussian'>
                <mean>0</mean>
                <stddev>0</stddev>
                <bias_mean>0</bias_mean>
                <bias_stddev>0</bias_stddev>
              </noise>
            </vertical>
          </velocity_sensing>
        </gps>
        <plugin name='gps_plugin' filename='libgazebo_gps_plugin.so'>
          <robotNamespace/>
          <gpsNoise>1</gpsNoise>
          <gpsXYRandomWalk>2.0</gpsXYRandomWalk>
          <gpsZRandomWalk>4.0</gpsZRandomWalk>
          <gpsXYNoiseDensity>0.0002</gpsXYNoiseDensity>
          <gpsZNoiseDensity>0.0004</gpsZNoiseDensity>
          <gpsVXYNoiseDensity>0.2</gpsVXYNoiseDensity>
          <gpsVZNoiseDensity>0.4</gpsVZNoiseDensity>
        </plugin>
        <!-- <plugin name='rotors_gazebo_gps_blimp_plugin' filename='librotors_gazebo_gps_plugin.so'>
          <robotNamespace>blimp</robotNamespace>
          <linkName>gps_blimp_link</linkName>
          <gpsTopic>gps</gpsTopic>
          <groundSpeedTopic>ground_speed</groundSpeedTopic>
          <horPosStdDev>0.0</horPosStdDev>
          <verPosStdDev>0.0</verPosStdDev>
          <horVelStdDev>0.0</horVelStdDev>
          <verVelStdDev>0.0</verVelStdDev>
        </plugin> -->
      </sensor>
    </link>
    <joint name='imutail_joint' type='revolute'>
      <pose relative_to='top_rud_part1_link'>0 0 0 3.14159 -0 0</pose>
      <parent>top_rud_part1_link</parent>
      <child>imutail_link</child>
      <axis>
        <xyz>1 0 0</xyz>
        <limit>
          <lower>0</lower>
          <upper>0</upper>
          <effort>0</effort>
          <velocity>0</velocity>
        </limit>
        <dynamics>
          <spring_reference>0</spring_reference>
          <spring_stiffness>0</spring_stiffness>
        </dynamics>
      </axis>
    </joint>
    <link name='imutail_link'>
      <pose relative_to='imutail_joint'>0 0 0 0 -0 0</pose>
      <inertial>
        <pose>0 0 0 0 -0 0</pose>
        <mass>1e-05</mass>
        <inertia>
          <ixx>1e-05</ixx>
          <ixy>0</ixy>
          <ixz>0</ixz>
          <iyy>1e-05</iyy>
          <iyz>0</iyz>
          <izz>1e-05</izz>
        </inertia>
      </inertial>
    </link>
    <joint name='odometry_sensortail_joint' type='revolute'>
      <pose relative_to='top_rud_part1_link'>0 0 0 3.14159 -0 0</pose>
      <parent>top_rud_part1_link</parent>
      <child>odometry_sensortail_link</child>
      <axis>
        <xyz>1 0 0</xyz>
        <limit>
          <lower>0</lower>
          <upper>0</upper>
          <effort>0</effort>
          <velocity>0</velocity>
        </limit>
        <dynamics>
          <spring_reference>0</spring_reference>
          <spring_stiffness>0</spring_stiffness>
        </dynamics>
      </axis>
    </joint>
    <link name='odometry_sensortail_link'>
      <pose relative_to='odometry_sensortail_joint'>0 0 0 0 -0 0</pose>
      <inertial>
        <pose>0 0 0 0 -0 0</pose>
        <mass>1e-05</mass>
        <inertia>
          <ixx>1e-05</ixx>
          <ixy>0</ixy>
          <ixz>0</ixz>
          <iyy>1e-05</iyy>
          <iyz>0</iyz>
          <izz>1e-05</izz>
        </inertia>
      </inertial>
    </link>
    <joint name='top_rud_part1_top_rud_joint_link_joint' type='revolute'>
      <pose relative_to='top_rud_part1_link'>-0.28 0 0 0 -0 0</pose>
      <parent>top_rud_part1_link</parent>
      <child>top_rud_joint_link</child>
      <axis>
        <xyz>0 0 -1</xyz>
        <limit>
          <lower>-1.0472</lower>
          <upper>1.0472</upper>
          <effort>500</effort>
          <velocity>2</velocity>
        </limit>
        <dynamics>
          <spring_reference>0</spring_reference>
          <spring_stiffness>0</spring_stiffness>
        </dynamics>
      </axis>
    </joint>
    <link name='top_rud_joint_link'>
      <pose relative_to='top_rud_part1_top_rud_joint_link_joint'>0 0 0 0 -0 0</pose>
      <inertial>
        <pose>-0.125 0 0 0 -0 0</pose>
        <mass>0.113</mass>
        <inertia>
          <ixx>0.00217337</ixx>
          <ixy>0</ixy>
          <ixz>0</ixz>
          <iyy>0.0030171</iyy>
          <iyz>0</iyz>
          <izz>0.000851266</izz>
        </inertia>
      </inertial>
      <collision name='top_rud_joint_link_fixed_joint_lump__top_rud_part2_link_collision'>
        <pose>-0.125 0 0 0 -0 0</pose>
        <geometry>
          <mesh>
            <scale>1 1 1</scale>
            <uri>model://rblimp/meshes/blimp_fin/blimp_top_rud_part2_v5.dae</uri>
          </mesh>
        </geometry>
        <surface>
          <contact>
            <ode>
              <kp>1e+06</kp>
              <kd>1e+06</kd>
            </ode>
          </contact>
          <friction>
            <ode>
              <mu>10</mu>
              <mu2>10</mu2>
            </ode>
          </friction>
        </surface>
      </collision>
      <visual name='top_rud_joint_link_visual'>
        <pose>0 0 0 0 -0 0</pose>
        <geometry>
          <cylinder>
            <length>0.3</length>
            <radius>0.01</radius>
          </cylinder>
        </geometry>
      </visual>
      <visual name='top_rud_joint_link_fixed_joint_lump__top_rud_part2_link_visual_1'>
        <pose>-0.125 0 0 0 -0 0</pose>
        <geometry>
          <mesh>
            <scale>1 1 1</scale>
            <uri>model://rblimp/meshes/blimp_fin/blimp_top_rud_part2_v5.dae</uri>
          </mesh>
        </geometry>
      </visual>
    </link>
    <joint name='blimp_body_aft_lift_joint' type='revolute'>
      <pose relative_to='blimp_body_link'>0 0 -0.3 1.5708 -1.5708 0</pose>
      <parent>blimp_body_link</parent>
      <child>aft_lift_joint_link</child>
      <axis>
        <xyz>1 0 0</xyz>
        <limit>
          <lower>0</lower>
          <upper>0</upper>
          <effort>1000</effort>
          <velocity>1000</velocity>
        </limit>
        <dynamics>
          <spring_reference>0</spring_reference>
          <spring_stiffness>0</spring_stiffness>
        </dynamics>
      </axis>
    </joint>
    <link name='aft_lift_joint_link'>
      <pose relative_to='blimp_body_aft_lift_joint'>0 0 0 0 -0 0</pose>
      <inertial>
        <pose>0 0 0 0 -0 0</pose>
        <mass>0.001</mass>
        <inertia>
          <ixx>0</ixx>
          <ixy>0</ixy>
          <ixz>0</ixz>
          <iyy>0</iyy>
          <iyz>0</iyz>
          <izz>0</izz>
        </inertia>
      </inertial>
      <visual name='aft_lift_joint_link_visual'>
        <pose>0 0 0 0 -0 0</pose>
        <geometry>
          <cylinder>
            <length>0.3</length>
            <radius>0.01</radius>
          </cylinder>
        </geometry>
      </visual>
    </link>
    <joint name='blimp_body_forward_lift_joint' type='revolute'>
      <pose relative_to='blimp_body_link'>0 0 2 1.5708 -1.5708 0</pose>
      <parent>blimp_body_link</parent>
      <child>forward_lift_joint_link</child>
      <axis>
        <xyz>1 0 0</xyz>
        <limit>
          <lower>0</lower>
          <upper>0</upper>
          <effort>1000</effort>
          <velocity>1000</velocity>
        </limit>
        <dynamics>
          <spring_reference>0</spring_reference>
          <spring_stiffness>0</spring_stiffness>
        </dynamics>
      </axis>
    </joint>
    <link name='forward_lift_joint_link'>
      <pose relative_to='blimp_body_forward_lift_joint'>0 0 0 0 -0 0</pose>
      <inertial>
        <pose>0 0 0 0 -0 0</pose>
        <mass>0.001</mass>
        <inertia>
          <ixx>0</ixx>
          <ixy>0</ixy>
          <ixz>0</ixz>
          <iyy>0</iyy>
          <iyz>0</iyz>
          <izz>0</izz>
        </inertia>
      </inertial>
      <visual name='forward_lift_joint_link_visual'>
        <pose>0 0 0 0 -0 0</pose>
        <geometry>
          <cylinder>
            <length>0.3</length>
            <radius>0.01</radius>
          </cylinder>
        </geometry>
      </visual>
    </link>
    <joint name='blimp_body_front_ballast_joint' type='revolute'>
      <pose relative_to='blimp_body_link'>0 0 2.5 0 -0 0</pose>
      <parent>blimp_body_link</parent>
      <child>front_ballast_joint_link</child>
      <axis>
        <xyz>1 0 0</xyz>
        <limit>
          <lower>0</lower>
          <upper>0</upper>
          <effort>1000</effort>
          <velocity>1000</velocity>
        </limit>
        <dynamics>
          <spring_reference>0</spring_reference>
          <spring_stiffness>0</spring_stiffness>
        </dynamics>
      </axis>
    </joint>
    <link name='front_ballast_joint_link'>
      <pose relative_to='blimp_body_front_ballast_joint'>0 0 0 0 -0 0</pose>
      <inertial>
        <pose>0 0 0 0 -0 0</pose>
        <mass>0.6</mass>
        <inertia>
          <ixx>0.00014</ixx>
          <ixy>0</ixy>
          <ixz>0</ixz>
          <iyy>0.00014</iyy>
          <iyz>0</iyz>
          <izz>3e-05</izz>
        </inertia>
      </inertial>
      <collision name='front_ballast_joint_link_collision'>
        <pose>0 0 0 0 -0 0</pose>
        <geometry>
          <cylinder>
            <length>0.05</length>
            <radius>0.01</radius>
          </cylinder>
        </geometry>
        <surface>
          <contact>
            <ode>
              <kp>1e+06</kp>
              <kd>1e+06</kd>
            </ode>
          </contact>
          <friction>
            <ode>
              <mu>10</mu>
              <mu2>10</mu2>
            </ode>
          </friction>
        </surface>
      </collision>
      <visual name='front_ballast_joint_link_visual'>
        <pose>0 0 0 0 -0 0</pose>
        <geometry>
          <cylinder>
            <length>0.05</length>
            <radius>0.01</radius>
          </cylinder>
        </geometry>
      </visual>
    </link>
    <joint name='base_stick_joint' type='revolute'>
      <pose relative_to='base_link'>-0.08 0 0.03 1.5708 -0 0</pose>
      <parent>base_link</parent>
      <child>stick_link</child>
      <axis>
        <xyz>0 0 -1</xyz>
        <limit>
          <lower>-1.74533</lower>
          <upper>1.74533</upper>
          <effort>1000</effort>
          <velocity>2</velocity>
        </limit>
        <dynamics>
          <spring_reference>0</spring_reference>
          <spring_stiffness>0</spring_stiffness>
        </dynamics>
      </axis>
    </joint>
    <link name='stick_link'>
      <pose relative_to='base_stick_joint'>0 0 0 0 -0 0</pose>
      <inertial>
        <pose>0 0.01173 0 0 -0 0</pose>
        <mass>1.705</mass>
        <inertia>
          <ixx>0.195486</ixx>
          <ixy>0</ixy>
          <ixz>0</ixz>
          <iyy>0.216802</iyy>
          <iyz>6.07153e-18</iyz>
          <izz>0.0218319</izz>
        </inertia>
      </inertial>
      <collision name='stick_link_collision'>
        <pose>0 0 0 0 -0 0</pose>
        <geometry>
          <mesh>
            <scale>1 1 1</scale>
            <uri>model://rblimp/meshes/blimp_wing/blimp_stick_v2.dae</uri>
          </mesh>
        </geometry>
        <surface>
          <contact>
            <ode>
              <kp>1e+06</kp>
              <kd>1e+06</kd>
            </ode>
          </contact>
          <friction>
            <ode>
              <mu>10</mu>
              <mu2>10</mu2>
            </ode>
          </friction>
        </surface>
      </collision>
      <collision name='stick_link_fixed_joint_lump__left_wing_link_collision_1'>
        <pose>0 0.02 -0.375 -1.5708 0 0</pose>
        <geometry>
          <mesh>
            <scale>1 1 1</scale>
            <uri>model://rblimp/meshes/blimp_wing/blimp_wing_v2.dae</uri>
          </mesh>
        </geometry>
        <surface>
          <contact>
            <ode>
              <kp>1e+06</kp>
              <kd>1e+06</kd>
            </ode>
          </contact>
          <friction>
            <ode>
              <mu>10</mu>
              <mu2>10</mu2>
            </ode>
          </friction>
        </surface>
      </collision>
      <collision name='stick_link_fixed_joint_lump__right_wing_link_collision_2'>
        <pose>0 0.02 0.375 -1.5708 0 0</pose>
        <geometry>
          <mesh>
            <scale>1 1 1</scale>
            <uri>model://rblimp/meshes/blimp_wing/blimp_wing_v2.dae</uri>
          </mesh>
        </geometry>
        <surface>
          <contact>
            <ode>
              <kp>1e+06</kp>
              <kd>1e+06</kd>
            </ode>
          </contact>
          <friction>
            <ode>
              <mu>10</mu>
              <mu2>10</mu2>
            </ode>
          </friction>
        </surface>
      </collision>
      <visual name='stick_link_visual'>
        <pose>0 0 0 0 -0 0</pose>
        <geometry>
          <mesh>
            <scale>1 1 1</scale>
            <uri>model://rblimp/meshes/blimp_wing/blimp_stick_v2.dae</uri>
          </mesh>
        </geometry>
      </visual>
      <visual name='stick_link_fixed_joint_lump__left_wing_link_visual_1'>
        <pose>0 0.02 -0.375 -1.5708 0 0</pose>
        <geometry>
          <mesh>
            <scale>1 1 1</scale>
            <uri>model://rblimp/meshes/blimp_wing/blimp_wing_v2.dae</uri>
          </mesh>
        </geometry>
      </visual>
      <visual name='stick_link_fixed_joint_lump__right_wing_link_visual_2'>
        <pose>0 0.02 0.375 -1.5708 0 0</pose>
        <geometry>
          <mesh>
            <scale>1 1 1</scale>
            <uri>model://rblimp/meshes/blimp_wing/blimp_wing_v2.dae</uri>
          </mesh>
        </geometry>
      </visual>
    </link>
    <joint name='stick_left_blade_joint' type='revolute'>
      <pose relative_to='stick_link'>0 0.025 -0.375 -1.5708 0 0</pose>
      <parent>stick_link</parent>
      <child>left_blade_link</child>
      <axis>
        <xyz>0 0 1</xyz>
        <limit>
          <lower>-1e+16</lower>
          <upper>1e+16</upper>
        </limit>
        <dynamics>
          <spring_reference>0</spring_reference>
          <spring_stiffness>0</spring_stiffness>
        </dynamics>
      </axis>
    </joint>
    <link name='left_blade_link'>
      <pose relative_to='stick_left_blade_joint'>0 0 0 0 -0 0</pose>
      <inertial>
        <pose>0 0 0 1.5708 -0 0</pose>
        <mass>0.05</mass>
        <inertia>
          <ixx>0.000635</ixx>
          <ixy>0</ixy>
          <ixz>0</ixz>
          <iyy>0.000635</iyy>
          <iyz>0</iyz>
          <izz>2.5e-06</izz>
        </inertia>
      </inertial>
      <collision name='left_blade_link_collision'>
        <pose>0 0 0 1.5708 -0 0</pose>
        <geometry>
          <mesh>
            <scale>1 1 1</scale>
            <uri>model://rblimp/meshes/blimp_propeller/blimp_left_propeller_ccw_v3.dae</uri>
          </mesh>
        </geometry>
        <surface>
          <contact>
            <ode>
              <kp>1e+06</kp>
              <kd>1e+06</kd>
            </ode>
          </contact>
          <friction>
            <ode>
              <mu>10</mu>
              <mu2>10</mu2>
            </ode>
          </friction>
        </surface>
      </collision>
      <visual name='left_blade_link_visual'>
        <pose>0 0 0 1.5708 -0 0</pose>
        <geometry>
          <mesh>
            <scale>1 1 1</scale>
            <uri>model://rblimp/meshes/blimp_propeller/blimp_left_propeller_ccw_v3.dae</uri>
          </mesh>
        </geometry>
      </visual>
    </link>
    <joint name='stick_right_blade_joint' type='revolute'>
      <pose relative_to='stick_link'>0 0.025 0.375 -1.5708 -0 3.14159</pose>
      <parent>stick_link</parent>
      <child>right_blade_link</child>
      <axis>
        <xyz>0 0 1</xyz>
        <limit>
          <lower>-1e+16</lower>
          <upper>1e+16</upper>
        </limit>
        <dynamics>
          <spring_reference>0</spring_reference>
          <spring_stiffness>0</spring_stiffness>
        </dynamics>
      </axis>
    </joint>
    <link name='right_blade_link'>
      <pose relative_to='stick_right_blade_joint'>0 0 0 0 -0 0</pose>
      <inertial>
        <pose>0 0 0 1.5708 -0 0</pose>
        <mass>0.05</mass>
        <inertia>
          <ixx>0.000635</ixx>
          <ixy>0</ixy>
          <ixz>0</ixz>
          <iyy>0.000635</iyy>
          <iyz>0</iyz>
          <izz>2.5e-06</izz>
        </inertia>
      </inertial>
      <collision name='right_blade_link_collision'>
        <pose>0 0 0 1.5708 -0 0</pose>
        <geometry>
          <mesh>
            <scale>1 1 1</scale>
            <uri>model://rblimp/meshes/blimp_propeller/blimp_right_propeller_cw_v3.dae</uri>
          </mesh>
        </geometry>
        <surface>
          <contact>
            <ode>
              <kp>1e+06</kp>
              <kd>1e+06</kd>
            </ode>
          </contact>
          <friction>
            <ode>
              <mu>10</mu>
              <mu2>10</mu2>
            </ode>
          </friction>
        </surface>
      </collision>
      <visual name='right_blade_link_visual'>
        <pose>0 0 0 1.5708 -0 0</pose>
        <geometry>
          <mesh>
            <scale>1 1 1</scale>
            <uri>model://rblimp/meshes/blimp_propeller/blimp_right_propeller_cw_v3.dae</uri>
          </mesh>
        </geometry>
      </visual>
    </link>
    <joint name='imugt_joint' type='revolute'>
      <pose relative_to='base_link'>0 0 0 0 -0 0</pose>
      <parent>base_link</parent>
      <child>imugt_link</child>
      <axis>
        <xyz>1 0 0</xyz>
        <limit>
          <lower>0</lower>
          <upper>0</upper>
          <effort>0</effort>
          <velocity>0</velocity>
        </limit>
        <dynamics>
          <spring_reference>0</spring_reference>
          <spring_stiffness>0</spring_stiffness>
        </dynamics>
      </axis>
    </joint>
    <link name='imugt_link'>
      <pose relative_to='imugt_joint'>0 0 0 0 -0 0</pose>
      <inertial>
        <pose>0 0 0 0 -0 0</pose>
        <mass>1e-05</mass>
        <inertia>
          <ixx>1e-05</ixx>
          <ixy>0</ixy>
          <ixz>0</ixz>
          <iyy>1e-05</iyy>
          <iyz>0</iyz>
          <izz>1e-05</izz>
        </inertia>
      </inertial>
    </link>
    <joint name='odometry_sensorgt_joint' type='revolute'>
      <pose relative_to='base_link'>0 0 0 0 -0 0</pose>
      <parent>base_link</parent>
      <child>odometry_sensorgt_link</child>
      <axis>
        <xyz>1 0 0</xyz>
        <limit>
          <lower>0</lower>
          <upper>0</upper>
          <effort>0</effort>
          <velocity>0</velocity>
        </limit>
        <dynamics>
          <spring_reference>0</spring_reference>
          <spring_stiffness>0</spring_stiffness>
        </dynamics>
      </axis>
    </joint>
    <link name='odometry_sensorgt_link'>
      <pose relative_to='odometry_sensorgt_joint'>0 0 0 0 -0 0</pose>
      <inertial>
        <pose>0 0 0 0 -0 0</pose>
        <mass>1e-05</mass>
        <inertia>
          <ixx>1e-05</ixx>
          <ixy>0</ixy>
          <ixz>0</ixz>
          <iyy>1e-05</iyy>
          <iyz>0</iyz>
          <izz>1e-05</izz>
        </inertia>
      </inertial>
    </link>
    <plugin name='controller_interface' filename='librotors_gazebo_controller_interface.so'>
      <robotNamespace>blimp</robotNamespace>
      <commandAttitudeThrustSubTopic>command/attitude</commandAttitudeThrustSubTopic>
      <commandRateThrustSubTopic>command/rate</commandRateThrustSubTopic>
      <commandMotorSpeedSubTopic>command/motor_speed</commandMotorSpeedSubTopic>
      <imuSubTopic>imu</imuSubTopic>
      <motorSpeedCommandPubTopic>gazebo/command/motor_speed</motorSpeedCommandPubTopic>
    </plugin>

    <plugin name='gazebo_ros_control' filename='libgazebo_ros_control.so'>
      <robotNamespace>/blimp</robotNamespace>
    </plugin>

    <plugin name='mavlink_interface' filename='libgazebo_mavlink_interface.so'>
      <robotNamespace>blimp</robotNamespace>
      <imuSubTopic>/imu</imuSubTopic>
      <gpsSubTopic>/gps</gpsSubTopic>

      <mavlink_addr>INADDR_ANY</mavlink_addr>
      <mavlink_udp_port>14560</mavlink_udp_port>
      <mavlink_tcp_port>4560</mavlink_tcp_port>
      <serialEnabled>false</serialEnabled>
      <serialDevice>/dev/ttyACM0</serialDevice>
      <baudRate>921600</baudRate>
      <qgc_addr>INADDR_ANY</qgc_addr>
      <qgc_udp_port>14550</qgc_udp_port>

      <hil_mode>false</hil_mode>
      <hil_state_level>false</hil_state_level>
      <enable_lockstep>true</enable_lockstep>
      <use_tcp>true</use_tcp>

      <send_vision_estimation>true</send_vision_estimation>
      <send_odometry>false</send_odometry>

      <control_channels>
        <channel name='left_blade_link'>
          <input_index>0</input_index>
          <input_offset>0</input_offset>
          <input_scaling>879.23</input_index>
          <zero_position_disarmed>0</zero_position_disarmed>
          <zero_position_armed>0</zero_position_armed>
          <joint_control_type>velocity</joint_control_type>
          <joint_name>stick_left_blade_joint</joint_name>
        </channel>
        <channel name='right_blade_link'>
          <input_index>1</input_index>
          <input_offset>0</input_offset>
          <input_scaling>879.23</input_index>
          <zero_position_disarmed>0</zero_position_disarmed>
          <zero_position_armed>0</zero_position_armed>
          <joint_control_type>velocity</joint_control_type>
          <joint_name>stick_right_blade_joint</joint_name>
        </channel>
      </control_channels>
    </plugin>

    <!-- <plugin name='mavlink_interface' filename='librotors_gazebo_mavlink_interface.so'>
      <robotNamespace>blimp</robotNamespace>
      <mavlinkControlSubTopic>/mavlink/from</mavlinkControlSubTopic>
      <imuSubTopic>imu</imuSubTopic>
      <mavlinkHilSensorPubTopic>/mavlink/to</mavlinkHilSensorPubTopic>
      <motorSpeedsPubTopic>gazebo/command/motor_speed</motorSpeedsPubTopic>
      <gpsUpdateFreq>5.0</gpsUpdateFreq>
      <rotorCount>3</rotorCount>
      <referenceMagNorth>0.21475</referenceMagNorth>
      <referenceMagEast>0.00797</referenceMagEast>
      <referenceMagDown>0.42817</referenceMagDown>
      <referenceLatitude>47.3667</referenceLatitude>
      <referenceLongitude>8.55</referenceLongitude>
      <referenceAltitude>500.0</referenceAltitude>
    </plugin> -->

    <plugin name='left_blade_link_motor_model' filename='librotors_gazebo_motor_model.so'>
      <robotNamespace>blimp</robotNamespace>
      <jointName>stick_left_blade_joint</jointName>
      <linkName>left_blade_link</linkName>
      <turningDirection>ccw</turningDirection>
      <timeConstantUp>1</timeConstantUp>
      <timeConstantDown>1</timeConstantDown>
      <maxRotVelocity>879.23</maxRotVelocity>
      <motorConstant>0.00371178707</motorConstant>
      <momentConstant>0.016</momentConstant>
      <commandSubTopic>gazebo/command/motor_speed</commandSubTopic>
      <motorNumber>0</motorNumber>
      <rotorDragCoefficient>8.06428e-05</rotorDragCoefficient>
      <rollingMomentCoefficient>1e-06</rollingMomentCoefficient>
      <motorSpeedPubTopic>motor_speed/0</motorSpeedPubTopic>
      <rotorVelocitySlowdownSim>1</rotorVelocitySlowdownSim>
    </plugin>

    <!-- <plugin name='left_blade_link_motor_model' filename='librotors_gazebo_motor_model.so'>
      <robotNamespace>blimp</robotNamespace>
      <jointName>stick_left_blade_joint</jointName>
      <linkName>left_blade_link</linkName>
      <turningDirection>ccw</turningDirection>
      <timeConstantUp>1</timeConstantUp>
      <timeConstantDown>1</timeConstantDown>
      <maxRotVelocity>879.23</maxRotVelocity>
      <motorConstant>0.00371178707</motorConstant>
      <momentConstant>0.016</momentConstant>
      <commandSubTopic>gazebo/command/motor_speed</commandSubTopic>
      <motorNumber>0</motorNumber>
      <rotorDragCoefficient>8.06428e-05</rotorDragCoefficient>
      <rollingMomentCoefficient>1e-06</rollingMomentCoefficient>
      <motorSpeedPubTopic>motor_speed/0</motorSpeedPubTopic>
      <rotorVelocitySlowdownSim>1</rotorVelocitySlowdownSim>
    </plugin> -->

    <!-- <plugin name='right_blade_link_motor_model' filename='librotors_gazebo_motor_model.so'> -->
    <plugin name='right_blade_link_motor_model' filename='libgazebo_motor_model.so'>
      <robotNamespace>blimp</robotNamespace>
      <jointName>stick_right_blade_joint</jointName>
      <linkName>right_blade_link</linkName>
      <turningDirection>cw</turningDirection>
      <timeConstantUp>1</timeConstantUp>
      <timeConstantDown>1</timeConstantDown>
      <maxRotVelocity>879.23</maxRotVelocity>
      <motorConstant>0.00371178707</motorConstant>
      <momentConstant>0.016</momentConstant>
      <commandSubTopic>gazebo/command/motor_speed</commandSubTopic>
      <motorNumber>1</motorNumber>
      <rotorDragCoefficient>8.06428e-05</rotorDragCoefficient>
      <rollingMomentCoefficient>1e-06</rollingMomentCoefficient>
      <motorSpeedPubTopic>motor_speed/1</motorSpeedPubTopic>
      <rotorVelocitySlowdownSim>1</rotorVelocitySlowdownSim>
    </plugin>

    <!-- <plugin name='bot_rud_motor_link_motor_model' filename='librotors_gazebo_motor_model.so'> -->
    <plugin name='bot_rud_motor_link_motor_model' filename='libgazebo_motor_model.so'>
      <robotNamespace>blimp</robotNamespace>
      <jointName>bot_rud_part1_bot_rud_motor_joint</jointName>
      <linkName>bot_rud_motor_link</linkName>
      <turningDirection>cw</turningDirection>
      <timeConstantUp>1</timeConstantUp>
      <timeConstantDown>1</timeConstantDown>
      <maxRotVelocity>879.23</maxRotVelocity>
      <motorConstant>0.00371178707</motorConstant>
      <momentConstant>0.016</momentConstant>
      <commandSubTopic>gazebo/command/motor_speed</commandSubTopic>
      <motorNumber>2</motorNumber>
      <rotorDragCoefficient>8.06428e-05</rotorDragCoefficient>
      <rollingMomentCoefficient>1e-06</rollingMomentCoefficient>
      <motorSpeedPubTopic>motor_speed/2</motorSpeedPubTopic>
      <rotorVelocitySlowdownSim>1</rotorVelocitySlowdownSim>
    </plugin>

    <!-- <plugin name='rotors_gazebo_imugt_plugin' filename='librotors_gazebo_imu_plugin.so'> -->
    <plugin name='rotors_gazebo_imugt_plugin' filename='libgazebo_imu_plugin.so'>
      <robotNamespace>blimp</robotNamespace>
      <linkName>imugt_link</linkName>
      <!-- <imuTopic>ground_truth/imu</imuTopic> -->
      <imuTopic>/imu</imuTopic>
      <gyroscopeNoiseDensity>0.0</gyroscopeNoiseDensity>
      <gyroscopeRandomWalk>0.0</gyroscopeRandomWalk>
      <gyroscopeBiasCorrelationTime>1000.0</gyroscopeBiasCorrelationTime>
      <gyroscopeTurnOnBiasSigma>0.0</gyroscopeTurnOnBiasSigma>
      <accelerometerNoiseDensity>0.0</accelerometerNoiseDensity>
      <accelerometerRandomWalk>0.0</accelerometerRandomWalk>
      <accelerometerBiasCorrelationTime>300.0</accelerometerBiasCorrelationTime>
      <accelerometerTurnOnBiasSigma>0.0</accelerometerTurnOnBiasSigma>
    </plugin>

    <plugin name='odometry_sensorgt' filename='librotors_gazebo_odometry_plugin.so'>
      <linkName>odometry_sensorgt_link</linkName>
      <robotNamespace>blimp</robotNamespace>
      <poseTopic>ground_truth/pose</poseTopic>
      <poseWithCovarianceTopic>ground_truth/pose_with_covariance</poseWithCovarianceTopic>
      <positionTopic>ground_truth/position</positionTopic>
      <transformTopic>ground_truth/transform</transformTopic>
      <odometryTopic>ground_truth/odometry</odometryTopic>
      <parentFrameId>world</parentFrameId>
      <childFrameId>base_link</childFrameId>
      <measurementDivisor>1</measurementDivisor>
      <measurementDelay>0</measurementDelay>
      <unknownDelay>0.0</unknownDelay>
      <noiseNormalPosition>0 0 0</noiseNormalPosition>
      <noiseNormalQuaternion>0 0 0</noiseNormalQuaternion>
      <noiseNormalLinearVelocity>0 0 0</noiseNormalLinearVelocity>
      <noiseNormalAngularVelocity>0 0 0</noiseNormalAngularVelocity>
      <noiseUniformPosition>0 0 0</noiseUniformPosition>
      <noiseUniformQuaternion>0 0 0</noiseUniformQuaternion>
      <noiseUniformLinearVelocity>0 0 0</noiseUniformLinearVelocity>
      <noiseUniformAngularVelocity>0 0 0</noiseUniformAngularVelocity>
    </plugin>

    <!-- <plugin name='rotors_gazebo_imutail_plugin' filename='librotors_gazebo_imu_plugin.so'> -->
    <plugin name='rotors_gazebo_imutail_plugin' filename='libgazebo_imu_plugin.so'>
      <robotNamespace>blimp</robotNamespace>
      <linkName>imutail_link</linkName>
      <imuTopic>tail/imu</imuTopic>
      <gyroscopeNoiseDensity>0.0</gyroscopeNoiseDensity>
      <gyroscopeRandomWalk>0.0</gyroscopeRandomWalk>
      <gyroscopeBiasCorrelationTime>1000.0</gyroscopeBiasCorrelationTime>
      <gyroscopeTurnOnBiasSigma>0.0</gyroscopeTurnOnBiasSigma>
      <accelerometerNoiseDensity>0.0</accelerometerNoiseDensity>
      <accelerometerRandomWalk>0.0</accelerometerRandomWalk>
      <accelerometerBiasCorrelationTime>300.0</accelerometerBiasCorrelationTime>
      <accelerometerTurnOnBiasSigma>0.0</accelerometerTurnOnBiasSigma>
    </plugin>

    <plugin name='odometry_sensortail' filename='librotors_gazebo_odometry_plugin.so'>
      <linkName>odometry_sensortail_link</linkName>
      <robotNamespace>blimp</robotNamespace>
      <poseTopic>tail/pose</poseTopic>
      <poseWithCovarianceTopic>tail/pose_with_covariance</poseWithCovarianceTopic>
      <positionTopic>tail/position</positionTopic>
      <transformTopic>tail/transform</transformTopic>
      <odometryTopic>tail/odometry</odometryTopic>
      <parentFrameId>world</parentFrameId>
      <childFrameId>top_rud_part1_link</childFrameId>
      <measurementDivisor>1</measurementDivisor>
      <measurementDelay>0</measurementDelay>
      <unknownDelay>0.0</unknownDelay>
      <noiseNormalPosition>0 0 0</noiseNormalPosition>
      <noiseNormalQuaternion>0 0 0</noiseNormalQuaternion>
      <noiseNormalLinearVelocity>0 0 0</noiseNormalLinearVelocity>
      <noiseNormalAngularVelocity>0 0 0</noiseNormalAngularVelocity>
      <noiseUniformPosition>0 0 0</noiseUniformPosition>
      <noiseUniformQuaternion>0 0 0</noiseUniformQuaternion>
      <noiseUniformLinearVelocity>0 0 0</noiseUniformLinearVelocity>
      <noiseUniformAngularVelocity>0 0 0</noiseUniformAngularVelocity>
    </plugin>
    <plugin name='forward_lift_joint_link_finliftdrag' filename='libfinliftdrag_plugin.so'>
      <robotNamespace>blimp</robotNamespace>
      <link_name>forward_lift_joint_link</link_name>
      <air_density>1.2041</air_density>
      <cw0>0.08</cw0>
      <cw1>0.6</cw1>
      <cw2>1.2</cw2>
      <cl0>0</cl0>
      <cl1>1.2</cl1>
      <cl2>0</cl2>
      <alpha_stall>0.3839724354387525</alpha_stall>
      <a0>0</a0>
      <area>1.57</area>
      <radial_symmetry>1</radial_symmetry>
      <upward>0 1 0</upward>
      <forward>1 0 0</forward>
      <cp>0 0 0</cp>
    </plugin>
    <plugin name='aft_lift_joint_link_finliftdrag' filename='libfinliftdrag_plugin.so'>
      <robotNamespace>blimp</robotNamespace>
      <link_name>aft_lift_joint_link</link_name>
      <air_density>1.2041</air_density>
      <cw0>0</cw0>
      <cw1>0.6</cw1>
      <cw2>1.2</cw2>
      <cl0>0</cl0>
      <cl1>1.2</cl1>
      <cl2>0</cl2>
      <alpha_stall>0.3839724354387525</alpha_stall>
      <a0>0</a0>
      <area>1.57</area>
      <radial_symmetry>1</radial_symmetry>
      <upward>0 1 0</upward>
      <forward>1 0 0</forward>
      <cp>0 0 0</cp>
    </plugin>
    <plugin name='bot_rud_part1_link_finliftdrag' filename='libfinliftdrag_plugin.so'>
      <robotNamespace>blimp</robotNamespace>
      <link_name>bot_rud_part1_link</link_name>
      <air_density>1.2041</air_density>
      <cw0>0.075</cw0>
      <cw1>0.6375</cw1>
      <cw2>1.2</cw2>
      <cl0>0</cl0>
      <cl1>0.6</cl1>
      <cl2>0</cl2>
      <alpha_stall>0.3839724354387525</alpha_stall>
      <a0>0</a0>
      <area>0.16</area>
      <radial_symmetry>0</radial_symmetry>
      <upward>0 -1 0</upward>
      <forward>1 0 0</forward>
      <cp>0 0 0</cp>
    </plugin>
    <plugin name='top_rud_part1_link_finliftdrag' filename='libfinliftdrag_plugin.so'>
      <robotNamespace>blimp</robotNamespace>
      <link_name>top_rud_part1_link</link_name>
      <air_density>1.2041</air_density>
      <cw0>0.075</cw0>
      <cw1>0.6375</cw1>
      <cw2>1.2</cw2>
      <cl0>0</cl0>
      <cl1>0.6</cl1>
      <cl2>0</cl2>
      <alpha_stall>0.3839724354387525</alpha_stall>
      <a0>0</a0>
      <area>0.16</area>
      <airspeedPubTopic>tail/indicatedAirspeed</airspeedPubTopic>
      <radial_symmetry>0</radial_symmetry>
      <upward>0 1 0</upward>
      <forward>1 0 0</forward>
      <cp>0 0 0</cp>
    </plugin>
    <plugin name='left_elv_part1_link_finliftdrag' filename='libfinliftdrag_plugin.so'>
      <robotNamespace>blimp</robotNamespace>
      <link_name>left_elv_part1_link</link_name>
      <air_density>1.2041</air_density>
      <cw0>0.075</cw0>
      <cw1>0.6375</cw1>
      <cw2>1.2</cw2>
      <cl0>0</cl0>
      <cl1>0.6</cl1>
      <cl2>0</cl2>
      <alpha_stall>0.3839724354387525</alpha_stall>
      <a0>0</a0>
      <area>0.16</area>
      <radial_symmetry>0</radial_symmetry>
      <upward>0 1 0</upward>
      <forward>1 0 0</forward>
      <cp>0 0 0</cp>
    </plugin>
    <plugin name='right_elv_part1_link_finliftdrag' filename='libfinliftdrag_plugin.so'>
      <robotNamespace>blimp</robotNamespace>
      <link_name>right_elv_part1_link</link_name>
      <air_density>1.2041</air_density>
      <cw0>0.075</cw0>
      <cw1>0.6375</cw1>
      <cw2>1.2</cw2>
      <cl0>0</cl0>
      <cl1>0.6</cl1>
      <cl2>0</cl2>
      <alpha_stall>0.3839724354387525</alpha_stall>
      <a0>0</a0>
      <area>0.16</area>
      <radial_symmetry>0</radial_symmetry>
      <upward>0 -1 0</upward>
      <forward>1 0 0</forward>
      <cp>0 0 0</cp>
    </plugin>
    <plugin name='bot_rud_joint_link_finliftdrag' filename='libfinliftdrag_plugin.so'>
      <robotNamespace>blimp</robotNamespace>
      <link_name>bot_rud_joint_link</link_name>
      <air_density>1.2041</air_density>
      <cw0>0</cw0>
      <cw1>0.6</cw1>
      <cw2>1.2</cw2>
      <cl0>0</cl0>
      <cl1>2.0</cl1>
      <cl2>0</cl2>
      <alpha_stall>0.3839724354387525</alpha_stall>
      <a0>0</a0>
      <area>0.16</area>
      <radial_symmetry>0</radial_symmetry>
      <upward>0 -1 0</upward>
      <forward>1 0 0</forward>
      <cp>0 0 0</cp>
    </plugin>
    <plugin name='top_rud_joint_link_finliftdrag' filename='libfinliftdrag_plugin.so'>
      <robotNamespace>blimp</robotNamespace>
      <link_name>top_rud_joint_link</link_name>
      <air_density>1.2041</air_density>
      <cw0>0</cw0>
      <cw1>0.6</cw1>
      <cw2>1.2</cw2>
      <cl0>0</cl0>
      <cl1>2.0</cl1>
      <cl2>0</cl2>
      <alpha_stall>0.3839724354387525</alpha_stall>
      <a0>0</a0>
      <area>0.16</area>
      <radial_symmetry>0</radial_symmetry>
      <upward>0 1 0</upward>
      <forward>1 0 0</forward>
      <cp>0 0 0</cp>
    </plugin>
    <plugin name='left_elv_joint_link_finliftdrag' filename='libfinliftdrag_plugin.so'>
      <robotNamespace>blimp</robotNamespace>
      <link_name>left_elv_joint_link</link_name>
      <air_density>1.2041</air_density>
      <cw0>0</cw0>
      <cw1>0.6</cw1>
      <cw2>1.2</cw2>
      <cl0>0</cl0>
      <cl1>2.0</cl1>
      <cl2>0</cl2>
      <alpha_stall>0.3839724354387525</alpha_stall>
      <a0>0</a0>
      <area>0.16</area>
      <radial_symmetry>0</radial_symmetry>
      <upward>0 1 0</upward>
      <forward>1 0 0</forward>
      <cp>0 0 0</cp>
    </plugin>
    <plugin name='right_elv_joint_link_finliftdrag' filename='libfinliftdrag_plugin.so'>
      <robotNamespace>blimp</robotNamespace>
      <link_name>right_elv_joint_link</link_name>
      <air_density>1.2041</air_density>
      <cw0>0</cw0>
      <cw1>0.6</cw1>
      <cw2>1.2</cw2>
      <cl0>0</cl0>
      <cl1>2.0</cl1>
      <cl2>0</cl2>
      <alpha_stall>0.3839724354387525</alpha_stall>
      <a0>0</a0>
      <area>0.16</area>
      <radial_symmetry>0</radial_symmetry>
      <upward>0 -1 0</upward>
      <forward>1 0 0</forward>
      <cp>0 0 0</cp>
    </plugin>
    <plugin name='dynamicvolume_plugin' filename='libdynamicvolume_plugin.so'>
      <robotNamespace>blimp</robotNamespace>
      <linkName>blimp_body_link</linkName>
      <dynamicvolumetopic>dynamicvolumetopic</dynamicvolumetopic>
      <heliummasstopic>heliummasstopic</heliummasstopic>
      <heliummass>1.723</heliummass>
      <reference_altitude>341.0</reference_altitude>
    </plugin>
    <frame name='base_gondola_body_joint' attached_to='base_link'>
      <pose>0 0 0.1 0 -0 0</pose>
    </frame>
    <frame name='gondola_body_link' attached_to='base_gondola_body_joint'/>
    <frame name='bot_rud_joint_link_bot_rud_part2_joint' attached_to='bot_rud_joint_link'>
      <pose>-0.125 0 0 0 -0 0</pose>
    </frame>
    <frame name='bot_rud_part2_link' attached_to='bot_rud_joint_link_bot_rud_part2_joint'/>
    <frame name='left_elv_joint_link_left_elv_part2_joint' attached_to='left_elv_joint_link'>
      <pose>-0.125 0 0 0 -0 0</pose>
    </frame>
    <frame name='left_elv_part2_link' attached_to='left_elv_joint_link_left_elv_part2_joint'/>
    <frame name='right_elv_joint_link_right_elv_part2_joint' attached_to='right_elv_joint_link'>
      <pose>-0.125 0 0 0 -0 0</pose>
    </frame>
    <frame name='right_elv_part2_link' attached_to='right_elv_joint_link_right_elv_part2_joint'/>
    <frame name='top_rud_joint_link_top_rud_part2_joint' attached_to='top_rud_joint_link'>
      <pose>-0.125 0 0 0 -0 0</pose>
    </frame>
    <frame name='top_rud_part2_link' attached_to='top_rud_joint_link_top_rud_part2_joint'/>
    <frame name='base_gondola_left_support_joint' attached_to='base_link'>
      <pose>0 0.1 -0.085 0.4 -0 0</pose>
    </frame>
    <frame name='gondola_left_support_link' attached_to='base_gondola_left_support_joint'/>
    <frame name='base_gondola_right_support_joint' attached_to='base_link'>
      <pose>0 -0.1 -0.085 0.4 0 3.14159</pose>
    </frame>
    <frame name='gondola_right_support_link' attached_to='base_gondola_right_support_joint'/>
    <frame name='stick_left_wing_joint' attached_to='stick_link'>
      <pose>0 0.02 -0.375 -1.5708 0 0</pose>
    </frame>
    <frame name='left_wing_link' attached_to='stick_left_wing_joint'/>
    <frame name='stick_right_wing_joint' attached_to='stick_link'>
      <pose>0 0.02 0.375 -1.5708 0 0</pose>
    </frame>
    <frame name='right_wing_link' attached_to='stick_right_wing_joint'/>
  </model>
</sdf>
